<?xml version="1.0"?>
<!-- created with Phobos 0.7 -->
<sdf version="1.5">
  <model name="snake_prickleback">
    <link name="body_0_link">
      <pose>0 0 0 0 0 0</pose>
      <inertial>
        <mass>0.0010764975</mass>
        <inertia>
          <ixx>4.72e-08</ixx>
          <ixy>-1.6e-09</ixy>
          <ixz>0</ixz>
          <iyy>4.031e-07</iyy>
          <iyz>0</iyz>
          <izz>3.965e-07</izz>
        </inertia>
        <pose>0.0162840299 -5e-10 0.00028867 0 0 0</pose>
      </inertial>
      <collision name="body_0_collision">
        <pose>0 0 0 0 0 0</pose>
        <geometry>
          <mesh>
            <uri>model://snake_prickleback/meshes/salamander_body_0_collision.dae</uri>
            <scale>1.0 1.0 1.0</scale>
          </mesh>
        </geometry>
      </collision>
      <visual name="body_0_visual">
        <pose>0.0 0.0 0.0 0.0 -0.0 0.0</pose>
        <material>
          <ambient>0 0 0 0</ambient>
          <diffuse>0 0 0 0</diffuse>
          <specular>0.4499999881 0.4499999881 0 1.0</specular>
        </material>
        <geometry>
          <mesh>
            <uri>model://snake_prickleback/meshes/salamander_body_0.dae</uri>
            <scale>1.0 1.0 1.0</scale>
          </mesh>
        </geometry>
      </visual>
    </link>
    <link name="body_1_link">
      <pose>0.0368381999 0 1.19857e-05 0 0 0</pose>
      <inertial>
        <mass>0.000274898</mass>
        <inertia>
          <ixx>1.47e-08</ixx>
          <ixy>0</ixy>
          <ixz>0</ixz>
          <iyy>1.41e-08</iyy>
          <iyz>0</iyz>
          <izz>1.21e-08</izz>
        </inertia>
        <pose>-0.0025969259 0 0.00023545 0 0 0</pose>
      </inertial>
      <collision name="body_1_collision">
        <pose>0 0 0 0 0 0</pose>
        <geometry>
          <mesh>
            <uri>model://snake_prickleback/meshes/salamander_body_1_collision.dae</uri>
            <scale>1.0 1.0 1.0</scale>
          </mesh>
        </geometry>
      </collision>
      <visual name="body_1_visual">
        <pose>0.0 0.0 0.0 0.0 -0.0 0.0</pose>
        <material>
          <ambient>0 0 0 0</ambient>
          <diffuse>0 0 0 0</diffuse>
          <specular>0.4499999881 0.4499999881 0 1.0</specular>
        </material>
        <geometry>
          <mesh>
            <uri>model://snake_prickleback/meshes/salamander_body_1.dae</uri>
            <scale>1.0 1.0 1.0</scale>
          </mesh>
        </geometry>
      </visual>
    </link>
    <link name="body_2_link">
      <pose>0.0497315712 0 1.2743e-06 0 0 0</pose>
      <inertial>
        <mass>0.0007215161</mass>
        <inertia>
          <ixx>4.26e-08</ixx>
          <ixy>0</ixy>
          <ixz>0</ixz>
          <iyy>4.88e-08</iyy>
          <iyz>0</iyz>
          <izz>3.59e-08</izz>
        </inertia>
        <pose>-0.0031417571 5e-10 0.0003078577 0 0 0</pose>
      </inertial>
      <collision name="body_2_collision">
        <pose>0 0 0 0 0 0</pose>
        <geometry>
          <mesh>
            <uri>model://snake_prickleback/meshes/salamander_body_2_collision.dae</uri>
            <scale>1.0 1.0 1.0</scale>
          </mesh>
        </geometry>
      </collision>
      <visual name="body_2_visual">
        <pose>0.0 0.0 0.0 0.0 -0.0 0.0</pose>
        <material>
          <ambient>0 0 0 0</ambient>
          <diffuse>0 0 0 0</diffuse>
          <specular>0.4499999881 0.4499999881 0 1.0</specular>
        </material>
        <geometry>
          <mesh>
            <uri>model://snake_prickleback/meshes/salamander_body_2.dae</uri>
            <scale>1.0 1.0 1.0</scale>
          </mesh>
        </geometry>
      </visual>
    </link>
    <link name="body_3_link">
      <pose>0.0626249388 0 -5.959e-07 0 0 0</pose>
      <inertial>
        <mass>0.0006067418</mass>
        <inertia>
          <ixx>3.8e-08</ixx>
          <ixy>-1e-10</ixy>
          <ixz>0</ixz>
          <iyy>4.66e-08</iyy>
          <iyz>0</iyz>
          <izz>3.26e-08</izz>
        </inertia>
        <pose>-0.0026654154 0 0.0003171539 0 0 0</pose>
      </inertial>
      <collision name="body_3_collision">
        <pose>0 0 0 0 0 0</pose>
        <geometry>
          <mesh>
            <uri>model://snake_prickleback/meshes/salamander_body_3_collision.dae</uri>
            <scale>1.0 1.0 1.0</scale>
          </mesh>
        </geometry>
      </collision>
      <visual name="body_3_visual">
        <pose>0.0 0.0 0.0 0.0 -0.0 0.0</pose>
        <material>
          <ambient>0 0 0 0</ambient>
          <diffuse>0 0 0 0</diffuse>
          <specular>0.4499999881 0.4499999881 0 1.0</specular>
        </material>
        <geometry>
          <mesh>
            <uri>model://snake_prickleback/meshes/salamander_body_3.dae</uri>
            <scale>1.0 1.0 1.0</scale>
          </mesh>
        </geometry>
      </visual>
    </link>
    <link name="body_4_link">
      <pose>0.0755183101 0 7.44e-08 0 0 0</pose>
      <inertial>
        <mass>4.83287e-05</mass>
        <inertia>
          <ixx>2.6e-09</ixx>
          <ixy>0</ixy>
          <ixz>0</ixz>
          <iyy>3.6e-09</iyy>
          <iyz>0</iyz>
          <izz>2.3e-09</izz>
        </inertia>
        <pose>-0.0025630295 0 0.0002598912 0 0 0</pose>
      </inertial>
      <collision name="body_4_collision">
        <pose>0 0 0 0 0 0</pose>
        <geometry>
          <mesh>
            <uri>model://snake_prickleback/meshes/salamander_body_4_collision.dae</uri>
            <scale>1.0 1.0 1.0</scale>
          </mesh>
        </geometry>
      </collision>
      <visual name="body_4_visual">
        <pose>0.0 0.0 0.0 0.0 -0.0 0.0</pose>
        <material>
          <ambient>0 0 0 0</ambient>
          <diffuse>0 0 0 0</diffuse>
          <specular>0.4499999881 0.4499999881 0 1.0</specular>
        </material>
        <geometry>
          <mesh>
            <uri>model://snake_prickleback/meshes/salamander_body_4.dae</uri>
            <scale>1.0 1.0 1.0</scale>
          </mesh>
        </geometry>
      </visual>
    </link>
    <link name="body_5_link">
      <pose>0.0884116814 0 8.3e-09 0 0 0</pose>
      <inertial>
        <mass>0.0002203355</mass>
        <inertia>
          <ixx>1.1e-08</ixx>
          <ixy>0</ixy>
          <ixz>0</ixz>
          <iyy>1.59e-08</iyy>
          <iyz>0</iyz>
          <izz>9.7e-09</izz>
        </inertia>
        <pose>-0.0023640615 2e-10 0.0003003745 0 0 0</pose>
      </inertial>
      <collision name="body_5_collision">
        <pose>0 0 0 0 0 0</pose>
        <geometry>
          <mesh>
            <uri>model://snake_prickleback/meshes/salamander_body_5_collision.dae</uri>
            <scale>1.0 1.0 1.0</scale>
          </mesh>
        </geometry>
      </collision>
      <visual name="body_5_visual">
        <pose>0.0 0.0 0.0 0.0 -0.0 0.0</pose>
        <material>
          <ambient>0 0 0 0</ambient>
          <diffuse>0 0 0 0</diffuse>
          <specular>0.4499999881 0.4499999881 0 1.0</specular>
        </material>
        <geometry>
          <mesh>
            <uri>model://snake_prickleback/meshes/salamander_body_5.dae</uri>
            <scale>1.0 1.0 1.0</scale>
          </mesh>
        </geometry>
      </visual>
    </link>
    <link name="body_6_link">
      <pose>0.1013050526 0 6.5e-09 0 0 0</pose>
      <inertial>
        <mass>0.0002335692</mass>
        <inertia>
          <ixx>1.03e-08</ixx>
          <ixy>0</ixy>
          <ixz>0</ixz>
          <iyy>1.52e-08</iyy>
          <iyz>0</iyz>
          <izz>9.1e-09</izz>
        </inertia>
        <pose>-0.0013204367 0 0.0002474073 0 0 0</pose>
      </inertial>
      <collision name="body_6_collision">
        <pose>0 0 0 0 0 0</pose>
        <geometry>
          <mesh>
            <uri>model://snake_prickleback/meshes/salamander_body_6_collision.dae</uri>
            <scale>1.0 1.0 1.0</scale>
          </mesh>
        </geometry>
      </collision>
      <visual name="body_6_visual">
        <pose>0.0 0.0 0.0 0.0 -0.0 0.0</pose>
        <material>
          <ambient>0 0 0 0</ambient>
          <diffuse>0 0 0 0</diffuse>
          <specular>0.4499999881 0.4499999881 0 1.0</specular>
        </material>
        <geometry>
          <mesh>
            <uri>model://snake_prickleback/meshes/salamander_body_6.dae</uri>
            <scale>1.0 1.0 1.0</scale>
          </mesh>
        </geometry>
      </visual>
    </link>
    <link name="body_7_link">
      <pose>0.1141984165 0 -3.7e-08 0 0 0</pose>
      <inertial>
        <mass>0.0001132323</mass>
        <inertia>
          <ixx>4.1e-09</ixx>
          <ixy>0</ixy>
          <ixz>0</ixz>
          <iyy>6.2e-09</iyy>
          <iyz>0</iyz>
          <izz>3.7e-09</izz>
        </inertia>
        <pose>-0.0007655024 0 0.0001754074 0 0 0</pose>
      </inertial>
      <collision name="body_7_collision">
        <pose>0 0 0 0 0 0</pose>
        <geometry>
          <mesh>
            <uri>model://snake_prickleback/meshes/salamander_body_7_collision.dae</uri>
            <scale>1.0 1.0 1.0</scale>
          </mesh>
        </geometry>
      </collision>
      <visual name="body_7_visual">
        <pose>0.0 0.0 0.0 0.0 -0.0 0.0</pose>
        <material>
          <ambient>0 0 0 0</ambient>
          <diffuse>0 0 0 0</diffuse>
          <specular>0.4499999881 0.4499999881 0 1.0</specular>
        </material>
        <geometry>
          <mesh>
            <uri>model://snake_prickleback/meshes/salamander_body_7.dae</uri>
            <scale>1.0 1.0 1.0</scale>
          </mesh>
        </geometry>
      </visual>
    </link>
    <link name="body_8_link">
      <pose>0.1270917952 0 -1.193e-07 0 0 0</pose>
      <inertial>
        <mass>0.0001090047</mass>
        <inertia>
          <ixx>3e-09</ixx>
          <ixy>0</ixy>
          <ixz>0</ixz>
          <iyy>4.8e-09</iyy>
          <iyz>0</iyz>
          <izz>2.9e-09</izz>
        </inertia>
        <pose>8.2403e-06 0 0.0001694435 0 0 0</pose>
      </inertial>
      <collision name="body_8_collision">
        <pose>0 0 0 0 0 0</pose>
        <geometry>
          <mesh>
            <uri>model://snake_prickleback/meshes/salamander_body_8_collision.dae</uri>
            <scale>1.0 1.0 1.0</scale>
          </mesh>
        </geometry>
      </collision>
      <visual name="body_8_visual">
        <pose>0.0 0.0 0.0 0.0 -0.0 0.0</pose>
        <material>
          <ambient>0 0 0 0</ambient>
          <diffuse>0 0 0 0</diffuse>
          <specular>0.4499999881 0.4499999881 0 1.0</specular>
        </material>
        <geometry>
          <mesh>
            <uri>model://snake_prickleback/meshes/salamander_body_8.dae</uri>
            <scale>1.0 1.0 1.0</scale>
          </mesh>
        </geometry>
      </visual>
    </link>
    <link name="body_9_link">
      <pose>0.139985159 0 1.8926e-06 0 0 0</pose>
      <inertial>
        <mass>0.000158273</mass>
        <inertia>
          <ixx>3.2e-09</ixx>
          <ixy>0</ixy>
          <ixz>0</ixz>
          <iyy>5.6e-09</iyy>
          <iyz>0</iyz>
          <izz>3.6e-09</izz>
        </inertia>
        <pose>0.0010851473 0 0.0001444671 0 0 0</pose>
      </inertial>
      <collision name="body_9_collision">
        <pose>0 0 0 0 0 0</pose>
        <geometry>
          <mesh>
            <uri>model://snake_prickleback/meshes/salamander_body_9_collision.dae</uri>
            <scale>1.0 1.0 1.0</scale>
          </mesh>
        </geometry>
      </collision>
      <visual name="body_9_visual">
        <pose>0.0 0.0 0.0 0.0 -0.0 0.0</pose>
        <material>
          <ambient>0 0 0 0</ambient>
          <diffuse>0 0 0 0</diffuse>
          <specular>0.4499999881 0.4499999881 0 1.0</specular>
        </material>
        <geometry>
          <mesh>
            <uri>model://snake_prickleback/meshes/salamander_body_9.dae</uri>
            <scale>1.0 1.0 1.0</scale>
          </mesh>
        </geometry>
      </visual>
    </link>
    <link name="body_10_link">
      <pose>0.1528785229 0 -7.3729e-06 0 0 0</pose>
      <inertial>
        <mass>7.96666e-05</mass>
        <inertia>
          <ixx>1e-09</ixx>
          <ixy>0</ixy>
          <ixz>0</ixz>
          <iyy>2.1e-09</iyy>
          <iyz>0</iyz>
          <izz>1.4e-09</izz>
        </inertia>
        <pose>0.0014331936 0 9.64492e-05 0 0 0</pose>
      </inertial>
      <collision name="body_10_collision">
        <pose>0 0 0 0 0 0</pose>
        <geometry>
          <mesh>
            <uri>model://snake_prickleback/meshes/salamander_body_10_collision.dae</uri>
            <scale>1.0 1.0 1.0</scale>
          </mesh>
        </geometry>
      </collision>
      <visual name="body_10_visual">
        <pose>0.0 0.0 0.0 0.0 -0.0 0.0</pose>
        <material>
          <ambient>0 0 0 0</ambient>
          <diffuse>0 0 0 0</diffuse>
          <specular>0.4499999881 0.4499999881 0 1.0</specular>
        </material>
        <geometry>
          <mesh>
            <uri>model://snake_prickleback/meshes/salamander_body_10.dae</uri>
            <scale>1.0 1.0 1.0</scale>
          </mesh>
        </geometry>
      </visual>
    </link>
    <link name="body_11_link">
      <pose>0.1657719016 0 -2.04942e-05 0 0 0</pose>
      <inertial>
        <mass>0.0003871155</mass>
        <inertia>
          <ixx>3.2e-09</ixx>
          <ixy>-5e-10</ixy>
          <ixz>0</ixz>
          <iyy>2.65e-08</iyy>
          <iyz>0</iyz>
          <izz>2.38e-08</izz>
        </inertia>
        <pose>0.0060428679 1e-10 8.57897e-05 0 0 0</pose>
      </inertial>
      <collision name="body_11_collision">
        <pose>0 0 0 0 0 0</pose>
        <geometry>
          <mesh>
            <uri>model://snake_prickleback/meshes/salamander_body_11_collision.dae</uri>
            <scale>1.0 1.0 1.0</scale>
          </mesh>
        </geometry>
      </collision>
      <visual name="body_11_visual">
        <pose>0.0 0.0 0.0 0.0 -0.0 0.0</pose>
        <material>
          <ambient>0 0 0 0</ambient>
          <diffuse>0 0 0 0</diffuse>
          <specular>0.4499999881 0.4499999881 0 1.0</specular>
        </material>
        <geometry>
          <mesh>
            <uri>model://snake_prickleback/meshes/salamander_body_11.dae</uri>
            <scale>1.0 1.0 1.0</scale>
          </mesh>
        </geometry>
      </visual>
    </link>
    <joint name="body_1_link" type="revolute">
      <parent>body_0_link</parent>
      <child>body_1_link</child>
      <pose>0.0 0.0 0.0 0.0 0.0 0.0</pose>
      <axis>
        <xyz>0 0 1.0</xyz>
        <limit>
          <lower>-0.5235987902</lower>
          <upper>0.5235987902</upper>
          <effort>10.0</effort>
          <velocity>10.0</velocity>
        </limit>
      </axis>
    </joint>
    <joint name="body_2_link" type="revolute">
      <parent>body_1_link</parent>
      <child>body_2_link</child>
      <pose>0.0 0.0 0.0 0.0 0.0 0.0</pose>
      <axis>
        <xyz>0 0 1.0</xyz>
        <limit>
          <lower>-0.5235987902</lower>
          <upper>0.5235987902</upper>
          <effort>10.0</effort>
          <velocity>10.0</velocity>
        </limit>
      </axis>
    </joint>
    <joint name="body_3_link" type="revolute">
      <parent>body_2_link</parent>
      <child>body_3_link</child>
      <pose>0.0 0.0 0.0 0.0 0.0 0.0</pose>
      <axis>
        <xyz>0 0 1.0</xyz>
        <limit>
          <lower>-0.5235987902</lower>
          <upper>0.5235987902</upper>
          <effort>10.0</effort>
          <velocity>10.0</velocity>
        </limit>
      </axis>
    </joint>
    <joint name="body_4_link" type="revolute">
      <parent>body_3_link</parent>
      <child>body_4_link</child>
      <pose>0.0 0.0 0.0 0.0 0.0 0.0</pose>
      <axis>
        <xyz>0 0 1.0</xyz>
        <limit>
          <lower>-0.5235987902</lower>
          <upper>0.5235987902</upper>
          <effort>10.0</effort>
          <velocity>10.0</velocity>
        </limit>
      </axis>
    </joint>
    <joint name="body_5_link" type="revolute">
      <parent>body_4_link</parent>
      <child>body_5_link</child>
      <pose>0.0 0.0 0.0 0.0 0.0 0.0</pose>
      <axis>
        <xyz>0 0 1.0</xyz>
        <limit>
          <lower>-0.5235987902</lower>
          <upper>0.5235987902</upper>
          <effort>10.0</effort>
          <velocity>10.0</velocity>
        </limit>
      </axis>
    </joint>
    <joint name="body_6_link" type="revolute">
      <parent>body_5_link</parent>
      <child>body_6_link</child>
      <pose>0.0 0.0 0.0 0.0 0.0 0.0</pose>
      <axis>
        <xyz>0 0 1.0</xyz>
        <limit>
          <lower>-0.5235987902</lower>
          <upper>0.5235987902</upper>
          <effort>10.0</effort>
          <velocity>10.0</velocity>
        </limit>
      </axis>
    </joint>
    <joint name="body_7_link" type="revolute">
      <parent>body_6_link</parent>
      <child>body_7_link</child>
      <pose>0.0 0.0 0.0 0.0 0.0 0.0</pose>
      <axis>
        <xyz>0 0 1.0</xyz>
        <limit>
          <lower>-0.5235987902</lower>
          <upper>0.5235987902</upper>
          <effort>10.0</effort>
          <velocity>10.0</velocity>
        </limit>
      </axis>
    </joint>
    <joint name="body_8_link" type="revolute">
      <parent>body_7_link</parent>
      <child>body_8_link</child>
      <pose>0.0 0.0 0.0 0.0 0.0 0.0</pose>
      <axis>
        <xyz>0 0 1.0</xyz>
        <limit>
          <lower>-0.5235987902</lower>
          <upper>0.5235987902</upper>
          <effort>10.0</effort>
          <velocity>10.0</velocity>
        </limit>
      </axis>
    </joint>
    <joint name="body_9_link" type="revolute">
      <parent>body_8_link</parent>
      <child>body_9_link</child>
      <pose>0.0 0.0 0.0 0.0 0.0 0.0</pose>
      <axis>
        <xyz>0 0 1.0</xyz>
        <limit>
          <lower>-0.5235987902</lower>
          <upper>0.5235987902</upper>
          <effort>10.0</effort>
          <velocity>10.0</velocity>
        </limit>
      </axis>
    </joint>
    <joint name="body_10_link" type="revolute">
      <parent>body_9_link</parent>
      <child>body_10_link</child>
      <pose>0.0 0.0 0.0 0.0 0.0 0.0</pose>
      <axis>
        <xyz>0 0 1.0</xyz>
        <limit>
          <lower>-0.5235987902</lower>
          <upper>0.5235987902</upper>
          <effort>10.0</effort>
          <velocity>10.0</velocity>
        </limit>
      </axis>
    </joint>
    <joint name="body_11_link" type="revolute">
      <parent>body_10_link</parent>
      <child>body_11_link</child>
      <pose>0.0 0.0 0.0 0.0 0.0 0.0</pose>
      <axis>
        <xyz>0 0 1.0</xyz>
        <limit>
          <lower>-0.5235987902</lower>
          <upper>0.5235987902</upper>
          <effort>10.0</effort>
          <velocity>10.0</velocity>
        </limit>
      </axis>
    </joint>
  </model>
</sdf>
