<?xml version="1.0"?>
<!-- created with Phobos 0.7 -->
<sdf version="1.5">
  <model name="penpoint_gunnel">
    <link name="penpoint_gunnel_version1_body_0_link">
      <pose>0 0 0 0 0 0</pose>
      <inertial>
        <mass>0.0018136475</mass>
        <inertia>
          <ixx>4.47e-08</ixx>
          <ixy>0</ixy>
          <ixz>-3e-10</ixz>
          <iyy>7.21e-08</iyy>
          <iyz>0</iyz>
          <izz>4.9e-08</izz>
        </inertia>
        <pose>0.0142741157 7.088e-07 0.0003077191 0 0 0</pose>
      </inertial>
      <collision name="penpoint_gunnel_version1_body_0_collision">
        <pose>0 0 0 0 0 0</pose>
        <geometry>
          <mesh>
            <uri>../meshes/obj/animat_penpoint_gunnel_version1_body_0_collision.obj</uri>
            <scale>1.0 1.0 1.0</scale>
          </mesh>
        </geometry>
      </collision>
      <visual name="penpoint_gunnel_version1_body_0_visual">
        <pose>0.0 0.0 0.0 0.0 -0.0 0.0</pose>
        <geometry>
          <mesh>
            <uri>../meshes/obj/animat_penpoint_gunnel_version1_body_0.obj</uri>
            <scale>1.0 1.0 1.0</scale>
          </mesh>
        </geometry>
      </visual>
    </link>
    <link name="penpoint_gunnel_version1_body_1_link">
      <pose>0.0234830007 0 8.30002e-05 0 0 0</pose>
      <inertial>
        <mass>0.0019372504</mass>
        <inertia>
          <ixx>6.7e-08</ixx>
          <ixy>0</ixy>
          <ixz>-3e-10</ixz>
          <iyy>7.27e-08</iyy>
          <iyz>0</iyz>
          <izz>3.63e-08</izz>
        </inertia>
        <pose>0.0028147604 9.8e-09 -6.27934e-05 0 0 0</pose>
      </inertial>
      <collision name="penpoint_gunnel_version1_body_1_collision">
        <pose>0 0 0 0 0 0</pose>
        <geometry>
          <mesh>
            <uri>../meshes/obj/animat_penpoint_gunnel_version1_body_1_collision.obj</uri>
            <scale>0.0058093667 0.0058093667 0.0106192827</scale>
          </mesh>
        </geometry>
      </collision>
      <visual name="penpoint_gunnel_version1_body_1_visual">
        <pose>0.0 0.0 0.0 0.0 -0.0 0.0</pose>
        <geometry>
          <mesh>
            <uri>../meshes/obj/animat_penpoint_gunnel_version1_body_1.obj</uri>
            <scale>0.0058093667 0.0058093667 0.0106192827</scale>
          </mesh>
        </geometry>
      </visual>
    </link>
    <link name="penpoint_gunnel_version1_body_2_link">
      <pose>0.0340503491 0 -6.30171e-05 0 0 0</pose>
      <inertial>
        <mass>0.0019352294</mass>
        <inertia>
          <ixx>7.18e-08</ixx>
          <ixy>0</ixy>
          <ixz>1e-10</ixz>
          <iyy>7.68e-08</iyy>
          <iyz>0</iyz>
          <izz>3.46e-08</izz>
        </inertia>
        <pose>0.0027197155 -1.387e-07 4.44222e-05 0 0 0</pose>
      </inertial>
      <collision name="penpoint_gunnel_version1_body_2_collision">
        <pose>0 0 0 0 0 0</pose>
        <geometry>
          <mesh>
            <uri>../meshes/obj/animat_penpoint_gunnel_version1_body_2_collision.obj</uri>
            <scale>0.0056794882 0.0056794882 0.0112404823</scale>
          </mesh>
        </geometry>
      </collision>
      <visual name="penpoint_gunnel_version1_body_2_visual">
        <pose>0.0 0.0 0.0 0.0 -0.0 0.0</pose>
        <geometry>
          <mesh>
            <uri>../meshes/obj/animat_penpoint_gunnel_version1_body_2.obj</uri>
            <scale>0.0056794882 0.0056794882 0.0112404823</scale>
          </mesh>
        </geometry>
      </visual>
    </link>
    <link name="penpoint_gunnel_version1_body_3_link">
      <pose>0.0446177013 0 2.68301e-05 0 0 0</pose>
      <inertial>
        <mass>0.0020846148</mass>
        <inertia>
          <ixx>8.05e-08</ixx>
          <ixy>0</ixy>
          <ixz>0</ixz>
          <iyy>8.48e-08</iyy>
          <iyz>0</iyz>
          <izz>3.99e-08</izz>
        </inertia>
        <pose>0.0026718155 1.64e-08 -1.24355e-05 0 0 0</pose>
      </inertial>
      <collision name="penpoint_gunnel_version1_body_3_collision">
        <pose>0 0 0 0 0 0</pose>
        <geometry>
          <mesh>
            <uri>../meshes/obj/animat_penpoint_gunnel_version1_body_3_collision.obj</uri>
            <scale>0.0059332252 0.0059332252 0.0114170313</scale>
          </mesh>
        </geometry>
      </collision>
      <visual name="penpoint_gunnel_version1_body_3_visual">
        <pose>0.0 0.0 0.0 0.0 -0.0 0.0</pose>
        <geometry>
          <mesh>
            <uri>../meshes/obj/animat_penpoint_gunnel_version1_body_3.obj</uri>
            <scale>0.0059332252 0.0059332252 0.0114170313</scale>
          </mesh>
        </geometry>
      </visual>
    </link>
    <link name="penpoint_gunnel_version1_body_4_link">
      <pose>0.0551850498 0 -8.9809e-06 0 0 0</pose>
      <inertial>
        <mass>0.0021577341</mass>
        <inertia>
          <ixx>8.45e-08</ixx>
          <ixy>0</ixy>
          <ixz>0</ixz>
          <iyy>8.88e-08</iyy>
          <iyz>0</iyz>
          <izz>4.21e-08</izz>
        </inertia>
        <pose>0.0025331527 -1.58e-08 8.3469e-06 0 0 0</pose>
      </inertial>
      <collision name="penpoint_gunnel_version1_body_4_collision">
        <pose>0 0 0 0 0 0</pose>
        <geometry>
          <mesh>
            <uri>../meshes/obj/animat_penpoint_gunnel_version1_body_4_collision.obj</uri>
            <scale>0.0061167479 0.0061167479 0.0114912987</scale>
          </mesh>
        </geometry>
      </collision>
      <visual name="penpoint_gunnel_version1_body_4_visual">
        <pose>0.0 0.0 0.0 0.0 -0.0 0.0</pose>
        <geometry>
          <mesh>
            <uri>../meshes/obj/animat_penpoint_gunnel_version1_body_4.obj</uri>
            <scale>0.0061167479 0.0061167479 0.0114912987</scale>
          </mesh>
        </geometry>
      </visual>
    </link>
    <link name="penpoint_gunnel_version1_body_5_link">
      <pose>0.0657524019 0 2.4343e-06 0 0 0</pose>
      <inertial>
        <mass>0.0021886852</mass>
        <inertia>
          <ixx>8.78e-08</ixx>
          <ixy>0</ixy>
          <ixz>0</ixz>
          <iyy>9.16e-08</iyy>
          <iyz>0</iyz>
          <izz>4.31e-08</izz>
        </inertia>
        <pose>0.002563633 5.58e-08 2.5484e-06 0 0 0</pose>
      </inertial>
      <collision name="penpoint_gunnel_version1_body_5_collision">
        <pose>0 0 0 0 0 0</pose>
        <geometry>
          <mesh>
            <uri>../meshes/obj/animat_penpoint_gunnel_version1_body_5_collision.obj</uri>
            <scale>0.0061315894 0.0061315894 0.0116031766</scale>
          </mesh>
        </geometry>
      </collision>
      <visual name="penpoint_gunnel_version1_body_5_visual">
        <pose>0.0 0.0 0.0 0.0 -0.0 0.0</pose>
        <geometry>
          <mesh>
            <uri>../meshes/obj/animat_penpoint_gunnel_version1_body_5.obj</uri>
            <scale>0.0061315894 0.0061315894 0.0116031766</scale>
          </mesh>
        </geometry>
      </visual>
    </link>
    <link name="penpoint_gunnel_version1_body_6_link">
      <pose>0.0763197467 0 -4.88e-07 0 0 0</pose>
      <inertial>
        <mass>0.0023416975</mass>
        <inertia>
          <ixx>9.83e-08</ixx>
          <ixy>0</ixy>
          <ixz>0</ixz>
          <iyy>1.035e-07</iyy>
          <iyz>0</iyz>
          <izz>4.75e-08</izz>
        </inertia>
        <pose>0.0026020035 -3.4e-08 4.907e-06 0 0 0</pose>
      </inertial>
      <collision name="penpoint_gunnel_version1_body_6_collision">
        <pose>0 0 0 0 0 0</pose>
        <geometry>
          <mesh>
            <uri>../meshes/obj/animat_penpoint_gunnel_version1_body_6_collision.obj</uri>
            <scale>0.0062388778 0.0062388778 0.011911869</scale>
          </mesh>
        </geometry>
      </collision>
      <visual name="penpoint_gunnel_version1_body_6_visual">
        <pose>0.0 0.0 0.0 0.0 -0.0 0.0</pose>
        <geometry>
          <mesh>
            <uri>../meshes/obj/animat_penpoint_gunnel_version1_body_6.obj</uri>
            <scale>0.0062388778 0.0062388778 0.011911869</scale>
          </mesh>
        </geometry>
      </visual>
    </link>
    <link name="penpoint_gunnel_version1_body_7_link">
      <pose>0.0868870988 0 3.98e-08 0 0 0</pose>
      <inertial>
        <mass>0.0022778335</mass>
        <inertia>
          <ixx>9.6e-08</ixx>
          <ixy>0</ixy>
          <ixz>0</ixz>
          <iyy>1.027e-07</iyy>
          <iyz>0</iyz>
          <izz>4.38e-08</izz>
        </inertia>
        <pose>0.0026523841 -1.78e-08 5.1997e-06 0 0 0</pose>
      </inertial>
      <collision name="penpoint_gunnel_version1_body_7_collision">
        <pose>0 0 0 0 0 0</pose>
        <geometry>
          <mesh>
            <uri>../meshes/obj/animat_penpoint_gunnel_version1_body_7_collision.obj</uri>
            <scale>0.0059719086 0.0059719086 0.0122533441</scale>
          </mesh>
        </geometry>
      </collision>
      <visual name="penpoint_gunnel_version1_body_7_visual">
        <pose>0.0 0.0 0.0 0.0 -0.0 0.0</pose>
        <geometry>
          <mesh>
            <uri>../meshes/obj/animat_penpoint_gunnel_version1_body_7.obj</uri>
            <scale>0.0059719086 0.0059719086 0.0122533441</scale>
          </mesh>
        </geometry>
      </visual>
    </link>
    <link name="penpoint_gunnel_version1_body_8_link">
      <pose>0.097454451 0 2.89e-08 0 0 0</pose>
      <inertial>
        <mass>0.0021033829</mass>
        <inertia>
          <ixx>8.51e-08</ixx>
          <ixy>0</ixy>
          <ixz>0</ixz>
          <iyy>9.19e-08</iyy>
          <iyz>0</iyz>
          <izz>3.83e-08</izz>
        </inertia>
        <pose>0.0028148219 -3.79e-08 5.5068e-06 0 0 0</pose>
      </inertial>
      <collision name="penpoint_gunnel_version1_body_8_collision">
        <pose>0 0 0 0 0 0</pose>
        <geometry>
          <mesh>
            <uri>../meshes/obj/animat_penpoint_gunnel_version1_body_8_collision.obj</uri>
            <scale>0.0056703091 0.0056703091 0.0119901299</scale>
          </mesh>
        </geometry>
      </collision>
      <visual name="penpoint_gunnel_version1_body_8_visual">
        <pose>0.0 0.0 0.0 0.0 -0.0 0.0</pose>
        <geometry>
          <mesh>
            <uri>../meshes/obj/animat_penpoint_gunnel_version1_body_8.obj</uri>
            <scale>0.0056703091 0.0056703091 0.0119901299</scale>
          </mesh>
        </geometry>
      </visual>
    </link>
    <link name="penpoint_gunnel_version1_body_9_link">
      <pose>0.1080218032 0 -1.53e-08 0 0 0</pose>
      <inertial>
        <mass>0.0021261488</mass>
        <inertia>
          <ixx>8.72e-08</ixx>
          <ixy>0</ixy>
          <ixz>0</ixz>
          <iyy>9.55e-08</iyy>
          <iyz>0</iyz>
          <izz>3.84e-08</izz>
        </inertia>
        <pose>0.002925545 1.2e-08 6.9993e-06 0 0 0</pose>
      </inertial>
      <collision name="penpoint_gunnel_version1_body_9_collision">
        <pose>0 0 0 0 0 0</pose>
        <geometry>
          <mesh>
            <uri>../meshes/obj/animat_penpoint_gunnel_version1_body_9_collision.obj</uri>
            <scale>0.0055528283 0.0055528283 0.0121796727</scale>
          </mesh>
        </geometry>
      </collision>
      <visual name="penpoint_gunnel_version1_body_9_visual">
        <pose>0.0 0.0 0.0 0.0 -0.0 0.0</pose>
        <geometry>
          <mesh>
            <uri>../meshes/obj/animat_penpoint_gunnel_version1_body_9.obj</uri>
            <scale>0.0055528283 0.0055528283 0.0121796727</scale>
          </mesh>
        </geometry>
      </visual>
    </link>
    <link name="penpoint_gunnel_version1_body_10_link">
      <pose>0.1185891479 0 0 0 0 0</pose>
      <inertial>
        <mass>0.0019431978</mass>
        <inertia>
          <ixx>7.53e-08</ixx>
          <ixy>0</ixy>
          <ixz>0</ixz>
          <iyy>8.43e-08</iyy>
          <iyz>0</iyz>
          <izz>3.29e-08</izz>
        </inertia>
        <pose>0.0030245632 -4.51e-08 7.4938e-06 0 0 0</pose>
      </inertial>
      <collision name="penpoint_gunnel_version1_body_10_collision">
        <pose>0 0 0 0 0 0</pose>
        <geometry>
          <mesh>
            <uri>../meshes/obj/animat_penpoint_gunnel_version1_body_10_collision.obj</uri>
            <scale>0.005223155 0.005223155 0.0120466948</scale>
          </mesh>
        </geometry>
      </collision>
      <visual name="penpoint_gunnel_version1_body_10_visual">
        <pose>0.0 0.0 0.0 0.0 -0.0 0.0</pose>
        <geometry>
          <mesh>
            <uri>../meshes/obj/animat_penpoint_gunnel_version1_body_10.obj</uri>
            <scale>0.005223155 0.005223155 0.0120466948</scale>
          </mesh>
        </geometry>
      </visual>
    </link>
    <link name="penpoint_gunnel_version1_body_11_link">
      <pose>0.1291565001 0 2.46e-08 0 0 0</pose>
      <inertial>
        <mass>0.0018203092</mass>
        <inertia>
          <ixx>6.81e-08</ixx>
          <ixy>0</ixy>
          <ixz>0</ixz>
          <iyy>7.81e-08</iyy>
          <iyz>0</iyz>
          <izz>2.95e-08</izz>
        </inertia>
        <pose>0.0032953622 2.65e-08 9.7296e-06 0 0 0</pose>
      </inertial>
      <collision name="penpoint_gunnel_version1_body_11_collision">
        <pose>0 0 0 0 0 0</pose>
        <geometry>
          <mesh>
            <uri>../meshes/obj/animat_penpoint_gunnel_version1_body_11_collision.obj</uri>
            <scale>0.004879415 0.004879415 0.0118367672</scale>
          </mesh>
        </geometry>
      </collision>
      <visual name="penpoint_gunnel_version1_body_11_visual">
        <pose>0.0 0.0 0.0 0.0 -0.0 0.0</pose>
        <geometry>
          <mesh>
            <uri>../meshes/obj/animat_penpoint_gunnel_version1_body_11.obj</uri>
            <scale>0.004879415 0.004879415 0.0118367672</scale>
          </mesh>
        </geometry>
      </visual>
    </link>
    <link name="penpoint_gunnel_version1_body_12_link">
      <pose>0.1397238523 0 -9.05e-08 0 0 0</pose>
      <inertial>
        <mass>0.0016329727</mass>
        <inertia>
          <ixx>6.1e-08</ixx>
          <ixy>0</ixy>
          <ixz>0</ixz>
          <iyy>7.19e-08</iyy>
          <iyz>0</iyz>
          <izz>2.42e-08</izz>
        </inertia>
        <pose>0.0034754127 -1.2e-08 1.55888e-05 0 0 0</pose>
      </inertial>
      <collision name="penpoint_gunnel_version1_body_12_collision">
        <pose>0 0 0 0 0 0</pose>
        <geometry>
          <mesh>
            <uri>../meshes/obj/animat_penpoint_gunnel_version1_body_12_collision.obj</uri>
            <scale>0.0043891668 0.0043891668 0.012040019</scale>
          </mesh>
        </geometry>
      </collision>
      <visual name="penpoint_gunnel_version1_body_12_visual">
        <pose>0.0 0.0 0.0 0.0 -0.0 0.0</pose>
        <geometry>
          <mesh>
            <uri>../meshes/obj/animat_penpoint_gunnel_version1_body_12.obj</uri>
            <scale>0.0043891668 0.0043891668 0.012040019</scale>
          </mesh>
        </geometry>
      </visual>
    </link>
    <link name="penpoint_gunnel_version1_body_13_link">
      <pose>0.1502912045 0 1.793e-07 0 0 0</pose>
      <inertial>
        <mass>0.0014169601</mass>
        <inertia>
          <ixx>5.28e-08</ixx>
          <ixy>0</ixy>
          <ixz>0</ixz>
          <iyy>6.26e-08</iyy>
          <iyz>0</iyz>
          <izz>1.89e-08</izz>
        </inertia>
        <pose>0.0037698001 -1.29e-08 2.08014e-05 0 0 0</pose>
      </inertial>
      <collision name="penpoint_gunnel_version1_body_13_collision">
        <pose>0 0 0 0 0 0</pose>
        <geometry>
          <mesh>
            <uri>../meshes/obj/animat_penpoint_gunnel_version1_body_13_collision.obj</uri>
            <scale>0.0037602782 0.0037602782 0.0122357607</scale>
          </mesh>
        </geometry>
      </collision>
      <visual name="penpoint_gunnel_version1_body_13_visual">
        <pose>0.0 0.0 0.0 0.0 -0.0 0.0</pose>
        <geometry>
          <mesh>
            <uri>../meshes/obj/animat_penpoint_gunnel_version1_body_13.obj</uri>
            <scale>0.0037602782 0.0037602782 0.0122357607</scale>
          </mesh>
        </geometry>
      </visual>
    </link>
    <link name="penpoint_gunnel_version1_body_14_link">
      <pose>0.1608585566 0 -4.95e-08 0 0 0</pose>
      <inertial>
        <mass>0.0012937181</mass>
        <inertia>
          <ixx>4.46e-08</ixx>
          <ixy>0</ixy>
          <ixz>0</ixz>
          <iyy>5.47e-08</iyy>
          <iyz>0</iyz>
          <izz>1.7e-08</izz>
        </inertia>
        <pose>0.0038085284 -1.33e-08 2.43291e-05 0 0 0</pose>
      </inertial>
      <collision name="penpoint_gunnel_version1_body_14_collision">
        <pose>0 0 0 0 0 0</pose>
        <geometry>
          <mesh>
            <uri>../meshes/obj/animat_penpoint_gunnel_version1_body_14_collision.obj</uri>
            <scale>0.0035510659 0.0035510659 0.0120280385</scale>
          </mesh>
        </geometry>
      </collision>
      <visual name="penpoint_gunnel_version1_body_14_visual">
        <pose>0.0 0.0 0.0 0.0 -0.0 0.0</pose>
        <geometry>
          <mesh>
            <uri>../meshes/obj/animat_penpoint_gunnel_version1_body_14.obj</uri>
            <scale>0.0035510659 0.0035510659 0.0120280385</scale>
          </mesh>
        </geometry>
      </visual>
    </link>
    <link name="penpoint_gunnel_version1_body_15_link">
      <pose>0.1714258939 0 -1.3398e-06 0 0 0</pose>
      <inertial>
        <mass>0.0009759172</mass>
        <inertia>
          <ixx>2.9e-08</ixx>
          <ixy>0</ixy>
          <ixz>0</ixz>
          <iyy>3.74e-08</iyy>
          <iyz>0</iyz>
          <izz>1.17e-08</izz>
        </inertia>
        <pose>0.0040236115 -6.7e-09 3.39376e-05 0 0 0</pose>
      </inertial>
      <collision name="penpoint_gunnel_version1_body_15_collision">
        <pose>0 0 0 0 0 0</pose>
        <geometry>
          <mesh>
            <uri>../meshes/obj/animat_penpoint_gunnel_version1_body_15_collision.obj</uri>
            <scale>0.0029498935 0.0029498935 0.0113754869</scale>
          </mesh>
        </geometry>
      </collision>
      <visual name="penpoint_gunnel_version1_body_15_visual">
        <pose>0.0 0.0 0.0 0.0 -0.0 0.0</pose>
        <geometry>
          <mesh>
            <uri>../meshes/obj/animat_penpoint_gunnel_version1_body_15.obj</uri>
            <scale>0.0029498935 0.0029498935 0.0113754869</scale>
          </mesh>
        </geometry>
      </visual>
    </link>
    <link name="penpoint_gunnel_version1_body_16_link">
      <pose>0.1819932461 0 7.7789e-06 0 0 0</pose>
      <inertial>
        <mass>0.0007313487</mass>
        <inertia>
          <ixx>1.88e-08</ixx>
          <ixy>0</ixy>
          <ixz>0</ixz>
          <iyy>2.51e-08</iyy>
          <iyz>0</iyz>
          <izz>8.1e-09</izz>
        </inertia>
        <pose>0.0042991787 -4.1e-09 3.32612e-05 0 0 0</pose>
      </inertial>
      <collision name="penpoint_gunnel_version1_body_16_collision">
        <pose>0 0 0 0 0 0</pose>
        <geometry>
          <mesh>
            <uri>../meshes/obj/animat_penpoint_gunnel_version1_body_16_collision.obj</uri>
            <scale>0.0023709536 0.0023709536 0.0106102824</scale>
          </mesh>
        </geometry>
      </collision>
      <visual name="penpoint_gunnel_version1_body_16_visual">
        <pose>0.0 0.0 0.0 0.0 -0.0 0.0</pose>
        <geometry>
          <mesh>
            <uri>../meshes/obj/animat_penpoint_gunnel_version1_body_16.obj</uri>
            <scale>0.0023709536 0.0023709536 0.0106102824</scale>
          </mesh>
        </geometry>
      </visual>
    </link>
    <link name="penpoint_gunnel_version1_body_17_link">
      <pose>0.1925605983 0 -3.0805e-05 0 0 0</pose>
      <inertial>
        <mass>0.0006135143</mass>
        <inertia>
          <ixx>1.35e-08</ixx>
          <ixy>0</ixy>
          <ixz>0</ixz>
          <iyy>1.87e-08</iyy>
          <iyz>0</iyz>
          <izz>6.4e-09</izz>
        </inertia>
        <pose>0.0044092541 -6.73e-08 5.23734e-05 0 0 0</pose>
      </inertial>
      <collision name="penpoint_gunnel_version1_body_17_collision">
        <pose>0 0 0 0 0 0</pose>
        <geometry>
          <mesh>
            <uri>../meshes/obj/animat_penpoint_gunnel_version1_body_17_collision.obj</uri>
            <scale>0.0020875931 0.0020875931 0.0099300146</scale>
          </mesh>
        </geometry>
      </collision>
      <visual name="penpoint_gunnel_version1_body_17_visual">
        <pose>0.0 0.0 0.0 0.0 -0.0 0.0</pose>
        <geometry>
          <mesh>
            <uri>../meshes/obj/animat_penpoint_gunnel_version1_body_17.obj</uri>
            <scale>0.0020875931 0.0020875931 0.0099300146</scale>
          </mesh>
        </geometry>
      </visual>
    </link>
    <link name="penpoint_gunnel_version1_body_18_link">
      <pose>0.2031279504 0 0.0001037117 0 0 0</pose>
      <inertial>
        <mass>0.0005353572</mass>
        <inertia>
          <ixx>9e-09</ixx>
          <ixy>0</ixy>
          <ixz>0</ixz>
          <iyy>1.36e-08</iyy>
          <iyz>0</iyz>
          <izz>5.7e-09</izz>
        </inertia>
        <pose>0.004327476 0 -2.20341e-05 0 0 0</pose>
      </inertial>
      <collision name="penpoint_gunnel_version1_body_18_collision">
        <pose>0 0 0 0 0 0</pose>
        <geometry>
          <mesh>
            <uri>../meshes/obj/animat_penpoint_gunnel_version1_body_18_collision.obj</uri>
            <scale>0.0020926595 0.0020926595 0.0088511705</scale>
          </mesh>
        </geometry>
      </collision>
      <visual name="penpoint_gunnel_version1_body_18_visual">
        <pose>0.0 0.0 0.0 0.0 -0.0 0.0</pose>
        <geometry>
          <mesh>
            <uri>../meshes/obj/animat_penpoint_gunnel_version1_body_18.obj</uri>
            <scale>0.0020926595 0.0020926595 0.0088511705</scale>
          </mesh>
        </geometry>
      </visual>
    </link>
    <link name="penpoint_gunnel_version1_body_19_link">
      <pose>0.2136953026 0 -0.0002777015 0 0 0</pose>
      <inertial>
        <mass>0.0003292181</mass>
        <inertia>
          <ixx>3.7e-09</ixx>
          <ixy>0</ixy>
          <ixz>0</ixz>
          <iyy>6.8e-09</iyy>
          <iyz>0</iyz>
          <izz>3.4e-09</izz>
        </inertia>
        <pose>0.004324913 -2.194e-07 0.0001242529 0 0 0</pose>
      </inertial>
      <collision name="penpoint_gunnel_version1_body_19_collision">
        <pose>0 0 0 0 0 0</pose>
        <geometry>
          <mesh>
            <uri>../meshes/obj/animat_penpoint_gunnel_version1_body_19_collision.obj</uri>
            <scale>0.0017609596 0.0017609596 0.0074294806</scale>
          </mesh>
        </geometry>
      </collision>
      <visual name="penpoint_gunnel_version1_body_19_visual">
        <pose>0.0 0.0 0.0 0.0 -0.0 0.0</pose>
        <geometry>
          <mesh>
            <uri>../meshes/obj/animat_penpoint_gunnel_version1_body_19.obj</uri>
            <scale>0.0017609596 0.0017609596 0.0074294806</scale>
          </mesh>
        </geometry>
      </visual>
    </link>
    <link name="penpoint_gunnel_version1_body_20_link">
      <pose>0.2242626548 0 0.0004603327 0 0 0</pose>
      <inertial>
        <mass>0.0001908415</mass>
        <inertia>
          <ixx>1.1e-09</ixx>
          <ixy>0</ixy>
          <ixz>3e-10</ixz>
          <iyy>2.8e-09</iyy>
          <iyz>0</iyz>
          <izz>1.9e-09</izz>
        </inertia>
        <pose>0.003966406 -9.229e-07 0.0005121595 0 0 0</pose>
      </inertial>
      <collision name="penpoint_gunnel_version1_body_20_collision">
        <pose>0 0 0 0 0 0</pose>
        <geometry>
          <mesh>
            <uri>../meshes/obj/animat_penpoint_gunnel_version1_body_20_collision.obj</uri>
            <scale>0.001295805 0.001295805 0.0058040619</scale>
          </mesh>
        </geometry>
      </collision>
      <visual name="penpoint_gunnel_version1_body_20_visual">
        <pose>0.0 0.0 0.0 0.0 -0.0 0.0</pose>
        <geometry>
          <mesh>
            <uri>../meshes/obj/animat_penpoint_gunnel_version1_body_20.obj</uri>
            <scale>0.001295805 0.001295805 0.0058040619</scale>
          </mesh>
        </geometry>
      </visual>
    </link>
    <joint name="penpoint_gunnel_version1_body_1_link" type="revolute">
      <parent>penpoint_gunnel_version1_body_0_link</parent>
      <child>penpoint_gunnel_version1_body_1_link</child>
      <pose>0.0 0.0 0.0 0.0 0.0 0.0</pose>
      <axis>
        <xyz>0 0 1.0</xyz>
        <limit>
          <lower>-0.5235987902</lower>
          <upper>0.5235987902</upper>
          <effort>10.0</effort>
          <velocity>10.0</velocity>
        </limit>
      </axis>
    </joint>
    <joint name="penpoint_gunnel_version1_body_2_link" type="revolute">
      <parent>penpoint_gunnel_version1_body_1_link</parent>
      <child>penpoint_gunnel_version1_body_2_link</child>
      <pose>0.0 0.0 0.0 0.0 0.0 0.0</pose>
      <axis>
        <xyz>0 0 1.0</xyz>
        <limit>
          <lower>-0.5235987902</lower>
          <upper>0.5235987902</upper>
          <effort>10.0</effort>
          <velocity>10.0</velocity>
        </limit>
      </axis>
    </joint>
    <joint name="penpoint_gunnel_version1_body_3_link" type="revolute">
      <parent>penpoint_gunnel_version1_body_2_link</parent>
      <child>penpoint_gunnel_version1_body_3_link</child>
      <pose>0.0 0.0 0.0 0.0 0.0 0.0</pose>
      <axis>
        <xyz>0 0 1.0</xyz>
        <limit>
          <lower>-0.5235987902</lower>
          <upper>0.5235987902</upper>
          <effort>10.0</effort>
          <velocity>10.0</velocity>
        </limit>
      </axis>
    </joint>
    <joint name="penpoint_gunnel_version1_body_4_link" type="revolute">
      <parent>penpoint_gunnel_version1_body_3_link</parent>
      <child>penpoint_gunnel_version1_body_4_link</child>
      <pose>0.0 0.0 0.0 0.0 0.0 0.0</pose>
      <axis>
        <xyz>0 0 1.0</xyz>
        <limit>
          <lower>-0.5235987902</lower>
          <upper>0.5235987902</upper>
          <effort>10.0</effort>
          <velocity>10.0</velocity>
        </limit>
      </axis>
    </joint>
    <joint name="penpoint_gunnel_version1_body_5_link" type="revolute">
      <parent>penpoint_gunnel_version1_body_4_link</parent>
      <child>penpoint_gunnel_version1_body_5_link</child>
      <pose>0.0 0.0 0.0 0.0 0.0 0.0</pose>
      <axis>
        <xyz>0 0 1.0</xyz>
        <limit>
          <lower>-0.5235987902</lower>
          <upper>0.5235987902</upper>
          <effort>10.0</effort>
          <velocity>10.0</velocity>
        </limit>
      </axis>
    </joint>
    <joint name="penpoint_gunnel_version1_body_6_link" type="revolute">
      <parent>penpoint_gunnel_version1_body_5_link</parent>
      <child>penpoint_gunnel_version1_body_6_link</child>
      <pose>0.0 0.0 0.0 0.0 0.0 0.0</pose>
      <axis>
        <xyz>0 0 1.0</xyz>
        <limit>
          <lower>-0.5235987902</lower>
          <upper>0.5235987902</upper>
          <effort>10.0</effort>
          <velocity>10.0</velocity>
        </limit>
      </axis>
    </joint>
    <joint name="penpoint_gunnel_version1_body_7_link" type="revolute">
      <parent>penpoint_gunnel_version1_body_6_link</parent>
      <child>penpoint_gunnel_version1_body_7_link</child>
      <pose>0.0 0.0 0.0 0.0 0.0 0.0</pose>
      <axis>
        <xyz>0 0 1.0</xyz>
        <limit>
          <lower>-0.5235987902</lower>
          <upper>0.5235987902</upper>
          <effort>10.0</effort>
          <velocity>10.0</velocity>
        </limit>
      </axis>
    </joint>
    <joint name="penpoint_gunnel_version1_body_8_link" type="revolute">
      <parent>penpoint_gunnel_version1_body_7_link</parent>
      <child>penpoint_gunnel_version1_body_8_link</child>
      <pose>0.0 0.0 0.0 0.0 0.0 0.0</pose>
      <axis>
        <xyz>0 0 1.0</xyz>
        <limit>
          <lower>-0.5235987902</lower>
          <upper>0.5235987902</upper>
          <effort>10.0</effort>
          <velocity>10.0</velocity>
        </limit>
      </axis>
    </joint>
    <joint name="penpoint_gunnel_version1_body_9_link" type="revolute">
      <parent>penpoint_gunnel_version1_body_8_link</parent>
      <child>penpoint_gunnel_version1_body_9_link</child>
      <pose>0.0 0.0 0.0 0.0 0.0 0.0</pose>
      <axis>
        <xyz>0 0 1.0</xyz>
        <limit>
          <lower>-0.5235987902</lower>
          <upper>0.5235987902</upper>
          <effort>10.0</effort>
          <velocity>10.0</velocity>
        </limit>
      </axis>
    </joint>
    <joint name="penpoint_gunnel_version1_body_10_link" type="revolute">
      <parent>penpoint_gunnel_version1_body_9_link</parent>
      <child>penpoint_gunnel_version1_body_10_link</child>
      <pose>0.0 0.0 0.0 0.0 0.0 0.0</pose>
      <axis>
        <xyz>0 0 1.0</xyz>
        <limit>
          <lower>-0.5235987902</lower>
          <upper>0.5235987902</upper>
          <effort>10.0</effort>
          <velocity>10.0</velocity>
        </limit>
      </axis>
    </joint>
    <joint name="penpoint_gunnel_version1_body_11_link" type="revolute">
      <parent>penpoint_gunnel_version1_body_10_link</parent>
      <child>penpoint_gunnel_version1_body_11_link</child>
      <pose>0.0 0.0 0.0 0.0 0.0 0.0</pose>
      <axis>
        <xyz>0 0 1.0</xyz>
        <limit>
          <lower>-0.5235987902</lower>
          <upper>0.5235987902</upper>
          <effort>10.0</effort>
          <velocity>10.0</velocity>
        </limit>
      </axis>
    </joint>
    <joint name="penpoint_gunnel_version1_body_12_link" type="revolute">
      <parent>penpoint_gunnel_version1_body_11_link</parent>
      <child>penpoint_gunnel_version1_body_12_link</child>
      <pose>0.0 0.0 0.0 0.0 0.0 0.0</pose>
      <axis>
        <xyz>0 0 1.0</xyz>
        <limit>
          <lower>-0.5235987902</lower>
          <upper>0.5235987902</upper>
          <effort>10.0</effort>
          <velocity>10.0</velocity>
        </limit>
      </axis>
    </joint>
    <joint name="penpoint_gunnel_version1_body_13_link" type="revolute">
      <parent>penpoint_gunnel_version1_body_12_link</parent>
      <child>penpoint_gunnel_version1_body_13_link</child>
      <pose>0.0 0.0 0.0 0.0 0.0 0.0</pose>
      <axis>
        <xyz>0 0 1.0</xyz>
        <limit>
          <lower>-0.5235987902</lower>
          <upper>0.5235987902</upper>
          <effort>10.0</effort>
          <velocity>10.0</velocity>
        </limit>
      </axis>
    </joint>
    <joint name="penpoint_gunnel_version1_body_14_link" type="revolute">
      <parent>penpoint_gunnel_version1_body_13_link</parent>
      <child>penpoint_gunnel_version1_body_14_link</child>
      <pose>0.0 0.0 0.0 0.0 0.0 0.0</pose>
      <axis>
        <xyz>0 0 1.0</xyz>
        <limit>
          <lower>-0.5235987902</lower>
          <upper>0.5235987902</upper>
          <effort>10.0</effort>
          <velocity>10.0</velocity>
        </limit>
      </axis>
    </joint>
    <joint name="penpoint_gunnel_version1_body_15_link" type="revolute">
      <parent>penpoint_gunnel_version1_body_14_link</parent>
      <child>penpoint_gunnel_version1_body_15_link</child>
      <pose>0.0 0.0 0.0 0.0 0.0 0.0</pose>
      <axis>
        <xyz>0 0 1.0</xyz>
        <limit>
          <lower>-0.5235987902</lower>
          <upper>0.5235987902</upper>
          <effort>10.0</effort>
          <velocity>10.0</velocity>
        </limit>
      </axis>
    </joint>
    <joint name="penpoint_gunnel_version1_body_16_link" type="revolute">
      <parent>penpoint_gunnel_version1_body_15_link</parent>
      <child>penpoint_gunnel_version1_body_16_link</child>
      <pose>0.0 0.0 0.0 0.0 0.0 0.0</pose>
      <axis>
        <xyz>0 0 1.0</xyz>
        <limit>
          <lower>-0.5235987902</lower>
          <upper>0.5235987902</upper>
          <effort>10.0</effort>
          <velocity>10.0</velocity>
        </limit>
      </axis>
    </joint>
    <joint name="penpoint_gunnel_version1_body_17_link" type="revolute">
      <parent>penpoint_gunnel_version1_body_16_link</parent>
      <child>penpoint_gunnel_version1_body_17_link</child>
      <pose>0.0 0.0 0.0 0.0 0.0 0.0</pose>
      <axis>
        <xyz>0 0 1.0</xyz>
        <limit>
          <lower>-0.5235987902</lower>
          <upper>0.5235987902</upper>
          <effort>10.0</effort>
          <velocity>10.0</velocity>
        </limit>
      </axis>
    </joint>
    <joint name="penpoint_gunnel_version1_body_18_link" type="revolute">
      <parent>penpoint_gunnel_version1_body_17_link</parent>
      <child>penpoint_gunnel_version1_body_18_link</child>
      <pose>0.0 0.0 0.0 0.0 0.0 0.0</pose>
      <axis>
        <xyz>0 0 1.0</xyz>
        <limit>
          <lower>-0.5235987902</lower>
          <upper>0.5235987902</upper>
          <effort>10.0</effort>
          <velocity>10.0</velocity>
        </limit>
      </axis>
    </joint>
    <joint name="penpoint_gunnel_version1_body_19_link" type="revolute">
      <parent>penpoint_gunnel_version1_body_18_link</parent>
      <child>penpoint_gunnel_version1_body_19_link</child>
      <pose>0.0 0.0 0.0 0.0 0.0 0.0</pose>
      <axis>
        <xyz>0 0 1.0</xyz>
        <limit>
          <lower>-0.5235987902</lower>
          <upper>0.5235987902</upper>
          <effort>10.0</effort>
          <velocity>10.0</velocity>
        </limit>
      </axis>
    </joint>
    <joint name="penpoint_gunnel_version1_body_20_link" type="revolute">
      <parent>penpoint_gunnel_version1_body_19_link</parent>
      <child>penpoint_gunnel_version1_body_20_link</child>
      <pose>0.0 0.0 0.0 0.0 0.0 0.0</pose>
      <axis>
        <xyz>0 0 1.0</xyz>
        <limit>
          <lower>-0.5235987902</lower>
          <upper>0.5235987902</upper>
          <effort>10.0</effort>
          <velocity>10.0</velocity>
        </limit>
      </axis>
    </joint>
  </model>
</sdf>
