<?xml version="1.0"?>
<!-- created with Phobos 0.7 -->
<sdf version="1.5">
  <model name="crescent_gunnel">
    <link name="crescent_gunnel_version0_body_0_link">
      <pose>0 0 0 0 0 0</pose>
      <inertial>
        <mass>0.000825494</mass>
        <inertia>
          <ixx>1.06e-08</ixx>
          <ixy>0</ixy>
          <ixz>0</ixz>
          <iyy>1.79e-08</iyy>
          <iyz>0</iyz>
          <izz>1.42e-08</izz>
        </inertia>
        <pose>0.0111169033 2.812e-07 0.0001181091 0 0 0</pose>
      </inertial>
      <collision name="crescent_gunnel_version0_body_0_collision">
        <pose>0 0 0 0 0 0</pose>
        <geometry>
          <mesh>
            <uri>../meshes/obj/animat_crescent_gunnel_version0_body_0_collision.001.obj</uri>
            <scale>1.0 1.0 1.0</scale>
          </mesh>
        </geometry>
      </collision>
      <visual name="crescent_gunnel_version0_body_0_visual">
        <pose>0.0 0.0 0.0 0.0 -0.0 0.0</pose>
        <geometry>
          <mesh>
            <uri>../meshes/obj/animat_crescent_gunnel_version0_body_0.obj</uri>
            <scale>1.0 1.0 1.0</scale>
          </mesh>
        </geometry>
      </visual>
    </link>
    <link name="crescent_gunnel_version0_body_1_link">
      <pose>0.0182850994 0 4.47509e-05 0 0 0</pose>
      <inertial>
        <mass>0.0007961419</mass>
        <inertia>
          <ixx>1.32e-08</ixx>
          <ixy>0</ixy>
          <ixz>0</ixz>
          <iyy>1.48e-08</iyy>
          <iyz>0</iyz>
          <izz>9.1e-09</izz>
        </inertia>
        <pose>0.0021612197 3.4e-09 -3.32064e-05 0 0 0</pose>
      </inertial>
      <collision name="crescent_gunnel_version0_body_1_collision">
        <pose>0 0 0 0 0 0</pose>
        <geometry>
          <mesh>
            <uri>../meshes/obj/animat_crescent_gunnel_version0_body_1_collision.001.obj</uri>
            <scale>0.0045409203 0.0045409203 0.0072059035</scale>
          </mesh>
        </geometry>
      </collision>
      <visual name="crescent_gunnel_version0_body_1_visual">
        <pose>0.0 0.0 0.0 0.0 -0.0 0.0</pose>
        <geometry>
          <mesh>
            <uri>../meshes/obj/animat_crescent_gunnel_version0_body_1.obj</uri>
            <scale>0.0045409203 0.0045409203 0.0072059035</scale>
          </mesh>
        </geometry>
      </visual>
    </link>
    <link name="crescent_gunnel_version0_body_2_link">
      <pose>0.0265133958 0 -3.72849e-05 0 0 0</pose>
      <inertial>
        <mass>0.0007243024</mass>
        <inertia>
          <ixx>1.16e-08</ixx>
          <ixy>0</ixy>
          <ixz>0</ixz>
          <iyy>1.29e-08</iyy>
          <iyz>0</iyz>
          <izz>7.7e-09</izz>
        </inertia>
        <pose>0.0021835882 6e-10 2.57447e-05 0 0 0</pose>
      </inertial>
      <collision name="crescent_gunnel_version0_body_2_collision">
        <pose>0 0 0 0 0 0</pose>
        <geometry>
          <mesh>
            <uri>../meshes/obj/animat_crescent_gunnel_version0_body_2_collision.001.obj</uri>
            <scale>0.0043151975 0.0043151975 0.0071265101</scale>
          </mesh>
        </geometry>
      </collision>
      <visual name="crescent_gunnel_version0_body_2_visual">
        <pose>0.0 0.0 0.0 0.0 -0.0 0.0</pose>
        <geometry>
          <mesh>
            <uri>../meshes/obj/animat_crescent_gunnel_version0_body_2.obj</uri>
            <scale>0.0043151975 0.0043151975 0.0071265101</scale>
          </mesh>
        </geometry>
      </visual>
    </link>
    <link name="crescent_gunnel_version0_body_3_link">
      <pose>0.0347416885 0 1.41341e-05 0 0 0</pose>
      <inertial>
        <mass>0.0007828775</mass>
        <inertia>
          <ixx>1.34e-08</ixx>
          <ixy>0</ixy>
          <ixz>0</ixz>
          <iyy>1.47e-08</iyy>
          <iyz>0</iyz>
          <izz>8.8e-09</izz>
        </inertia>
        <pose>0.0022261704 -1.04e-08 -6.6428e-06 0 0 0</pose>
      </inertial>
      <collision name="crescent_gunnel_version0_body_3_collision">
        <pose>0 0 0 0 0 0</pose>
        <geometry>
          <mesh>
            <uri>../meshes/obj/animat_crescent_gunnel_version0_body_3_collision.001.obj</uri>
            <scale>0.0044519305 0.0044519305 0.0072491765</scale>
          </mesh>
        </geometry>
      </collision>
      <visual name="crescent_gunnel_version0_body_3_visual">
        <pose>0.0 0.0 0.0 0.0 -0.0 0.0</pose>
        <geometry>
          <mesh>
            <uri>../meshes/obj/animat_crescent_gunnel_version0_body_3.obj</uri>
            <scale>0.0044519305 0.0044519305 0.0072491765</scale>
          </mesh>
        </geometry>
      </visual>
    </link>
    <link name="crescent_gunnel_version0_body_4_link">
      <pose>0.0429699868 0 -5.0224e-06 0 0 0</pose>
      <inertial>
        <mass>0.0008061575</mass>
        <inertia>
          <ixx>1.4e-08</ixx>
          <ixy>0</ixy>
          <ixz>0</ixz>
          <iyy>1.55e-08</iyy>
          <iyz>0</iyz>
          <izz>9e-09</izz>
        </inertia>
        <pose>0.00213366 -1.14e-08 4.6994e-06 0 0 0</pose>
      </inertial>
      <collision name="crescent_gunnel_version0_body_4_collision">
        <pose>0 0 0 0 0 0</pose>
        <geometry>
          <mesh>
            <uri>../meshes/obj/animat_crescent_gunnel_version0_body_4_collision.001.obj</uri>
            <scale>0.0045102239 0.0045102239 0.0074436069</scale>
          </mesh>
        </geometry>
      </collision>
      <visual name="crescent_gunnel_version0_body_4_visual">
        <pose>0.0 0.0 0.0 0.0 -0.0 0.0</pose>
        <geometry>
          <mesh>
            <uri>../meshes/obj/animat_crescent_gunnel_version0_body_4.obj</uri>
            <scale>0.0045102239 0.0045102239 0.0074436069</scale>
          </mesh>
        </geometry>
      </visual>
    </link>
    <link name="crescent_gunnel_version0_body_5_link">
      <pose>0.0511982813 0 1.3153e-06 0 0 0</pose>
      <inertial>
        <mass>0.0008043398</mass>
        <inertia>
          <ixx>1.44e-08</ixx>
          <ixy>0</ixy>
          <ixz>0</ixz>
          <iyy>1.58e-08</iyy>
          <iyz>0</iyz>
          <izz>8.9e-09</izz>
        </inertia>
        <pose>0.0022085235 -4.5e-09 1.4267e-06 0 0 0</pose>
      </inertial>
      <collision name="crescent_gunnel_version0_body_5_collision">
        <pose>0 0 0 0 0 0</pose>
        <geometry>
          <mesh>
            <uri>../meshes/obj/animat_crescent_gunnel_version0_body_5_collision.001.obj</uri>
            <scale>0.0044298768 0.0044298768 0.0075314641</scale>
          </mesh>
        </geometry>
      </collision>
      <visual name="crescent_gunnel_version0_body_5_visual">
        <pose>0.0 0.0 0.0 0.0 -0.0 0.0</pose>
        <geometry>
          <mesh>
            <uri>../meshes/obj/animat_crescent_gunnel_version0_body_5.obj</uri>
            <scale>0.0044298768 0.0044298768 0.0075314641</scale>
          </mesh>
        </geometry>
      </visual>
    </link>
    <link name="crescent_gunnel_version0_body_6_link">
      <pose>0.0594265759 0 -2.698e-07 0 0 0</pose>
      <inertial>
        <mass>0.0008443013</mass>
        <inertia>
          <ixx>1.57e-08</ixx>
          <ixy>0</ixy>
          <ixz>0</ixz>
          <iyy>1.74e-08</iyy>
          <iyz>0</iyz>
          <izz>9.5e-09</izz>
        </inertia>
        <pose>0.0022183359 4.29e-08 2.604e-06 0 0 0</pose>
      </inertial>
      <collision name="crescent_gunnel_version0_body_6_collision">
        <pose>0 0 0 0 0 0</pose>
        <geometry>
          <mesh>
            <uri>../meshes/obj/animat_crescent_gunnel_version0_body_6_collision.001.obj</uri>
            <scale>0.0044527054 0.0044527054 0.0077864528</scale>
          </mesh>
        </geometry>
      </collision>
      <visual name="crescent_gunnel_version0_body_6_visual">
        <pose>0.0 0.0 0.0 0.0 -0.0 0.0</pose>
        <geometry>
          <mesh>
            <uri>../meshes/obj/animat_crescent_gunnel_version0_body_6.obj</uri>
            <scale>0.0044527054 0.0044527054 0.0077864528</scale>
          </mesh>
        </geometry>
      </visual>
    </link>
    <link name="crescent_gunnel_version0_body_7_link">
      <pose>0.0676548705 0 1.66e-08 0 0 0</pose>
      <inertial>
        <mass>0.0008314426</mass>
        <inertia>
          <ixx>1.56e-08</ixx>
          <ixy>0</ixy>
          <ixz>0</ixz>
          <iyy>1.75e-08</iyy>
          <iyz>0</iyz>
          <izz>9e-09</izz>
        </inertia>
        <pose>0.0022815838 2e-08 2.87e-06 0 0 0</pose>
      </inertial>
      <collision name="crescent_gunnel_version0_body_7_collision">
        <pose>0 0 0 0 0 0</pose>
        <geometry>
          <mesh>
            <uri>../meshes/obj/animat_crescent_gunnel_version0_body_7_collision.001.obj</uri>
            <scale>0.0043032169 0.0043032169 0.0079433322</scale>
          </mesh>
        </geometry>
      </collision>
      <visual name="crescent_gunnel_version0_body_7_visual">
        <pose>0.0 0.0 0.0 0.0 -0.0 0.0</pose>
        <geometry>
          <mesh>
            <uri>../meshes/obj/animat_crescent_gunnel_version0_body_7.obj</uri>
            <scale>0.0043032169 0.0043032169 0.0079433322</scale>
          </mesh>
        </geometry>
      </visual>
    </link>
    <link name="crescent_gunnel_version0_body_8_link">
      <pose>0.075883165 0 2.1e-08 0 0 0</pose>
      <inertial>
        <mass>0.000791764</mass>
        <inertia>
          <ixx>1.48e-08</ixx>
          <ixy>0</ixy>
          <ixz>0</ixz>
          <iyy>1.69e-08</iyy>
          <iyz>0</iyz>
          <izz>8.1e-09</izz>
        </inertia>
        <pose>0.0023920015 5.7e-09 3.4152e-06 0 0 0</pose>
      </inertial>
      <collision name="crescent_gunnel_version0_body_8_collision">
        <pose>0 0 0 0 0 0</pose>
        <geometry>
          <mesh>
            <uri>../meshes/obj/animat_crescent_gunnel_version0_body_8_collision.001.obj</uri>
            <scale>0.0040659308 0.0040659308 0.0080484152</scale>
          </mesh>
        </geometry>
      </collision>
      <visual name="crescent_gunnel_version0_body_8_visual">
        <pose>0.0 0.0 0.0 0.0 -0.0 0.0</pose>
        <geometry>
          <mesh>
            <uri>../meshes/obj/animat_crescent_gunnel_version0_body_8.obj</uri>
            <scale>0.0040659308 0.0040659308 0.0080484152</scale>
          </mesh>
        </geometry>
      </visual>
    </link>
    <link name="crescent_gunnel_version0_body_9_link">
      <pose>0.0841114596 0 -1.32e-08 0 0 0</pose>
      <inertial>
        <mass>0.0007760612</mass>
        <inertia>
          <ixx>1.46e-08</ixx>
          <ixy>0</ixy>
          <ixz>0</ixz>
          <iyy>1.69e-08</iyy>
          <iyz>0</iyz>
          <izz>7.7e-09</izz>
        </inertia>
        <pose>0.0024762526 2.9e-09 4.2231e-06 0 0 0</pose>
      </inertial>
      <collision name="crescent_gunnel_version0_body_9_collision">
        <pose>0 0 0 0 0 0</pose>
        <geometry>
          <mesh>
            <uri>../meshes/obj/animat_crescent_gunnel_version0_body_9_collision.001.obj</uri>
            <scale>0.0039129257 0.0039129257 0.0081698895</scale>
          </mesh>
        </geometry>
      </collision>
      <visual name="crescent_gunnel_version0_body_9_visual">
        <pose>0.0 0.0 0.0 0.0 -0.0 0.0</pose>
        <geometry>
          <mesh>
            <uri>../meshes/obj/animat_crescent_gunnel_version0_body_9.obj</uri>
            <scale>0.0039129257 0.0039129257 0.0081698895</scale>
          </mesh>
        </geometry>
      </visual>
    </link>
    <link name="crescent_gunnel_version0_body_10_link">
      <pose>0.0923397541 0 4e-09 0 0 0</pose>
      <inertial>
        <mass>0.0007320913</mass>
        <inertia>
          <ixx>1.33e-08</ixx>
          <ixy>0</ixy>
          <ixz>0</ixz>
          <iyy>1.57e-08</iyy>
          <iyz>0</iyz>
          <izz>7e-09</izz>
        </inertia>
        <pose>0.0025525317 -8.4e-09 4.8619e-06 0 0 0</pose>
      </inertial>
      <collision name="crescent_gunnel_version0_body_10_collision">
        <pose>0 0 0 0 0 0</pose>
        <geometry>
          <mesh>
            <uri>../meshes/obj/animat_crescent_gunnel_version0_body_10_collision.001.obj</uri>
            <scale>0.0037176609 0.0037176609 0.0081620216</scale>
          </mesh>
        </geometry>
      </collision>
      <visual name="crescent_gunnel_version0_body_10_visual">
        <pose>0.0 0.0 0.0 0.0 -0.0 0.0</pose>
        <geometry>
          <mesh>
            <uri>../meshes/obj/animat_crescent_gunnel_version0_body_10.obj</uri>
            <scale>0.0037176609 0.0037176609 0.0081620216</scale>
          </mesh>
        </geometry>
      </visual>
    </link>
    <link name="crescent_gunnel_version0_body_11_link">
      <pose>0.1005680487 0 4.4e-09 0 0 0</pose>
      <inertial>
        <mass>0.0006613666</mass>
        <inertia>
          <ixx>1.12e-08</ixx>
          <ixy>0</ixy>
          <ixz>0</ixz>
          <iyy>1.37e-08</iyy>
          <iyz>0</iyz>
          <izz>6e-09</izz>
        </inertia>
        <pose>0.0026843844 5.6e-09 5.7838e-06 0 0 0</pose>
      </inertial>
      <collision name="crescent_gunnel_version0_body_11_collision">
        <pose>0 0 0 0 0 0</pose>
        <geometry>
          <mesh>
            <uri>../meshes/obj/animat_crescent_gunnel_version0_body_11_collision.001.obj</uri>
            <scale>0.003449142 0.003449142 0.0079735518</scale>
          </mesh>
        </geometry>
      </collision>
      <visual name="crescent_gunnel_version0_body_11_visual">
        <pose>0.0 0.0 0.0 0.0 -0.0 0.0</pose>
        <geometry>
          <mesh>
            <uri>../meshes/obj/animat_crescent_gunnel_version0_body_11.obj</uri>
            <scale>0.003449142 0.003449142 0.0079735518</scale>
          </mesh>
        </geometry>
      </visual>
    </link>
    <link name="crescent_gunnel_version0_body_12_link">
      <pose>0.1087963432 0 -1.78e-08 0 0 0</pose>
      <inertial>
        <mass>0.0005888624</mass>
        <inertia>
          <ixx>9.5e-09</ixx>
          <ixy>0</ixy>
          <ixz>0</ixz>
          <iyy>1.2e-08</iyy>
          <iyz>0</iyz>
          <izz>5e-09</izz>
        </inertia>
        <pose>0.0028533863 -4.5e-09 8.0222e-06 0 0 0</pose>
      </inertial>
      <collision name="crescent_gunnel_version0_body_12_collision">
        <pose>0 0 0 0 0 0</pose>
        <geometry>
          <mesh>
            <uri>../meshes/obj/animat_crescent_gunnel_version0_body_12_collision.001.obj</uri>
            <scale>0.003121376 0.003121376 0.0078519583</scale>
          </mesh>
        </geometry>
      </collision>
      <visual name="crescent_gunnel_version0_body_12_visual">
        <pose>0.0 0.0 0.0 0.0 -0.0 0.0</pose>
        <geometry>
          <mesh>
            <uri>../meshes/obj/animat_crescent_gunnel_version0_body_12.obj</uri>
            <scale>0.003121376 0.003121376 0.0078519583</scale>
          </mesh>
        </geometry>
      </visual>
    </link>
    <link name="crescent_gunnel_version0_body_13_link">
      <pose>0.1170246378 0 2.79e-08 0 0 0</pose>
      <inertial>
        <mass>0.0005021081</mass>
        <inertia>
          <ixx>7.6e-09</ixx>
          <ixy>0</ixy>
          <ixz>0</ixz>
          <iyy>1e-08</iyy>
          <iyz>0</iyz>
          <izz>3.9e-09</izz>
        </inertia>
        <pose>0.0029943066 3.5e-09 1.11302e-05 0 0 0</pose>
      </inertial>
      <collision name="crescent_gunnel_version0_body_13_collision">
        <pose>0 0 0 0 0 0</pose>
        <geometry>
          <mesh>
            <uri>../meshes/obj/animat_crescent_gunnel_version0_body_13_collision.001.obj</uri>
            <scale>0.0027296543 0.0027296543 0.0078131557</scale>
          </mesh>
        </geometry>
      </collision>
      <visual name="crescent_gunnel_version0_body_13_visual">
        <pose>0.0 0.0 0.0 0.0 -0.0 0.0</pose>
        <geometry>
          <mesh>
            <uri>../meshes/obj/animat_crescent_gunnel_version0_body_13.obj</uri>
            <scale>0.0027296543 0.0027296543 0.0078131557</scale>
          </mesh>
        </geometry>
      </visual>
    </link>
    <link name="crescent_gunnel_version0_body_14_link">
      <pose>0.1252529323 0 -9.1e-09 0 0 0</pose>
      <inertial>
        <mass>0.0004113464</mass>
        <inertia>
          <ixx>5.6e-09</ixx>
          <ixy>0</ixy>
          <ixz>0</ixz>
          <iyy>7.7e-09</iyy>
          <iyz>0</iyz>
          <izz>3e-09</izz>
        </inertia>
        <pose>0.0031466039 5e-10 1.39779e-05 0 0 0</pose>
      </inertial>
      <collision name="crescent_gunnel_version0_body_14_collision">
        <pose>0 0 0 0 0 0</pose>
        <geometry>
          <mesh>
            <uri>../meshes/obj/animat_crescent_gunnel_version0_body_14_collision.001.obj</uri>
            <scale>0.002353251 0.002353251 0.0075334311</scale>
          </mesh>
        </geometry>
      </collision>
      <visual name="crescent_gunnel_version0_body_14_visual">
        <pose>0.0 0.0 0.0 0.0 -0.0 0.0</pose>
        <geometry>
          <mesh>
            <uri>../meshes/obj/animat_crescent_gunnel_version0_body_14.obj</uri>
            <scale>0.002353251 0.002353251 0.0075334311</scale>
          </mesh>
        </geometry>
      </visual>
    </link>
    <link name="crescent_gunnel_version0_body_15_link">
      <pose>0.1334812343 0 -2.262e-07 0 0 0</pose>
      <inertial>
        <mass>0.0003413994</mass>
        <inertia>
          <ixx>4.1e-09</ixx>
          <ixy>0</ixy>
          <ixz>0</ixz>
          <iyy>5.8e-09</iyy>
          <iyz>0</iyz>
          <izz>2.4e-09</izz>
        </inertia>
        <pose>0.0032526106 3.5e-09 1.48841e-05 0 0 0</pose>
      </inertial>
      <collision name="crescent_gunnel_version0_body_15_collision">
        <pose>0 0 0 0 0 0</pose>
        <geometry>
          <mesh>
            <uri>../meshes/obj/animat_crescent_gunnel_version0_body_15_collision.001.obj</uri>
            <scale>0.0020675063 0.0020675063 0.0071589351</scale>
          </mesh>
        </geometry>
      </collision>
      <visual name="crescent_gunnel_version0_body_15_visual">
        <pose>0.0 0.0 0.0 0.0 -0.0 0.0</pose>
        <geometry>
          <mesh>
            <uri>../meshes/obj/animat_crescent_gunnel_version0_body_15.obj</uri>
            <scale>0.0020675063 0.0020675063 0.0071589351</scale>
          </mesh>
        </geometry>
      </visual>
    </link>
    <link name="crescent_gunnel_version0_body_16_link">
      <pose>0.1417095214 0 1.3531e-06 0 0 0</pose>
      <inertial>
        <mass>0.0002891406</mass>
        <inertia>
          <ixx>2.9e-09</ixx>
          <ixy>0</ixy>
          <ixz>0</ixz>
          <iyy>4.3e-09</iyy>
          <iyz>0</iyz>
          <izz>2e-09</izz>
        </inertia>
        <pose>0.0032877177 3.8e-09 1.17023e-05 0 0 0</pose>
      </inertial>
      <collision name="crescent_gunnel_version0_body_16_collision">
        <pose>0 0 0 0 0 0</pose>
        <geometry>
          <mesh>
            <uri>../meshes/obj/animat_crescent_gunnel_version0_body_16_collision.001.obj</uri>
            <scale>0.0019308329 0.0019308329 0.0065559149</scale>
          </mesh>
        </geometry>
      </collision>
      <visual name="crescent_gunnel_version0_body_16_visual">
        <pose>0.0 0.0 0.0 0.0 -0.0 0.0</pose>
        <geometry>
          <mesh>
            <uri>../meshes/obj/animat_crescent_gunnel_version0_body_16.obj</uri>
            <scale>0.0019308329 0.0019308329 0.0065559149</scale>
          </mesh>
        </geometry>
      </visual>
    </link>
    <link name="crescent_gunnel_version0_body_17_link">
      <pose>0.1499378234 0 -5.3965e-06 0 0 0</pose>
      <inertial>
        <mass>0.0002310995</mass>
        <inertia>
          <ixx>1.8e-09</ixx>
          <ixy>0</ixy>
          <ixz>0</ixz>
          <iyy>3e-09</iyy>
          <iyz>0</iyz>
          <izz>1.5e-09</izz>
        </inertia>
        <pose>0.0033273103 -1.18e-08 1.3133e-05 0 0 0</pose>
      </inertial>
      <collision name="crescent_gunnel_version0_body_17_collision">
        <pose>0 0 0 0 0 0</pose>
        <geometry>
          <mesh>
            <uri>../meshes/obj/animat_crescent_gunnel_version0_body_17_collision.001.obj</uri>
            <scale>0.0017700195 0.0017700195 0.0058298111</scale>
          </mesh>
        </geometry>
      </collision>
      <visual name="crescent_gunnel_version0_body_17_visual">
        <pose>0.0 0.0 0.0 0.0 -0.0 0.0</pose>
        <geometry>
          <mesh>
            <uri>../meshes/obj/animat_crescent_gunnel_version0_body_17.obj</uri>
            <scale>0.0017700195 0.0017700195 0.0058298111</scale>
          </mesh>
        </geometry>
      </visual>
    </link>
    <link name="crescent_gunnel_version0_body_18_link">
      <pose>0.1581661105 0 1.7264e-05 0 0 0</pose>
      <inertial>
        <mass>0.0001790714</mass>
        <inertia>
          <ixx>1e-09</ixx>
          <ixy>0</ixy>
          <ixz>0</ixz>
          <iyy>2e-09</iyy>
          <iyz>0</iyz>
          <izz>1.2e-09</izz>
        </inertia>
        <pose>0.0033252242 4.57e-08 -9.67e-08 0 0 0</pose>
      </inertial>
      <collision name="crescent_gunnel_version0_body_18_collision">
        <pose>0 0 0 0 0 0</pose>
        <geometry>
          <mesh>
            <uri>../meshes/obj/animat_crescent_gunnel_version0_body_18_collision.001.obj</uri>
            <scale>0.001637876 0.001637876 0.004999876</scale>
          </mesh>
        </geometry>
      </collision>
      <visual name="crescent_gunnel_version0_body_18_visual">
        <pose>0.0 0.0 0.0 0.0 -0.0 0.0</pose>
        <geometry>
          <mesh>
            <uri>../meshes/obj/animat_crescent_gunnel_version0_body_18.obj</uri>
            <scale>0.001637876 0.001637876 0.004999876</scale>
          </mesh>
        </geometry>
      </visual>
    </link>
    <link name="crescent_gunnel_version0_body_19_link">
      <pose>0.1663944125 0 -4.78027e-05 0 0 0</pose>
      <inertial>
        <mass>9.12754e-05</mass>
        <inertia>
          <ixx>3e-10</ixx>
          <ixy>0</ixy>
          <ixz>0</ixz>
          <iyy>8e-10</iyy>
          <iyz>0</iyz>
          <izz>6e-10</izz>
        </inertia>
        <pose>0.0032387376 -4.76e-08 3.12971e-05 0 0 0</pose>
      </inertial>
      <collision name="crescent_gunnel_version0_body_19_collision">
        <pose>0 0 0 0 0 0</pose>
        <geometry>
          <mesh>
            <uri>../meshes/obj/animat_crescent_gunnel_version0_body_19_collision.001.obj</uri>
            <scale>0.001265049 0.001265049 0.0041057467</scale>
          </mesh>
        </geometry>
      </collision>
      <visual name="crescent_gunnel_version0_body_19_visual">
        <pose>0.0 0.0 0.0 0.0 -0.0 0.0</pose>
        <geometry>
          <mesh>
            <uri>../meshes/obj/animat_crescent_gunnel_version0_body_19.obj</uri>
            <scale>0.001265049 0.001265049 0.0041057467</scale>
          </mesh>
        </geometry>
      </visual>
    </link>
    <link name="crescent_gunnel_version0_body_20_link">
      <pose>0.1746226996 0 7.06322e-05 0 0 0</pose>
      <inertial>
        <mass>2.29698e-05</mass>
        <inertia>
          <ixx>1e-10</ixx>
          <ixy>0</ixy>
          <ixz>0</ixz>
          <iyy>1e-10</iyy>
          <iyz>0</iyz>
          <izz>1e-10</izz>
        </inertia>
        <pose>0.0028029531 -2.289e-07 7.48927e-05 0 0 0</pose>
      </inertial>
      <collision name="crescent_gunnel_version0_body_20_collision">
        <pose>0 0 0 0 0 0</pose>
        <geometry>
          <mesh>
            <uri>../meshes/obj/animat_crescent_gunnel_version0_body_20_collision.001.obj</uri>
            <scale>0.0006264448 0.0006264448 0.0029065013</scale>
          </mesh>
        </geometry>
      </collision>
      <visual name="crescent_gunnel_version0_body_20_visual">
        <pose>0.0 0.0 0.0 0.0 -0.0 0.0</pose>
        <geometry>
          <mesh>
            <uri>../meshes/obj/animat_crescent_gunnel_version0_body_20.obj</uri>
            <scale>0.0006264448 0.0006264448 0.0029065013</scale>
          </mesh>
        </geometry>
      </visual>
    </link>
    <joint name="crescent_gunnel_version0_body_1_link" type="revolute">
      <parent>crescent_gunnel_version0_body_0_link</parent>
      <child>crescent_gunnel_version0_body_1_link</child>
      <pose>0.0 0.0 0.0 0.0 0.0 0.0</pose>
      <axis>
        <xyz>0 0 1.0</xyz>
        <limit>
          <lower>-0.5235987902</lower>
          <upper>0.5235987902</upper>
          <effort>10.0</effort>
          <velocity>10.0</velocity>
        </limit>
      </axis>
    </joint>
    <joint name="crescent_gunnel_version0_body_2_link" type="revolute">
      <parent>crescent_gunnel_version0_body_1_link</parent>
      <child>crescent_gunnel_version0_body_2_link</child>
      <pose>0.0 0.0 0.0 0.0 0.0 0.0</pose>
      <axis>
        <xyz>0 0 1.0</xyz>
        <limit>
          <lower>-0.5235987902</lower>
          <upper>0.5235987902</upper>
          <effort>10.0</effort>
          <velocity>10.0</velocity>
        </limit>
      </axis>
    </joint>
    <joint name="crescent_gunnel_version0_body_3_link" type="revolute">
      <parent>crescent_gunnel_version0_body_2_link</parent>
      <child>crescent_gunnel_version0_body_3_link</child>
      <pose>0.0 0.0 0.0 0.0 0.0 0.0</pose>
      <axis>
        <xyz>0 0 1.0</xyz>
        <limit>
          <lower>-0.5235987902</lower>
          <upper>0.5235987902</upper>
          <effort>10.0</effort>
          <velocity>10.0</velocity>
        </limit>
      </axis>
    </joint>
    <joint name="crescent_gunnel_version0_body_4_link" type="revolute">
      <parent>crescent_gunnel_version0_body_3_link</parent>
      <child>crescent_gunnel_version0_body_4_link</child>
      <pose>0.0 0.0 0.0 0.0 0.0 0.0</pose>
      <axis>
        <xyz>0 0 1.0</xyz>
        <limit>
          <lower>-0.5235987902</lower>
          <upper>0.5235987902</upper>
          <effort>10.0</effort>
          <velocity>10.0</velocity>
        </limit>
      </axis>
    </joint>
    <joint name="crescent_gunnel_version0_body_5_link" type="revolute">
      <parent>crescent_gunnel_version0_body_4_link</parent>
      <child>crescent_gunnel_version0_body_5_link</child>
      <pose>0.0 0.0 0.0 0.0 0.0 0.0</pose>
      <axis>
        <xyz>0 0 1.0</xyz>
        <limit>
          <lower>-0.5235987902</lower>
          <upper>0.5235987902</upper>
          <effort>10.0</effort>
          <velocity>10.0</velocity>
        </limit>
      </axis>
    </joint>
    <joint name="crescent_gunnel_version0_body_6_link" type="revolute">
      <parent>crescent_gunnel_version0_body_5_link</parent>
      <child>crescent_gunnel_version0_body_6_link</child>
      <pose>0.0 0.0 0.0 0.0 0.0 0.0</pose>
      <axis>
        <xyz>0 0 1.0</xyz>
        <limit>
          <lower>-0.5235987902</lower>
          <upper>0.5235987902</upper>
          <effort>10.0</effort>
          <velocity>10.0</velocity>
        </limit>
      </axis>
    </joint>
    <joint name="crescent_gunnel_version0_body_7_link" type="revolute">
      <parent>crescent_gunnel_version0_body_6_link</parent>
      <child>crescent_gunnel_version0_body_7_link</child>
      <pose>0.0 0.0 0.0 0.0 0.0 0.0</pose>
      <axis>
        <xyz>0 0 1.0</xyz>
        <limit>
          <lower>-0.5235987902</lower>
          <upper>0.5235987902</upper>
          <effort>10.0</effort>
          <velocity>10.0</velocity>
        </limit>
      </axis>
    </joint>
    <joint name="crescent_gunnel_version0_body_8_link" type="revolute">
      <parent>crescent_gunnel_version0_body_7_link</parent>
      <child>crescent_gunnel_version0_body_8_link</child>
      <pose>0.0 0.0 0.0 0.0 0.0 0.0</pose>
      <axis>
        <xyz>0 0 1.0</xyz>
        <limit>
          <lower>-0.5235987902</lower>
          <upper>0.5235987902</upper>
          <effort>10.0</effort>
          <velocity>10.0</velocity>
        </limit>
      </axis>
    </joint>
    <joint name="crescent_gunnel_version0_body_9_link" type="revolute">
      <parent>crescent_gunnel_version0_body_8_link</parent>
      <child>crescent_gunnel_version0_body_9_link</child>
      <pose>0.0 0.0 0.0 0.0 0.0 0.0</pose>
      <axis>
        <xyz>0 0 1.0</xyz>
        <limit>
          <lower>-0.5235987902</lower>
          <upper>0.5235987902</upper>
          <effort>10.0</effort>
          <velocity>10.0</velocity>
        </limit>
      </axis>
    </joint>
    <joint name="crescent_gunnel_version0_body_10_link" type="revolute">
      <parent>crescent_gunnel_version0_body_9_link</parent>
      <child>crescent_gunnel_version0_body_10_link</child>
      <pose>0.0 0.0 0.0 0.0 0.0 0.0</pose>
      <axis>
        <xyz>0 0 1.0</xyz>
        <limit>
          <lower>-0.5235987902</lower>
          <upper>0.5235987902</upper>
          <effort>10.0</effort>
          <velocity>10.0</velocity>
        </limit>
      </axis>
    </joint>
    <joint name="crescent_gunnel_version0_body_11_link" type="revolute">
      <parent>crescent_gunnel_version0_body_10_link</parent>
      <child>crescent_gunnel_version0_body_11_link</child>
      <pose>0.0 0.0 0.0 0.0 0.0 0.0</pose>
      <axis>
        <xyz>0 0 1.0</xyz>
        <limit>
          <lower>-0.5235987902</lower>
          <upper>0.5235987902</upper>
          <effort>10.0</effort>
          <velocity>10.0</velocity>
        </limit>
      </axis>
    </joint>
    <joint name="crescent_gunnel_version0_body_12_link" type="revolute">
      <parent>crescent_gunnel_version0_body_11_link</parent>
      <child>crescent_gunnel_version0_body_12_link</child>
      <pose>0.0 0.0 0.0 0.0 0.0 0.0</pose>
      <axis>
        <xyz>0 0 1.0</xyz>
        <limit>
          <lower>-0.5235987902</lower>
          <upper>0.5235987902</upper>
          <effort>10.0</effort>
          <velocity>10.0</velocity>
        </limit>
      </axis>
    </joint>
    <joint name="crescent_gunnel_version0_body_13_link" type="revolute">
      <parent>crescent_gunnel_version0_body_12_link</parent>
      <child>crescent_gunnel_version0_body_13_link</child>
      <pose>0.0 0.0 0.0 0.0 0.0 0.0</pose>
      <axis>
        <xyz>0 0 1.0</xyz>
        <limit>
          <lower>-0.5235987902</lower>
          <upper>0.5235987902</upper>
          <effort>10.0</effort>
          <velocity>10.0</velocity>
        </limit>
      </axis>
    </joint>
    <joint name="crescent_gunnel_version0_body_14_link" type="revolute">
      <parent>crescent_gunnel_version0_body_13_link</parent>
      <child>crescent_gunnel_version0_body_14_link</child>
      <pose>0.0 0.0 0.0 0.0 0.0 0.0</pose>
      <axis>
        <xyz>0 0 1.0</xyz>
        <limit>
          <lower>-0.5235987902</lower>
          <upper>0.5235987902</upper>
          <effort>10.0</effort>
          <velocity>10.0</velocity>
        </limit>
      </axis>
    </joint>
    <joint name="crescent_gunnel_version0_body_15_link" type="revolute">
      <parent>crescent_gunnel_version0_body_14_link</parent>
      <child>crescent_gunnel_version0_body_15_link</child>
      <pose>0.0 0.0 0.0 0.0 0.0 0.0</pose>
      <axis>
        <xyz>0 0 1.0</xyz>
        <limit>
          <lower>-0.5235987902</lower>
          <upper>0.5235987902</upper>
          <effort>10.0</effort>
          <velocity>10.0</velocity>
        </limit>
      </axis>
    </joint>
    <joint name="crescent_gunnel_version0_body_16_link" type="revolute">
      <parent>crescent_gunnel_version0_body_15_link</parent>
      <child>crescent_gunnel_version0_body_16_link</child>
      <pose>0.0 0.0 0.0 0.0 0.0 0.0</pose>
      <axis>
        <xyz>0 0 1.0</xyz>
        <limit>
          <lower>-0.5235987902</lower>
          <upper>0.5235987902</upper>
          <effort>10.0</effort>
          <velocity>10.0</velocity>
        </limit>
      </axis>
    </joint>
    <joint name="crescent_gunnel_version0_body_17_link" type="revolute">
      <parent>crescent_gunnel_version0_body_16_link</parent>
      <child>crescent_gunnel_version0_body_17_link</child>
      <pose>0.0 0.0 0.0 0.0 0.0 0.0</pose>
      <axis>
        <xyz>0 0 1.0</xyz>
        <limit>
          <lower>-0.5235987902</lower>
          <upper>0.5235987902</upper>
          <effort>10.0</effort>
          <velocity>10.0</velocity>
        </limit>
      </axis>
    </joint>
    <joint name="crescent_gunnel_version0_body_18_link" type="revolute">
      <parent>crescent_gunnel_version0_body_17_link</parent>
      <child>crescent_gunnel_version0_body_18_link</child>
      <pose>0.0 0.0 0.0 0.0 0.0 0.0</pose>
      <axis>
        <xyz>0 0 1.0</xyz>
        <limit>
          <lower>-0.5235987902</lower>
          <upper>0.5235987902</upper>
          <effort>10.0</effort>
          <velocity>10.0</velocity>
        </limit>
      </axis>
    </joint>
    <joint name="crescent_gunnel_version0_body_19_link" type="revolute">
      <parent>crescent_gunnel_version0_body_18_link</parent>
      <child>crescent_gunnel_version0_body_19_link</child>
      <pose>0.0 0.0 0.0 0.0 0.0 0.0</pose>
      <axis>
        <xyz>0 0 1.0</xyz>
        <limit>
          <lower>-0.5235987902</lower>
          <upper>0.5235987902</upper>
          <effort>10.0</effort>
          <velocity>10.0</velocity>
        </limit>
      </axis>
    </joint>
    <joint name="crescent_gunnel_version0_body_20_link" type="revolute">
      <parent>crescent_gunnel_version0_body_19_link</parent>
      <child>crescent_gunnel_version0_body_20_link</child>
      <pose>0.0 0.0 0.0 0.0 0.0 0.0</pose>
      <axis>
        <xyz>0 0 1.0</xyz>
        <limit>
          <lower>-0.5235987902</lower>
          <upper>0.5235987902</upper>
          <effort>10.0</effort>
          <velocity>10.0</velocity>
        </limit>
      </axis>
    </joint>
  </model>
</sdf>
