<?xml version="1.0"?>
<!-- created with Phobos 0.7 -->
<sdf version="1.5">
  <model name="northern_ronquil">
    <link name="northern_ronquil_version0_body_0_link">
      <pose>0 0 0 0 0 0</pose>
      <inertial>
        <mass>0.0009281609</mass>
        <inertia>
          <ixx>2.08e-08</ixx>
          <ixy>0</ixy>
          <ixz>2e-10</ixz>
          <iyy>1.74e-08</iyy>
          <iyz>0</iyz>
          <izz>1.72e-08</izz>
        </inertia>
        <pose>0.0089382418 5.407e-07 0.0001598552 0 0 0</pose>
      </inertial>
      <collision name="northern_ronquil_version0_body_0_collision">
        <pose>0 0 0 0 0 0</pose>
        <geometry>
          <mesh>
            <uri>../meshes/obj/animat_northern_ronquil_version0_body_0_collision.obj</uri>
            <scale>1.0 1.0 1.0</scale>
          </mesh>
        </geometry>
      </collision>
      <visual name="northern_ronquil_version0_body_0_visual">
        <pose>0.0 0.0 0.0 0.0 -0.0 0.0</pose>
        <geometry>
          <mesh>
            <uri>../meshes/obj/animat_northern_ronquil_version0_body_0.obj</uri>
            <scale>1.0 1.0 1.0</scale>
          </mesh>
        </geometry>
      </visual>
    </link>
    <link name="northern_ronquil_version0_body_1_link">
      <pose>0.0174163003 0 2.71471e-05 0 0 0</pose>
      <inertial>
        <mass>0.0015971831</mass>
        <inertia>
          <ixx>5.87e-08</ixx>
          <ixy>0</ixy>
          <ixz>0</ixz>
          <iyy>4.21e-08</iyy>
          <iyz>0</iyz>
          <izz>4.01e-08</izz>
        </inertia>
        <pose>-0.0007064119 1.098e-07 -1.47604e-05 0 0 0</pose>
      </inertial>
      <collision name="northern_ronquil_version0_body_1_collision">
        <pose>0 0 0 0 0 0</pose>
        <geometry>
          <mesh>
            <uri>../meshes/obj/animat_northern_ronquil_version0_body_1_collision.obj</uri>
            <scale>0.0087085366 0.0087085366 0.009126544</scale>
          </mesh>
        </geometry>
      </collision>
      <visual name="northern_ronquil_version0_body_1_visual">
        <pose>0.0 0.0 0.0 0.0 -0.0 0.0</pose>
        <geometry>
          <mesh>
            <uri>../meshes/obj/animat_northern_ronquil_version0_body_1.obj</uri>
            <scale>0.0087085366 0.0087085366 0.009126544</scale>
          </mesh>
        </geometry>
      </visual>
    </link>
    <link name="northern_ronquil_version0_body_2_link">
      <pose>0.0252536349 0 -2.14264e-05 0 0 0</pose>
      <inertial>
        <mass>0.0020223323</mass>
        <inertia>
          <ixx>8.59e-08</ixx>
          <ixy>0</ixy>
          <ixz>0</ixz>
          <iyy>5.99e-08</iyy>
          <iyz>0</iyz>
          <izz>5.98e-08</izz>
        </inertia>
        <pose>-0.0009196922 2.857e-07 1.03815e-05 0 0 0</pose>
      </inertial>
      <collision name="northern_ronquil_version0_body_2_collision">
        <pose>0 0 0 0 0 0</pose>
        <geometry>
          <mesh>
            <uri>../meshes/obj/animat_northern_ronquil_version0_body_2_collision.obj</uri>
            <scale>0.0094336271 0.0094336271 0.0097470284</scale>
          </mesh>
        </geometry>
      </collision>
      <visual name="northern_ronquil_version0_body_2_visual">
        <pose>0.0 0.0 0.0 0.0 -0.0 0.0</pose>
        <geometry>
          <mesh>
            <uri>../meshes/obj/animat_northern_ronquil_version0_body_2.obj</uri>
            <scale>0.0094336271 0.0094336271 0.0097470284</scale>
          </mesh>
        </geometry>
      </visual>
    </link>
    <link name="northern_ronquil_version0_body_3_link">
      <pose>0.0330909714 0 8.679e-06 0 0 0</pose>
      <inertial>
        <mass>0.0023141806</mass>
        <inertia>
          <ixx>1.062e-07</ixx>
          <ixy>0</ixy>
          <ixz>0</ixz>
          <iyy>7.69e-08</iyy>
          <iyz>0</iyz>
          <izz>7.11e-08</izz>
        </inertia>
        <pose>-0.0007613637 1.972e-07 -1.076e-07 0 0 0</pose>
      </inertial>
      <collision name="northern_ronquil_version0_body_3_collision">
        <pose>0 0 0 0 0 0</pose>
        <geometry>
          <mesh>
            <uri>../meshes/obj/animat_northern_ronquil_version0_body_3_collision.obj</uri>
            <scale>0.0095476508 0.0095476508 0.0103999376</scale>
          </mesh>
        </geometry>
      </collision>
      <visual name="northern_ronquil_version0_body_3_visual">
        <pose>0.0 0.0 0.0 0.0 -0.0 0.0</pose>
        <geometry>
          <mesh>
            <uri>../meshes/obj/animat_northern_ronquil_version0_body_3.obj</uri>
            <scale>0.0095476508 0.0095476508 0.0103999376</scale>
          </mesh>
        </geometry>
      </visual>
    </link>
    <link name="northern_ronquil_version0_body_4_link">
      <pose>0.0409283042 0 -3.0095e-06 0 0 0</pose>
      <inertial>
        <mass>0.0023825939</mass>
        <inertia>
          <ixx>1.138e-07</ixx>
          <ixy>0</ixy>
          <ixz>0</ixz>
          <iyy>8.66e-08</iyy>
          <iyz>0</iyz>
          <izz>6.87e-08</izz>
        </inertia>
        <pose>-0.0006431639 1.319e-07 3.8109e-06 0 0 0</pose>
      </inertial>
      <collision name="northern_ronquil_version0_body_4_collision">
        <pose>0 0 0 0 0 0</pose>
        <geometry>
          <mesh>
            <uri>../meshes/obj/animat_northern_ronquil_version0_body_4_collision.obj</uri>
            <scale>0.0092424154 0.0092424154 0.0110448003</scale>
          </mesh>
        </geometry>
      </collision>
      <visual name="northern_ronquil_version0_body_4_visual">
        <pose>0.0 0.0 0.0 0.0 -0.0 0.0</pose>
        <geometry>
          <mesh>
            <uri>../meshes/obj/animat_northern_ronquil_version0_body_4.obj</uri>
            <scale>0.0092424154 0.0092424154 0.0110448003</scale>
          </mesh>
        </geometry>
      </visual>
    </link>
    <link name="northern_ronquil_version0_body_5_link">
      <pose>0.0487656407 0 8.422e-07 0 0 0</pose>
      <inertial>
        <mass>0.0023368416</mass>
        <inertia>
          <ixx>1.137e-07</ixx>
          <ixy>0</ixy>
          <ixz>0</ixz>
          <iyy>8.88e-08</iyy>
          <iyz>0</iyz>
          <izz>6.41e-08</izz>
        </inertia>
        <pose>-0.0005540587 4.34e-08 1.9403e-06 0 0 0</pose>
      </inertial>
      <collision name="northern_ronquil_version0_body_5_collision">
        <pose>0 0 0 0 0 0</pose>
        <geometry>
          <mesh>
            <uri>../meshes/obj/animat_northern_ronquil_version0_body_5_collision.obj</uri>
            <scale>0.0089868903 0.0089868903 0.0113764405</scale>
          </mesh>
        </geometry>
      </collision>
      <visual name="northern_ronquil_version0_body_5_visual">
        <pose>0.0 0.0 0.0 0.0 -0.0 0.0</pose>
        <geometry>
          <mesh>
            <uri>../meshes/obj/animat_northern_ronquil_version0_body_5.obj</uri>
            <scale>0.0089868903 0.0089868903 0.0113764405</scale>
          </mesh>
        </geometry>
      </visual>
    </link>
    <link name="northern_ronquil_version0_body_6_link">
      <pose>0.0566029735 0 -1.743e-07 0 0 0</pose>
      <inertial>
        <mass>0.0023932143</mass>
        <inertia>
          <ixx>1.18e-07</ixx>
          <ixy>0</ixy>
          <ixz>0</ixz>
          <iyy>9.31e-08</iyy>
          <iyz>0</iyz>
          <izz>6.58e-08</izz>
        </inertia>
        <pose>-0.0004699454 8.07e-08 2.6345e-06 0 0 0</pose>
      </inertial>
      <collision name="northern_ronquil_version0_body_6_collision">
        <pose>0 0 0 0 0 0</pose>
        <geometry>
          <mesh>
            <uri>../meshes/obj/animat_northern_ronquil_version0_body_6_collision.obj</uri>
            <scale>0.0089580417 0.0089580417 0.0115234256</scale>
          </mesh>
        </geometry>
      </collision>
      <visual name="northern_ronquil_version0_body_6_visual">
        <pose>0.0 0.0 0.0 0.0 -0.0 0.0</pose>
        <geometry>
          <mesh>
            <uri>../meshes/obj/animat_northern_ronquil_version0_body_6.obj</uri>
            <scale>0.0089580417 0.0089580417 0.0115234256</scale>
          </mesh>
        </geometry>
      </visual>
    </link>
    <link name="northern_ronquil_version0_body_7_link">
      <pose>0.06444031 0 1.05e-08 0 0 0</pose>
      <inertial>
        <mass>0.0024388967</mass>
        <inertia>
          <ixx>1.191e-07</ixx>
          <ixy>0</ixy>
          <ixz>0</ixz>
          <iyy>9.55e-08</iyy>
          <iyz>0</iyz>
          <izz>6.61e-08</izz>
        </inertia>
        <pose>-0.0003178865 -1.304e-07 3.0171e-06 0 0 0</pose>
      </inertial>
      <collision name="northern_ronquil_version0_body_7_collision">
        <pose>0 0 0 0 0 0</pose>
        <geometry>
          <mesh>
            <uri>../meshes/obj/animat_northern_ronquil_version0_body_7_collision.obj</uri>
            <scale>0.0088440776 0.0088440776 0.0115616918</scale>
          </mesh>
        </geometry>
      </collision>
      <visual name="northern_ronquil_version0_body_7_visual">
        <pose>0.0 0.0 0.0 0.0 -0.0 0.0</pose>
        <geometry>
          <mesh>
            <uri>../meshes/obj/animat_northern_ronquil_version0_body_7.obj</uri>
            <scale>0.0088440776 0.0088440776 0.0115616918</scale>
          </mesh>
        </geometry>
      </visual>
    </link>
    <link name="northern_ronquil_version0_body_8_link">
      <pose>0.0722776428 0 1.27e-08 0 0 0</pose>
      <inertial>
        <mass>0.0023565228</mass>
        <inertia>
          <ixx>1.114e-07</ixx>
          <ixy>0</ixy>
          <ixz>0</ixz>
          <iyy>9.18e-08</iyy>
          <iyz>0</iyz>
          <izz>5.99e-08</izz>
        </inertia>
        <pose>-0.0001023412 -2.13e-08 3.3321e-06 0 0 0</pose>
      </inertial>
      <collision name="northern_ronquil_version0_body_8_collision">
        <pose>0 0 0 0 0 0</pose>
        <geometry>
          <mesh>
            <uri>../meshes/obj/animat_northern_ronquil_version0_body_8_collision.obj</uri>
            <scale>0.0084930658 0.0084930658 0.0115500689</scale>
          </mesh>
        </geometry>
      </collision>
      <visual name="northern_ronquil_version0_body_8_visual">
        <pose>0.0 0.0 0.0 0.0 -0.0 0.0</pose>
        <geometry>
          <mesh>
            <uri>../meshes/obj/animat_northern_ronquil_version0_body_8.obj</uri>
            <scale>0.0084930658 0.0084930658 0.0115500689</scale>
          </mesh>
        </geometry>
      </visual>
    </link>
    <link name="northern_ronquil_version0_body_9_link">
      <pose>0.080114983 0 -8.4e-09 0 0 0</pose>
      <inertial>
        <mass>0.002242966</mass>
        <inertia>
          <ixx>9.91e-08</ixx>
          <ixy>0</ixy>
          <ixz>0</ixz>
          <iyy>8.38e-08</iyy>
          <iyz>0</iyz>
          <izz>5.33e-08</izz>
        </inertia>
        <pose>0.0001581982 -4.16e-08 3.469e-06 0 0 0</pose>
      </inertial>
      <collision name="northern_ronquil_version0_body_9_collision">
        <pose>0 0 0 0 0 0</pose>
        <geometry>
          <mesh>
            <uri>../meshes/obj/animat_northern_ronquil_version0_body_9_collision.obj</uri>
            <scale>0.0081043839 0.0081043839 0.0113084912</scale>
          </mesh>
        </geometry>
      </collision>
      <visual name="northern_ronquil_version0_body_9_visual">
        <pose>0.0 0.0 0.0 0.0 -0.0 0.0</pose>
        <geometry>
          <mesh>
            <uri>../meshes/obj/animat_northern_ronquil_version0_body_9.obj</uri>
            <scale>0.0081043839 0.0081043839 0.0113084912</scale>
          </mesh>
        </geometry>
      </visual>
    </link>
    <link name="northern_ronquil_version0_body_10_link">
      <pose>0.0879523158 0 1e-10 0 0 0</pose>
      <inertial>
        <mass>0.0020139495</mass>
        <inertia>
          <ixx>8.16e-08</ixx>
          <ixy>0</ixy>
          <ixz>0</ixz>
          <iyy>7.15e-08</iyy>
          <iyz>0</iyz>
          <izz>4.22e-08</izz>
        </inertia>
        <pose>0.0004384145 7.18e-08 3.0298e-06 0 0 0</pose>
      </inertial>
      <collision name="northern_ronquil_version0_body_10_collision">
        <pose>0 0 0 0 0 0</pose>
        <geometry>
          <mesh>
            <uri>../meshes/obj/animat_northern_ronquil_version0_body_10_collision.obj</uri>
            <scale>0.0075166821 0.0075166821 0.0110358596</scale>
          </mesh>
        </geometry>
      </collision>
      <visual name="northern_ronquil_version0_body_10_visual">
        <pose>0.0 0.0 0.0 0.0 -0.0 0.0</pose>
        <geometry>
          <mesh>
            <uri>../meshes/obj/animat_northern_ronquil_version0_body_10.obj</uri>
            <scale>0.0075166821 0.0075166821 0.0110358596</scale>
          </mesh>
        </geometry>
      </visual>
    </link>
    <link name="northern_ronquil_version0_body_11_link">
      <pose>0.0957896486 0 1.11e-08 0 0 0</pose>
      <inertial>
        <mass>0.0018293522</mass>
        <inertia>
          <ixx>6.84e-08</ixx>
          <ixy>0</ixy>
          <ixz>0</ixz>
          <iyy>6.24e-08</iyy>
          <iyz>0</iyz>
          <izz>3.44e-08</izz>
        </inertia>
        <pose>0.0007962808 7.9e-09 3.6527e-06 0 0 0</pose>
      </inertial>
      <collision name="northern_ronquil_version0_body_11_collision">
        <pose>0 0 0 0 0 0</pose>
        <geometry>
          <mesh>
            <uri>../meshes/obj/animat_northern_ronquil_version0_body_11_collision.obj</uri>
            <scale>0.0069377422 0.0069377422 0.0108082294</scale>
          </mesh>
        </geometry>
      </collision>
      <visual name="northern_ronquil_version0_body_11_visual">
        <pose>0.0 0.0 0.0 0.0 -0.0 0.0</pose>
        <geometry>
          <mesh>
            <uri>../meshes/obj/animat_northern_ronquil_version0_body_11.obj</uri>
            <scale>0.0069377422 0.0069377422 0.0108082294</scale>
          </mesh>
        </geometry>
      </visual>
    </link>
    <link name="northern_ronquil_version0_body_12_link">
      <pose>0.1036269814 0 -3.31e-08 0 0 0</pose>
      <inertial>
        <mass>0.0015903565</mass>
        <inertia>
          <ixx>5.23e-08</ixx>
          <ixy>0</ixy>
          <ixz>0</ixz>
          <iyy>4.97e-08</iyy>
          <iyz>0</iyz>
          <izz>2.6e-08</izz>
        </inertia>
        <pose>0.0010441095 3.53e-08 3.1305e-06 0 0 0</pose>
      </inertial>
      <collision name="northern_ronquil_version0_body_12_collision">
        <pose>0 0 0 0 0 0</pose>
        <geometry>
          <mesh>
            <uri>../meshes/obj/animat_northern_ronquil_version0_body_12_collision.obj</uri>
            <scale>0.0063353777 0.0063353777 0.0103703737</scale>
          </mesh>
        </geometry>
      </collision>
      <visual name="northern_ronquil_version0_body_12_visual">
        <pose>0.0 0.0 0.0 0.0 -0.0 0.0</pose>
        <geometry>
          <mesh>
            <uri>../meshes/obj/animat_northern_ronquil_version0_body_12.obj</uri>
            <scale>0.0063353777 0.0063353777 0.0103703737</scale>
          </mesh>
        </geometry>
      </visual>
    </link>
    <link name="northern_ronquil_version0_body_13_link">
      <pose>0.1114643216 0 5.99e-08 0 0 0</pose>
      <inertial>
        <mass>0.0013267635</mass>
        <inertia>
          <ixx>3.84e-08</ixx>
          <ixy>0</ixy>
          <ixz>0</ixz>
          <iyy>3.81e-08</iyy>
          <iyz>0</iyz>
          <izz>1.88e-08</izz>
        </inertia>
        <pose>0.0014393553 6.48e-08 3.7326e-06 0 0 0</pose>
      </inertial>
      <collision name="northern_ronquil_version0_body_13_collision">
        <pose>0 0 0 0 0 0</pose>
        <geometry>
          <mesh>
            <uri>../meshes/obj/animat_northern_ronquil_version0_body_13_collision.obj</uri>
            <scale>0.0056351423 0.0056351423 0.0098426342</scale>
          </mesh>
        </geometry>
      </collision>
      <visual name="northern_ronquil_version0_body_13_visual">
        <pose>0.0 0.0 0.0 0.0 -0.0 0.0</pose>
        <geometry>
          <mesh>
            <uri>../meshes/obj/animat_northern_ronquil_version0_body_13.obj</uri>
            <scale>0.0056351423 0.0056351423 0.0098426342</scale>
          </mesh>
        </geometry>
      </visual>
    </link>
    <link name="northern_ronquil_version0_body_14_link">
      <pose>0.1193016544 0 -1.94e-08 0 0 0</pose>
      <inertial>
        <mass>0.0011587104</mass>
        <inertia>
          <ixx>2.92e-08</ixx>
          <ixy>0</ixy>
          <ixz>0</ixz>
          <iyy>3.07e-08</iyy>
          <iyz>0</iyz>
          <izz>1.46e-08</izz>
        </inertia>
        <pose>0.0016885623 -2.68e-08 3.8643e-06 0 0 0</pose>
      </inertial>
      <collision name="northern_ronquil_version0_body_14_collision">
        <pose>0 0 0 0 0 0</pose>
        <geometry>
          <mesh>
            <uri>../meshes/obj/animat_northern_ronquil_version0_body_14_collision.obj</uri>
            <scale>0.0050911903 0.0050911903 0.0094841123</scale>
          </mesh>
        </geometry>
      </collision>
      <visual name="northern_ronquil_version0_body_14_visual">
        <pose>0.0 0.0 0.0 0.0 -0.0 0.0</pose>
        <geometry>
          <mesh>
            <uri>../meshes/obj/animat_northern_ronquil_version0_body_14.obj</uri>
            <scale>0.0050911903 0.0050911903 0.0094841123</scale>
          </mesh>
        </geometry>
      </visual>
    </link>
    <link name="northern_ronquil_version0_body_15_link">
      <pose>0.1271389872 0 -4.808e-07 0 0 0</pose>
      <inertial>
        <mass>0.0008584064</mass>
        <inertia>
          <ixx>1.69e-08</ixx>
          <ixy>0</ixy>
          <ixz>0</ixz>
          <iyy>1.94e-08</iyy>
          <iyz>0</iyz>
          <izz>8.9e-09</izz>
        </inertia>
        <pose>0.002061516 -8.36e-08 4.8799e-06 0 0 0</pose>
      </inertial>
      <collision name="northern_ronquil_version0_body_15_collision">
        <pose>0 0 0 0 0 0</pose>
        <geometry>
          <mesh>
            <uri>../meshes/obj/animat_northern_ronquil_version0_body_15_collision.obj</uri>
            <scale>0.0042652488 0.0042652488 0.0086037517</scale>
          </mesh>
        </geometry>
      </collision>
      <visual name="northern_ronquil_version0_body_15_visual">
        <pose>0.0 0.0 0.0 0.0 -0.0 0.0</pose>
        <geometry>
          <mesh>
            <uri>../meshes/obj/animat_northern_ronquil_version0_body_15.obj</uri>
            <scale>0.0042652488 0.0042652488 0.0086037517</scale>
          </mesh>
        </geometry>
      </visual>
    </link>
    <link name="northern_ronquil_version0_body_16_link">
      <pose>0.1349763274 0 2.6894e-06 0 0 0</pose>
      <inertial>
        <mass>0.0005928205</mass>
        <inertia>
          <ixx>9.2e-09</ixx>
          <ixy>0</ixy>
          <ixz>0</ixz>
          <iyy>1.17e-08</iyy>
          <iyz>0</iyz>
          <izz>5e-09</izz>
        </inertia>
        <pose>0.0024349838 -2.12e-08 6.4158e-06 0 0 0</pose>
      </inertial>
      <collision name="northern_ronquil_version0_body_16_collision">
        <pose>0 0 0 0 0 0</pose>
        <geometry>
          <mesh>
            <uri>../meshes/obj/animat_northern_ronquil_version0_body_16_collision.obj</uri>
            <scale>0.0033353567 0.0033353567 0.0079347491</scale>
          </mesh>
        </geometry>
      </collision>
      <visual name="northern_ronquil_version0_body_16_visual">
        <pose>0.0 0.0 0.0 0.0 -0.0 0.0</pose>
        <geometry>
          <mesh>
            <uri>../meshes/obj/animat_northern_ronquil_version0_body_16.obj</uri>
            <scale>0.0033353567 0.0033353567 0.0079347491</scale>
          </mesh>
        </geometry>
      </visual>
    </link>
    <link name="northern_ronquil_version0_body_17_link">
      <pose>0.1428136528 0 -1.15215e-05 0 0 0</pose>
      <inertial>
        <mass>0.0003536852</mass>
        <inertia>
          <ixx>4e-09</ixx>
          <ixy>0</ixy>
          <ixz>0</ixz>
          <iyy>5.6e-09</iyy>
          <iyz>0</iyz>
          <izz>2.4e-09</izz>
        </inertia>
        <pose>0.0027690083 -1.86e-08 1.5815e-05 0 0 0</pose>
      </inertial>
      <collision name="northern_ronquil_version0_body_17_collision">
        <pose>0 0 0 0 0 0</pose>
        <geometry>
          <mesh>
            <uri>../meshes/obj/animat_northern_ronquil_version0_body_17_collision.obj</uri>
            <scale>0.0024164915 0.0024164915 0.007052958</scale>
          </mesh>
        </geometry>
      </collision>
      <visual name="northern_ronquil_version0_body_17_visual">
        <pose>0.0 0.0 0.0 0.0 -0.0 0.0</pose>
        <geometry>
          <mesh>
            <uri>../meshes/obj/animat_northern_ronquil_version0_body_17.obj</uri>
            <scale>0.0024164915 0.0024164915 0.007052958</scale>
          </mesh>
        </geometry>
      </visual>
    </link>
    <link name="northern_ronquil_version0_body_18_link">
      <pose>0.150650993 0 3.51311e-05 0 0 0</pose>
      <inertial>
        <mass>0.0002278755</mass>
        <inertia>
          <ixx>1.9e-09</ixx>
          <ixy>0</ixy>
          <ixz>0</ixz>
          <iyy>3e-09</iyy>
          <iyz>0</iyz>
          <izz>1.4e-09</izz>
        </inertia>
        <pose>0.0031771359 -2.62e-08 -2.4094e-06 0 0 0</pose>
      </inertial>
      <collision name="northern_ronquil_version0_body_18_collision">
        <pose>0 0 0 0 0 0</pose>
        <geometry>
          <mesh>
            <uri>../meshes/obj/animat_northern_ronquil_version0_body_18_collision.obj</uri>
            <scale>0.001798749 0.001798749 0.0059678555</scale>
          </mesh>
        </geometry>
      </collision>
      <visual name="northern_ronquil_version0_body_18_visual">
        <pose>0.0 0.0 0.0 0.0 -0.0 0.0</pose>
        <geometry>
          <mesh>
            <uri>../meshes/obj/animat_northern_ronquil_version0_body_18.obj</uri>
            <scale>0.001798749 0.001798749 0.0059678555</scale>
          </mesh>
        </geometry>
      </visual>
    </link>
    <link name="northern_ronquil_version0_body_19_link">
      <pose>0.1584883332 0 -7.4674e-05 0 0 0</pose>
      <inertial>
        <mass>0.0001899517</mass>
        <inertia>
          <ixx>1.6e-09</ixx>
          <ixy>0</ixy>
          <ixz>0</ixz>
          <iyy>2.5e-09</iyy>
          <iyz>0</iyz>
          <izz>1.1e-09</izz>
        </inertia>
        <pose>0.0034036341 -2.556e-07 3.91288e-05 0 0 0</pose>
      </inertial>
      <collision name="northern_ronquil_version0_body_19_collision">
        <pose>0 0 0 0 0 0</pose>
        <geometry>
          <mesh>
            <uri>../meshes/obj/animat_northern_ronquil_version0_body_19_collision.obj</uri>
            <scale>0.0014652014 0.0014652014 0.0057888031</scale>
          </mesh>
        </geometry>
      </collision>
      <visual name="northern_ronquil_version0_body_19_visual">
        <pose>0.0 0.0 0.0 0.0 -0.0 0.0</pose>
        <geometry>
          <mesh>
            <uri>../meshes/obj/animat_northern_ronquil_version0_body_19.obj</uri>
            <scale>0.0014652014 0.0014652014 0.0057888031</scale>
          </mesh>
        </geometry>
      </visual>
    </link>
    <link name="northern_ronquil_version0_body_20_link">
      <pose>0.1663256586 0 0.0001607723 0 0 0</pose>
      <inertial>
        <mass>0.0001449672</mass>
        <inertia>
          <ixx>9e-10</ixx>
          <ixy>0</ixy>
          <ixz>1e-10</ixz>
          <iyy>1.6e-09</iyy>
          <iyz>0</iyz>
          <izz>8e-10</izz>
        </inertia>
        <pose>0.0027982295 -5.513e-07 0.000264358 0 0 0</pose>
      </inertial>
      <collision name="northern_ronquil_version0_body_20_collision">
        <pose>0 0 0 0 0 0</pose>
        <geometry>
          <mesh>
            <uri>../meshes/obj/animat_northern_ronquil_version0_body_20_collision.obj</uri>
            <scale>0.0012868643 0.0012868643 0.005812943</scale>
          </mesh>
        </geometry>
      </collision>
      <visual name="northern_ronquil_version0_body_20_visual">
        <pose>0.0 0.0 0.0 0.0 -0.0 0.0</pose>
        <geometry>
          <mesh>
            <uri>../meshes/obj/animat_northern_ronquil_version0_body_20.obj</uri>
            <scale>0.0012868643 0.0012868643 0.005812943</scale>
          </mesh>
        </geometry>
      </visual>
    </link>
    <joint name="northern_ronquil_version0_body_1_link" type="revolute">
      <parent>northern_ronquil_version0_body_0_link</parent>
      <child>northern_ronquil_version0_body_1_link</child>
      <pose>0.0 0.0 0.0 0.0 0.0 0.0</pose>
      <axis>
        <xyz>0 0 1.0</xyz>
        <limit>
          <lower>-0.5235987902</lower>
          <upper>0.5235987902</upper>
          <effort>10.0</effort>
          <velocity>10.0</velocity>
        </limit>
      </axis>
    </joint>
    <joint name="northern_ronquil_version0_body_2_link" type="revolute">
      <parent>northern_ronquil_version0_body_1_link</parent>
      <child>northern_ronquil_version0_body_2_link</child>
      <pose>0.0 0.0 0.0 0.0 0.0 0.0</pose>
      <axis>
        <xyz>0 0 1.0</xyz>
        <limit>
          <lower>-0.5235987902</lower>
          <upper>0.5235987902</upper>
          <effort>10.0</effort>
          <velocity>10.0</velocity>
        </limit>
      </axis>
    </joint>
    <joint name="northern_ronquil_version0_body_3_link" type="revolute">
      <parent>northern_ronquil_version0_body_2_link</parent>
      <child>northern_ronquil_version0_body_3_link</child>
      <pose>0.0 0.0 0.0 0.0 0.0 0.0</pose>
      <axis>
        <xyz>0 0 1.0</xyz>
        <limit>
          <lower>-0.5235987902</lower>
          <upper>0.5235987902</upper>
          <effort>10.0</effort>
          <velocity>10.0</velocity>
        </limit>
      </axis>
    </joint>
    <joint name="northern_ronquil_version0_body_4_link" type="revolute">
      <parent>northern_ronquil_version0_body_3_link</parent>
      <child>northern_ronquil_version0_body_4_link</child>
      <pose>0.0 0.0 0.0 0.0 0.0 0.0</pose>
      <axis>
        <xyz>0 0 1.0</xyz>
        <limit>
          <lower>-0.5235987902</lower>
          <upper>0.5235987902</upper>
          <effort>10.0</effort>
          <velocity>10.0</velocity>
        </limit>
      </axis>
    </joint>
    <joint name="northern_ronquil_version0_body_5_link" type="revolute">
      <parent>northern_ronquil_version0_body_4_link</parent>
      <child>northern_ronquil_version0_body_5_link</child>
      <pose>0.0 0.0 0.0 0.0 0.0 0.0</pose>
      <axis>
        <xyz>0 0 1.0</xyz>
        <limit>
          <lower>-0.5235987902</lower>
          <upper>0.5235987902</upper>
          <effort>10.0</effort>
          <velocity>10.0</velocity>
        </limit>
      </axis>
    </joint>
    <joint name="northern_ronquil_version0_body_6_link" type="revolute">
      <parent>northern_ronquil_version0_body_5_link</parent>
      <child>northern_ronquil_version0_body_6_link</child>
      <pose>0.0 0.0 0.0 0.0 0.0 0.0</pose>
      <axis>
        <xyz>0 0 1.0</xyz>
        <limit>
          <lower>-0.5235987902</lower>
          <upper>0.5235987902</upper>
          <effort>10.0</effort>
          <velocity>10.0</velocity>
        </limit>
      </axis>
    </joint>
    <joint name="northern_ronquil_version0_body_7_link" type="revolute">
      <parent>northern_ronquil_version0_body_6_link</parent>
      <child>northern_ronquil_version0_body_7_link</child>
      <pose>0.0 0.0 0.0 0.0 0.0 0.0</pose>
      <axis>
        <xyz>0 0 1.0</xyz>
        <limit>
          <lower>-0.5235987902</lower>
          <upper>0.5235987902</upper>
          <effort>10.0</effort>
          <velocity>10.0</velocity>
        </limit>
      </axis>
    </joint>
    <joint name="northern_ronquil_version0_body_8_link" type="revolute">
      <parent>northern_ronquil_version0_body_7_link</parent>
      <child>northern_ronquil_version0_body_8_link</child>
      <pose>0.0 0.0 0.0 0.0 0.0 0.0</pose>
      <axis>
        <xyz>0 0 1.0</xyz>
        <limit>
          <lower>-0.5235987902</lower>
          <upper>0.5235987902</upper>
          <effort>10.0</effort>
          <velocity>10.0</velocity>
        </limit>
      </axis>
    </joint>
    <joint name="northern_ronquil_version0_body_9_link" type="revolute">
      <parent>northern_ronquil_version0_body_8_link</parent>
      <child>northern_ronquil_version0_body_9_link</child>
      <pose>0.0 0.0 0.0 0.0 0.0 0.0</pose>
      <axis>
        <xyz>0 0 1.0</xyz>
        <limit>
          <lower>-0.5235987902</lower>
          <upper>0.5235987902</upper>
          <effort>10.0</effort>
          <velocity>10.0</velocity>
        </limit>
      </axis>
    </joint>
    <joint name="northern_ronquil_version0_body_10_link" type="revolute">
      <parent>northern_ronquil_version0_body_9_link</parent>
      <child>northern_ronquil_version0_body_10_link</child>
      <pose>0.0 0.0 0.0 0.0 0.0 0.0</pose>
      <axis>
        <xyz>0 0 1.0</xyz>
        <limit>
          <lower>-0.5235987902</lower>
          <upper>0.5235987902</upper>
          <effort>10.0</effort>
          <velocity>10.0</velocity>
        </limit>
      </axis>
    </joint>
    <joint name="northern_ronquil_version0_body_11_link" type="revolute">
      <parent>northern_ronquil_version0_body_10_link</parent>
      <child>northern_ronquil_version0_body_11_link</child>
      <pose>0.0 0.0 0.0 0.0 0.0 0.0</pose>
      <axis>
        <xyz>0 0 1.0</xyz>
        <limit>
          <lower>-0.5235987902</lower>
          <upper>0.5235987902</upper>
          <effort>10.0</effort>
          <velocity>10.0</velocity>
        </limit>
      </axis>
    </joint>
    <joint name="northern_ronquil_version0_body_12_link" type="revolute">
      <parent>northern_ronquil_version0_body_11_link</parent>
      <child>northern_ronquil_version0_body_12_link</child>
      <pose>0.0 0.0 0.0 0.0 0.0 0.0</pose>
      <axis>
        <xyz>0 0 1.0</xyz>
        <limit>
          <lower>-0.5235987902</lower>
          <upper>0.5235987902</upper>
          <effort>10.0</effort>
          <velocity>10.0</velocity>
        </limit>
      </axis>
    </joint>
    <joint name="northern_ronquil_version0_body_13_link" type="revolute">
      <parent>northern_ronquil_version0_body_12_link</parent>
      <child>northern_ronquil_version0_body_13_link</child>
      <pose>0.0 0.0 0.0 0.0 0.0 0.0</pose>
      <axis>
        <xyz>0 0 1.0</xyz>
        <limit>
          <lower>-0.5235987902</lower>
          <upper>0.5235987902</upper>
          <effort>10.0</effort>
          <velocity>10.0</velocity>
        </limit>
      </axis>
    </joint>
    <joint name="northern_ronquil_version0_body_14_link" type="revolute">
      <parent>northern_ronquil_version0_body_13_link</parent>
      <child>northern_ronquil_version0_body_14_link</child>
      <pose>0.0 0.0 0.0 0.0 0.0 0.0</pose>
      <axis>
        <xyz>0 0 1.0</xyz>
        <limit>
          <lower>-0.5235987902</lower>
          <upper>0.5235987902</upper>
          <effort>10.0</effort>
          <velocity>10.0</velocity>
        </limit>
      </axis>
    </joint>
    <joint name="northern_ronquil_version0_body_15_link" type="revolute">
      <parent>northern_ronquil_version0_body_14_link</parent>
      <child>northern_ronquil_version0_body_15_link</child>
      <pose>0.0 0.0 0.0 0.0 0.0 0.0</pose>
      <axis>
        <xyz>0 0 1.0</xyz>
        <limit>
          <lower>-0.5235987902</lower>
          <upper>0.5235987902</upper>
          <effort>10.0</effort>
          <velocity>10.0</velocity>
        </limit>
      </axis>
    </joint>
    <joint name="northern_ronquil_version0_body_16_link" type="revolute">
      <parent>northern_ronquil_version0_body_15_link</parent>
      <child>northern_ronquil_version0_body_16_link</child>
      <pose>0.0 0.0 0.0 0.0 0.0 0.0</pose>
      <axis>
        <xyz>0 0 1.0</xyz>
        <limit>
          <lower>-0.5235987902</lower>
          <upper>0.5235987902</upper>
          <effort>10.0</effort>
          <velocity>10.0</velocity>
        </limit>
      </axis>
    </joint>
    <joint name="northern_ronquil_version0_body_17_link" type="revolute">
      <parent>northern_ronquil_version0_body_16_link</parent>
      <child>northern_ronquil_version0_body_17_link</child>
      <pose>0.0 0.0 0.0 0.0 0.0 0.0</pose>
      <axis>
        <xyz>0 0 1.0</xyz>
        <limit>
          <lower>-0.5235987902</lower>
          <upper>0.5235987902</upper>
          <effort>10.0</effort>
          <velocity>10.0</velocity>
        </limit>
      </axis>
    </joint>
    <joint name="northern_ronquil_version0_body_18_link" type="revolute">
      <parent>northern_ronquil_version0_body_17_link</parent>
      <child>northern_ronquil_version0_body_18_link</child>
      <pose>0.0 0.0 0.0 0.0 0.0 0.0</pose>
      <axis>
        <xyz>0 0 1.0</xyz>
        <limit>
          <lower>-0.5235987902</lower>
          <upper>0.5235987902</upper>
          <effort>10.0</effort>
          <velocity>10.0</velocity>
        </limit>
      </axis>
    </joint>
    <joint name="northern_ronquil_version0_body_19_link" type="revolute">
      <parent>northern_ronquil_version0_body_18_link</parent>
      <child>northern_ronquil_version0_body_19_link</child>
      <pose>0.0 0.0 0.0 0.0 0.0 0.0</pose>
      <axis>
        <xyz>0 0 1.0</xyz>
        <limit>
          <lower>-0.5235987902</lower>
          <upper>0.5235987902</upper>
          <effort>10.0</effort>
          <velocity>10.0</velocity>
        </limit>
      </axis>
    </joint>
    <joint name="northern_ronquil_version0_body_20_link" type="revolute">
      <parent>northern_ronquil_version0_body_19_link</parent>
      <child>northern_ronquil_version0_body_20_link</child>
      <pose>0.0 0.0 0.0 0.0 0.0 0.0</pose>
      <axis>
        <xyz>0 0 1.0</xyz>
        <limit>
          <lower>-0.5235987902</lower>
          <upper>0.5235987902</upper>
          <effort>10.0</effort>
          <velocity>10.0</velocity>
        </limit>
      </axis>
    </joint>
  </model>
</sdf>
