<?xml version="1.0"?>
<!-- created with Phobos 0.7 -->
<sdf version="1.5">
  <model name="slender_cockscomb">
    <link name="slender_cockscomb_version0_body_0_link">
      <pose>0 0 0 0 0 0</pose>
      <inertial>
        <mass>0.0003408206</mass>
        <inertia>
          <ixx>3.2e-09</ixx>
          <ixy>0</ixy>
          <ixz>0</ixz>
          <iyy>4.1e-09</iyy>
          <iyz>0</iyz>
          <izz>2.6e-09</izz>
        </inertia>
        <pose>0.0071608587 2.955e-07 8.18656e-05 0 0 0</pose>
      </inertial>
      <collision name="slender_cockscomb_version0_body_0_collision">
        <pose>0 0 0 0 0 0</pose>
        <geometry>
          <mesh>
            <uri>../meshes/obj/animat_slender_cockscomb_version0_body_0_collision.obj</uri>
            <scale>1.0 1.0 1.0</scale>
          </mesh>
        </geometry>
      </collision>
      <visual name="slender_cockscomb_version0_body_0_visual">
        <pose>0.0 0.0 0.0 0.0 -0.0 0.0</pose>
        <geometry>
          <mesh>
            <uri>../meshes/obj/animat_slender_cockscomb_version0_body_0.obj</uri>
            <scale>1.0 1.0 1.0</scale>
          </mesh>
        </geometry>
      </visual>
    </link>
    <link name="slender_cockscomb_version0_body_1_link">
      <pose>0.0120291999 0 1.91223e-05 0 0 0</pose>
      <inertial>
        <mass>0.0003848547</mass>
        <inertia>
          <ixx>5.5e-09</ixx>
          <ixy>0</ixy>
          <ixz>0</ixz>
          <iyy>5.3e-09</iyy>
          <iyz>0</iyz>
          <izz>2.3e-09</izz>
        </inertia>
        <pose>0.0009843949 -3.9e-08 -1.25107e-05 0 0 0</pose>
      </inertial>
      <collision name="slender_cockscomb_version0_body_1_collision">
        <pose>0 0 0 0 0 0</pose>
        <geometry>
          <mesh>
            <uri>../meshes/obj/animat_slender_cockscomb_version0_body_1_collision.obj</uri>
            <scale>0.0036716461 0.0036716461 0.0068108439</scale>
          </mesh>
        </geometry>
      </collision>
      <visual name="slender_cockscomb_version0_body_1_visual">
        <pose>0.0 0.0 0.0 0.0 -0.0 0.0</pose>
        <geometry>
          <mesh>
            <uri>../meshes/obj/animat_slender_cockscomb_version0_body_1.obj</uri>
            <scale>0.0036716461 0.0036716461 0.0068108439</scale>
          </mesh>
        </geometry>
      </visual>
    </link>
    <link name="slender_cockscomb_version0_body_2_link">
      <pose>0.01744234 0 -1.45103e-05 0 0 0</pose>
      <inertial>
        <mass>0.0004443804</mass>
        <inertia>
          <ixx>6.9e-09</ixx>
          <ixy>0</ixy>
          <ixz>0</ixz>
          <iyy>6.7e-09</iyy>
          <iyz>0</iyz>
          <izz>3e-09</izz>
        </inertia>
        <pose>0.0009126291 2.7e-08 1.07256e-05 0 0 0</pose>
      </inertial>
      <collision name="slender_cockscomb_version0_body_2_collision">
        <pose>0 0 0 0 0 0</pose>
        <geometry>
          <mesh>
            <uri>../meshes/obj/animat_slender_cockscomb_version0_body_2_collision.obj</uri>
            <scale>0.0038955212 0.0038955212 0.0072138309</scale>
          </mesh>
        </geometry>
      </collision>
      <visual name="slender_cockscomb_version0_body_2_visual">
        <pose>0.0 0.0 0.0 0.0 -0.0 0.0</pose>
        <geometry>
          <mesh>
            <uri>../meshes/obj/animat_slender_cockscomb_version0_body_2.obj</uri>
            <scale>0.0038955212 0.0038955212 0.0072138309</scale>
          </mesh>
        </geometry>
      </visual>
    </link>
    <link name="slender_cockscomb_version0_body_3_link">
      <pose>0.0228554793 0 6.2806e-06 0 0 0</pose>
      <inertial>
        <mass>0.0004467667</mass>
        <inertia>
          <ixx>7.1e-09</ixx>
          <ixy>0</ixy>
          <ixz>0</ixz>
          <iyy>6.8e-09</iyy>
          <iyz>0</iyz>
          <izz>3e-09</izz>
        </inertia>
        <pose>0.0008415096 -7.9e-09 -1.7429e-06 0 0 0</pose>
      </inertial>
      <collision name="slender_cockscomb_version0_body_3_collision">
        <pose>0 0 0 0 0 0</pose>
        <geometry>
          <mesh>
            <uri>../meshes/obj/animat_slender_cockscomb_version0_body_3_collision.obj</uri>
            <scale>0.0039255023 0.0039255023 0.0072824955</scale>
          </mesh>
        </geometry>
      </collision>
      <visual name="slender_cockscomb_version0_body_3_visual">
        <pose>0.0 0.0 0.0 0.0 -0.0 0.0</pose>
        <geometry>
          <mesh>
            <uri>../meshes/obj/animat_slender_cockscomb_version0_body_3.obj</uri>
            <scale>0.0039255023 0.0039255023 0.0072824955</scale>
          </mesh>
        </geometry>
      </visual>
    </link>
    <link name="slender_cockscomb_version0_body_4_link">
      <pose>0.0282686204 0 -2.1199e-06 0 0 0</pose>
      <inertial>
        <mass>0.0004455367</mass>
        <inertia>
          <ixx>7e-09</ixx>
          <ixy>0</ixy>
          <ixz>0</ixz>
          <iyy>6.7e-09</iyy>
          <iyz>0</iyz>
          <izz>3e-09</izz>
        </inertia>
        <pose>0.0008149556 -3e-09 2.6693e-06 0 0 0</pose>
      </inertial>
      <collision name="slender_cockscomb_version0_body_4_collision">
        <pose>0 0 0 0 0 0</pose>
        <geometry>
          <mesh>
            <uri>../meshes/obj/animat_slender_cockscomb_version0_body_4_collision.obj</uri>
            <scale>0.0039749146 0.0039749146 0.0072318912</scale>
          </mesh>
        </geometry>
      </collision>
      <visual name="slender_cockscomb_version0_body_4_visual">
        <pose>0.0 0.0 0.0 0.0 -0.0 0.0</pose>
        <geometry>
          <mesh>
            <uri>../meshes/obj/animat_slender_cockscomb_version0_body_4.obj</uri>
            <scale>0.0039749146 0.0039749146 0.0072318912</scale>
          </mesh>
        </geometry>
      </visual>
    </link>
    <link name="slender_cockscomb_version0_body_5_link">
      <pose>0.0336817615 0 5.604e-07 0 0 0</pose>
      <inertial>
        <mass>0.0004764273</mass>
        <inertia>
          <ixx>7.7e-09</ixx>
          <ixy>0</ixy>
          <ixz>0</ixz>
          <iyy>7.3e-09</iyy>
          <iyz>0</iyz>
          <izz>3.4e-09</izz>
        </inertia>
        <pose>0.0008212812 5.8e-08 1.8174e-06 0 0 0</pose>
      </inertial>
      <collision name="slender_cockscomb_version0_body_5_collision">
        <pose>0 0 0 0 0 0</pose>
        <geometry>
          <mesh>
            <uri>../meshes/obj/animat_slender_cockscomb_version0_body_5_collision.obj</uri>
            <scale>0.00410676 0.00410676 0.0072614551</scale>
          </mesh>
        </geometry>
      </collision>
      <visual name="slender_cockscomb_version0_body_5_visual">
        <pose>0.0 0.0 0.0 0.0 -0.0 0.0</pose>
        <geometry>
          <mesh>
            <uri>../meshes/obj/animat_slender_cockscomb_version0_body_5.obj</uri>
            <scale>0.00410676 0.00410676 0.0072614551</scale>
          </mesh>
        </geometry>
      </visual>
    </link>
    <link name="slender_cockscomb_version0_body_6_link">
      <pose>0.0390948988 0 -1.133e-07 0 0 0</pose>
      <inertial>
        <mass>0.0004897138</mass>
        <inertia>
          <ixx>8e-09</ixx>
          <ixy>0</ixy>
          <ixz>0</ixz>
          <iyy>7.8e-09</iyy>
          <iyz>0</iyz>
          <izz>3.4e-09</izz>
        </inertia>
        <pose>0.0008790456 -5.7e-08 2.6162e-06 0 0 0</pose>
      </inertial>
      <collision name="slender_cockscomb_version0_body_6_collision">
        <pose>0 0 0 0 0 0</pose>
        <geometry>
          <mesh>
            <uri>../meshes/obj/animat_slender_cockscomb_version0_body_6_collision.obj</uri>
            <scale>0.0040437579 0.0040437579 0.0074325204</scale>
          </mesh>
        </geometry>
      </collision>
      <visual name="slender_cockscomb_version0_body_6_visual">
        <pose>0.0 0.0 0.0 0.0 -0.0 0.0</pose>
        <geometry>
          <mesh>
            <uri>../meshes/obj/animat_slender_cockscomb_version0_body_6.obj</uri>
            <scale>0.0040437579 0.0040437579 0.0074325204</scale>
          </mesh>
        </geometry>
      </visual>
    </link>
    <link name="slender_cockscomb_version0_body_7_link">
      <pose>0.04450804 0 4.6e-09 0 0 0</pose>
      <inertial>
        <mass>0.0004702037</mass>
        <inertia>
          <ixx>7.8e-09</ixx>
          <ixy>0</ixy>
          <ixz>0</ixz>
          <iyy>7.7e-09</iyy>
          <iyz>0</iyz>
          <izz>3e-09</izz>
        </inertia>
        <pose>0.0010074228 -1.186e-07 3.2904e-06 0 0 0</pose>
      </inertial>
      <collision name="slender_cockscomb_version0_body_7_collision">
        <pose>0 0 0 0 0 0</pose>
        <geometry>
          <mesh>
            <uri>../meshes/obj/animat_slender_cockscomb_version0_body_7_collision.obj</uri>
            <scale>0.003803134 0.003803134 0.0075874329</scale>
          </mesh>
        </geometry>
      </collision>
      <visual name="slender_cockscomb_version0_body_7_visual">
        <pose>0.0 0.0 0.0 0.0 -0.0 0.0</pose>
        <geometry>
          <mesh>
            <uri>../meshes/obj/animat_slender_cockscomb_version0_body_7.obj</uri>
            <scale>0.003803134 0.003803134 0.0075874329</scale>
          </mesh>
        </geometry>
      </visual>
    </link>
    <link name="slender_cockscomb_version0_body_8_link">
      <pose>0.0499211811 0 9.6e-09 0 0 0</pose>
      <inertial>
        <mass>0.0004471494</mass>
        <inertia>
          <ixx>7.7e-09</ixx>
          <ixy>0</ixy>
          <ixz>0</ixz>
          <iyy>7.7e-09</iyy>
          <iyz>0</iyz>
          <izz>2.6e-09</izz>
        </inertia>
        <pose>0.0011135638 -4.5e-09 4.0341e-06 0 0 0</pose>
      </inertial>
      <collision name="slender_cockscomb_version0_body_8_collision">
        <pose>0 0 0 0 0 0</pose>
        <geometry>
          <mesh>
            <uri>../meshes/obj/animat_slender_cockscomb_version0_body_8_collision.obj</uri>
            <scale>0.0035386086 0.0035386086 0.0078772902</scale>
          </mesh>
        </geometry>
      </collision>
      <visual name="slender_cockscomb_version0_body_8_visual">
        <pose>0.0 0.0 0.0 0.0 -0.0 0.0</pose>
        <geometry>
          <mesh>
            <uri>../meshes/obj/animat_slender_cockscomb_version0_body_8.obj</uri>
            <scale>0.0035386086 0.0035386086 0.0078772902</scale>
          </mesh>
        </geometry>
      </visual>
    </link>
    <link name="slender_cockscomb_version0_body_9_link">
      <pose>0.0553343184 0 -5.1e-09 0 0 0</pose>
      <inertial>
        <mass>0.0004346635</mass>
        <inertia>
          <ixx>7.5e-09</ixx>
          <ixy>0</ixy>
          <ixz>0</ixz>
          <iyy>7.7e-09</iyy>
          <iyz>0</iyz>
          <izz>2.5e-09</izz>
        </inertia>
        <pose>0.0011895783 -9.3e-09 4.6893e-06 0 0 0</pose>
      </inertial>
      <collision name="slender_cockscomb_version0_body_9_collision">
        <pose>0 0 0 0 0 0</pose>
        <geometry>
          <mesh>
            <uri>../meshes/obj/animat_slender_cockscomb_version0_body_9_collision.obj</uri>
            <scale>0.0033971667 0.0033971667 0.0079982877</scale>
          </mesh>
        </geometry>
      </collision>
      <visual name="slender_cockscomb_version0_body_9_visual">
        <pose>0.0 0.0 0.0 0.0 -0.0 0.0</pose>
        <geometry>
          <mesh>
            <uri>../meshes/obj/animat_slender_cockscomb_version0_body_9.obj</uri>
            <scale>0.0033971667 0.0033971667 0.0079982877</scale>
          </mesh>
        </geometry>
      </visual>
    </link>
    <link name="slender_cockscomb_version0_body_10_link">
      <pose>0.0607474595 0 1.2e-09 0 0 0</pose>
      <inertial>
        <mass>0.0004340502</mass>
        <inertia>
          <ixx>7.5e-09</ixx>
          <ixy>0</ixy>
          <ixz>0</ixz>
          <iyy>7.8e-09</iyy>
          <iyz>0</iyz>
          <izz>2.4e-09</izz>
        </inertia>
        <pose>0.0012803526 -5e-09 5.9757e-06 0 0 0</pose>
      </inertial>
      <collision name="slender_cockscomb_version0_body_10_collision">
        <pose>0 0 0 0 0 0</pose>
        <geometry>
          <mesh>
            <uri>../meshes/obj/animat_slender_cockscomb_version0_body_10_collision.obj</uri>
            <scale>0.0032928586 0.0032928586 0.0080731511</scale>
          </mesh>
        </geometry>
      </collision>
      <visual name="slender_cockscomb_version0_body_10_visual">
        <pose>0.0 0.0 0.0 0.0 -0.0 0.0</pose>
        <geometry>
          <mesh>
            <uri>../meshes/obj/animat_slender_cockscomb_version0_body_10.obj</uri>
            <scale>0.0032928586 0.0032928586 0.0080731511</scale>
          </mesh>
        </geometry>
      </visual>
    </link>
    <link name="slender_cockscomb_version0_body_11_link">
      <pose>0.0661605969 0 9.2e-09 0 0 0</pose>
      <inertial>
        <mass>0.0003822427</mass>
        <inertia>
          <ixx>6.3e-09</ixx>
          <ixy>0</ixy>
          <ixz>0</ixz>
          <iyy>6.6e-09</iyy>
          <iyz>0</iyz>
          <izz>1.9e-09</izz>
        </inertia>
        <pose>0.0013615339 5e-09 6.8501e-06 0 0 0</pose>
      </inertial>
      <collision name="slender_cockscomb_version0_body_11_collision">
        <pose>0 0 0 0 0 0</pose>
        <geometry>
          <mesh>
            <uri>../meshes/obj/animat_slender_cockscomb_version0_body_11_collision.obj</uri>
            <scale>0.0030079484 0.0030079484 0.0080068707</scale>
          </mesh>
        </geometry>
      </collision>
      <visual name="slender_cockscomb_version0_body_11_visual">
        <pose>0.0 0.0 0.0 0.0 -0.0 0.0</pose>
        <geometry>
          <mesh>
            <uri>../meshes/obj/animat_slender_cockscomb_version0_body_11.obj</uri>
            <scale>0.0030079484 0.0030079484 0.0080068707</scale>
          </mesh>
        </geometry>
      </visual>
    </link>
    <link name="slender_cockscomb_version0_body_12_link">
      <pose>0.0715737417 0 -2.35e-08 0 0 0</pose>
      <inertial>
        <mass>0.000357131</mass>
        <inertia>
          <ixx>5.9e-09</ixx>
          <ixy>0</ixy>
          <ixz>0</ixz>
          <iyy>6.3e-09</iyy>
          <iyz>0</iyz>
          <izz>1.7e-09</izz>
        </inertia>
        <pose>0.0015216544 -1.85e-08 8.4169e-06 0 0 0</pose>
      </inertial>
      <collision name="slender_cockscomb_version0_body_12_collision">
        <pose>0 0 0 0 0 0</pose>
        <geometry>
          <mesh>
            <uri>../meshes/obj/animat_slender_cockscomb_version0_body_12_collision.obj</uri>
            <scale>0.0027900934 0.0027900934 0.0079914331</scale>
          </mesh>
        </geometry>
      </collision>
      <visual name="slender_cockscomb_version0_body_12_visual">
        <pose>0.0 0.0 0.0 0.0 -0.0 0.0</pose>
        <geometry>
          <mesh>
            <uri>../meshes/obj/animat_slender_cockscomb_version0_body_12.obj</uri>
            <scale>0.0027900934 0.0027900934 0.0079914331</scale>
          </mesh>
        </geometry>
      </visual>
    </link>
    <link name="slender_cockscomb_version0_body_13_link">
      <pose>0.0769868791 0 4.49e-08 0 0 0</pose>
      <inertial>
        <mass>0.0003495623</mass>
        <inertia>
          <ixx>5.6e-09</ixx>
          <ixy>0</ixy>
          <ixz>0</ixz>
          <iyy>6e-09</iyy>
          <iyz>0</iyz>
          <izz>1.6e-09</izz>
        </inertia>
        <pose>0.0015126616 -2.06e-08 9.2472e-06 0 0 0</pose>
      </inertial>
      <collision name="slender_cockscomb_version0_body_13_collision">
        <pose>0 0 0 0 0 0</pose>
        <geometry>
          <mesh>
            <uri>../meshes/obj/animat_slender_cockscomb_version0_body_13_collision.obj</uri>
            <scale>0.0027346611 0.0027346611 0.0080179572</scale>
          </mesh>
        </geometry>
      </collision>
      <visual name="slender_cockscomb_version0_body_13_visual">
        <pose>0.0 0.0 0.0 0.0 -0.0 0.0</pose>
        <geometry>
          <mesh>
            <uri>../meshes/obj/animat_slender_cockscomb_version0_body_13.obj</uri>
            <scale>0.0027346611 0.0027346611 0.0080179572</scale>
          </mesh>
        </geometry>
      </visual>
    </link>
    <link name="slender_cockscomb_version0_body_14_link">
      <pose>0.0824000165 0 -1.91e-08 0 0 0</pose>
      <inertial>
        <mass>0.0002975007</mass>
        <inertia>
          <ixx>4.3e-09</ixx>
          <ixy>0</ixy>
          <ixz>0</ixz>
          <iyy>4.7e-09</iyy>
          <iyz>0</iyz>
          <izz>1.2e-09</izz>
        </inertia>
        <pose>0.0016601905 -1.83e-08 1.02921e-05 0 0 0</pose>
      </inertial>
      <collision name="slender_cockscomb_version0_body_14_collision">
        <pose>0 0 0 0 0 0</pose>
        <geometry>
          <mesh>
            <uri>../meshes/obj/animat_slender_cockscomb_version0_body_14_collision.obj</uri>
            <scale>0.0024609566 0.0024609566 0.0076435804</scale>
          </mesh>
        </geometry>
      </collision>
      <visual name="slender_cockscomb_version0_body_14_visual">
        <pose>0.0 0.0 0.0 0.0 -0.0 0.0</pose>
        <geometry>
          <mesh>
            <uri>../meshes/obj/animat_slender_cockscomb_version0_body_14.obj</uri>
            <scale>0.0024609566 0.0024609566 0.0076435804</scale>
          </mesh>
        </geometry>
      </visual>
    </link>
    <link name="slender_cockscomb_version0_body_15_link">
      <pose>0.0878131613 0 -3.439e-07 0 0 0</pose>
      <inertial>
        <mass>0.0002752169</mass>
        <inertia>
          <ixx>3.8e-09</ixx>
          <ixy>0</ixy>
          <ixz>0</ixz>
          <iyy>4.2e-09</iyy>
          <iyz>0</iyz>
          <izz>1.1e-09</izz>
        </inertia>
        <pose>0.0017565489 -1.9e-08 1.33032e-05 0 0 0</pose>
      </inertial>
      <collision name="slender_cockscomb_version0_body_15_collision">
        <pose>0 0 0 0 0 0</pose>
        <geometry>
          <mesh>
            <uri>../meshes/obj/animat_slender_cockscomb_version0_body_15_collision.obj</uri>
            <scale>0.0022979379 0.0022979379 0.0074959397</scale>
          </mesh>
        </geometry>
      </collision>
      <visual name="slender_cockscomb_version0_body_15_visual">
        <pose>0.0 0.0 0.0 0.0 -0.0 0.0</pose>
        <geometry>
          <mesh>
            <uri>../meshes/obj/animat_slender_cockscomb_version0_body_15.obj</uri>
            <scale>0.0022979379 0.0022979379 0.0074959397</scale>
          </mesh>
        </geometry>
      </visual>
    </link>
    <link name="slender_cockscomb_version0_body_16_link">
      <pose>0.0932262987 0 2.1021e-06 0 0 0</pose>
      <inertial>
        <mass>0.0002158694</mass>
        <inertia>
          <ixx>2.6e-09</ixx>
          <ixy>0</ixy>
          <ixz>0</ixz>
          <iyy>3.1e-09</iyy>
          <iyz>0</iyz>
          <izz>8e-10</izz>
        </inertia>
        <pose>0.0018571317 -1.73e-08 1.70637e-05 0 0 0</pose>
      </inertial>
      <collision name="slender_cockscomb_version0_body_16_collision">
        <pose>0 0 0 0 0 0</pose>
        <geometry>
          <mesh>
            <uri>../meshes/obj/animat_slender_cockscomb_version0_body_16_collision.obj</uri>
            <scale>0.0019502044 0.0019502044 0.0072485805</scale>
          </mesh>
        </geometry>
      </collision>
      <visual name="slender_cockscomb_version0_body_16_visual">
        <pose>0.0 0.0 0.0 0.0 -0.0 0.0</pose>
        <geometry>
          <mesh>
            <uri>../meshes/obj/animat_slender_cockscomb_version0_body_16.obj</uri>
            <scale>0.0019502044 0.0019502044 0.0072485805</scale>
          </mesh>
        </geometry>
      </visual>
    </link>
    <link name="slender_cockscomb_version0_body_17_link">
      <pose>0.0986394435 0 -9.0208e-06 0 0 0</pose>
      <inertial>
        <mass>0.0001415292</mass>
        <inertia>
          <ixx>1.3e-09</ixx>
          <ixy>0</ixy>
          <ixz>0</ixz>
          <iyy>1.7e-09</iyy>
          <iyz>0</iyz>
          <izz>4e-10</izz>
        </inertia>
        <pose>0.002018474 -1.35e-08 2.85399e-05 0 0 0</pose>
      </inertial>
      <collision name="slender_cockscomb_version0_body_17_collision">
        <pose>0 0 0 0 0 0</pose>
        <geometry>
          <mesh>
            <uri>../meshes/obj/animat_slender_cockscomb_version0_body_17_collision.obj</uri>
            <scale>0.0014862418 0.0014862418 0.0066126585</scale>
          </mesh>
        </geometry>
      </collision>
      <visual name="slender_cockscomb_version0_body_17_visual">
        <pose>0.0 0.0 0.0 0.0 -0.0 0.0</pose>
        <geometry>
          <mesh>
            <uri>../meshes/obj/animat_slender_cockscomb_version0_body_17.obj</uri>
            <scale>0.0014862418 0.0014862418 0.0066126585</scale>
          </mesh>
        </geometry>
      </visual>
    </link>
    <link name="slender_cockscomb_version0_body_18_link">
      <pose>0.1040525809 0 2.95419e-05 0 0 0</pose>
      <inertial>
        <mass>8.30158e-05</mass>
        <inertia>
          <ixx>6e-10</ixx>
          <ixy>0</ixy>
          <ixz>0</ixz>
          <iyy>8e-10</iyy>
          <iyz>0</iyz>
          <izz>2e-10</izz>
        </inertia>
        <pose>0.0020914003 9.8e-09 1.25343e-05 0 0 0</pose>
      </inertial>
      <collision name="slender_cockscomb_version0_body_18_collision">
        <pose>0 0 0 0 0 0</pose>
        <geometry>
          <mesh>
            <uri>../meshes/obj/animat_slender_cockscomb_version0_body_18_collision.obj</uri>
            <scale>0.0010862947 0.0010862947 0.0057554245</scale>
          </mesh>
        </geometry>
      </collision>
      <visual name="slender_cockscomb_version0_body_18_visual">
        <pose>0.0 0.0 0.0 0.0 -0.0 0.0</pose>
        <geometry>
          <mesh>
            <uri>../meshes/obj/animat_slender_cockscomb_version0_body_18.obj</uri>
            <scale>0.0010862947 0.0010862947 0.0057554245</scale>
          </mesh>
        </geometry>
      </visual>
    </link>
    <link name="slender_cockscomb_version0_body_19_link">
      <pose>0.1094657183 0 -0.0001175951 0 0 0</pose>
      <inertial>
        <mass>3.06941e-05</mass>
        <inertia>
          <ixx>1e-10</ixx>
          <ixy>0</ixy>
          <ixz>0</ixz>
          <iyy>2e-10</iyy>
          <iyz>0</iyz>
          <izz>1e-10</izz>
        </inertia>
        <pose>0.0020392463 -1.766e-07 6.46791e-05 0 0 0</pose>
      </inertial>
      <collision name="slender_cockscomb_version0_body_19_collision">
        <pose>0 0 0 0 0 0</pose>
        <geometry>
          <mesh>
            <uri>../meshes/obj/animat_slender_cockscomb_version0_body_19_collision.obj</uri>
            <scale>0.0006899834 0.0006899834 0.0042596459</scale>
          </mesh>
        </geometry>
      </collision>
      <visual name="slender_cockscomb_version0_body_19_visual">
        <pose>0.0 0.0 0.0 0.0 -0.0 0.0</pose>
        <geometry>
          <mesh>
            <uri>../meshes/obj/animat_slender_cockscomb_version0_body_19.obj</uri>
            <scale>0.0006899834 0.0006899834 0.0042596459</scale>
          </mesh>
        </geometry>
      </visual>
    </link>
    <link name="slender_cockscomb_version0_body_20_link">
      <pose>0.1148788631 0 0.0001435585 0 0 0</pose>
      <inertial>
        <mass>1.03583e-05</mass>
        <inertia>
          <ixx>1e-10</ixx>
          <ixy>0</ixy>
          <ixz>0</ixz>
          <iyy>1e-10</iyy>
          <iyz>0</iyz>
          <izz>1e-10</izz>
        </inertia>
        <pose>0.0018933564 -1.817e-07 9.65868e-05 0 0 0</pose>
      </inertial>
      <collision name="slender_cockscomb_version0_body_20_collision">
        <pose>0 0 0 0 0 0</pose>
        <geometry>
          <mesh>
            <uri>../meshes/obj/animat_slender_cockscomb_version0_body_20_collision.obj</uri>
            <scale>0.0004627109 0.0004627109 0.0021467805</scale>
          </mesh>
        </geometry>
      </collision>
      <visual name="slender_cockscomb_version0_body_20_visual">
        <pose>0.0 0.0 0.0 0.0 -0.0 0.0</pose>
        <geometry>
          <mesh>
            <uri>../meshes/obj/animat_slender_cockscomb_version0_body_20.obj</uri>
            <scale>0.0004627109 0.0004627109 0.0021467805</scale>
          </mesh>
        </geometry>
      </visual>
    </link>
    <joint name="slender_cockscomb_version0_body_1_link" type="revolute">
      <parent>slender_cockscomb_version0_body_0_link</parent>
      <child>slender_cockscomb_version0_body_1_link</child>
      <pose>0.0 0.0 0.0 0.0 0.0 0.0</pose>
      <axis>
        <xyz>0 0 1.0</xyz>
        <limit>
          <lower>-0.5235987902</lower>
          <upper>0.5235987902</upper>
          <effort>10.0</effort>
          <velocity>10.0</velocity>
        </limit>
      </axis>
    </joint>
    <joint name="slender_cockscomb_version0_body_2_link" type="revolute">
      <parent>slender_cockscomb_version0_body_1_link</parent>
      <child>slender_cockscomb_version0_body_2_link</child>
      <pose>0.0 0.0 0.0 0.0 0.0 0.0</pose>
      <axis>
        <xyz>0 0 1.0</xyz>
        <limit>
          <lower>-0.5235987902</lower>
          <upper>0.5235987902</upper>
          <effort>10.0</effort>
          <velocity>10.0</velocity>
        </limit>
      </axis>
    </joint>
    <joint name="slender_cockscomb_version0_body_3_link" type="revolute">
      <parent>slender_cockscomb_version0_body_2_link</parent>
      <child>slender_cockscomb_version0_body_3_link</child>
      <pose>0.0 0.0 0.0 0.0 0.0 0.0</pose>
      <axis>
        <xyz>0 0 1.0</xyz>
        <limit>
          <lower>-0.5235987902</lower>
          <upper>0.5235987902</upper>
          <effort>10.0</effort>
          <velocity>10.0</velocity>
        </limit>
      </axis>
    </joint>
    <joint name="slender_cockscomb_version0_body_4_link" type="revolute">
      <parent>slender_cockscomb_version0_body_3_link</parent>
      <child>slender_cockscomb_version0_body_4_link</child>
      <pose>0.0 0.0 0.0 0.0 0.0 0.0</pose>
      <axis>
        <xyz>0 0 1.0</xyz>
        <limit>
          <lower>-0.5235987902</lower>
          <upper>0.5235987902</upper>
          <effort>10.0</effort>
          <velocity>10.0</velocity>
        </limit>
      </axis>
    </joint>
    <joint name="slender_cockscomb_version0_body_5_link" type="revolute">
      <parent>slender_cockscomb_version0_body_4_link</parent>
      <child>slender_cockscomb_version0_body_5_link</child>
      <pose>0.0 0.0 0.0 0.0 0.0 0.0</pose>
      <axis>
        <xyz>0 0 1.0</xyz>
        <limit>
          <lower>-0.5235987902</lower>
          <upper>0.5235987902</upper>
          <effort>10.0</effort>
          <velocity>10.0</velocity>
        </limit>
      </axis>
    </joint>
    <joint name="slender_cockscomb_version0_body_6_link" type="revolute">
      <parent>slender_cockscomb_version0_body_5_link</parent>
      <child>slender_cockscomb_version0_body_6_link</child>
      <pose>0.0 0.0 0.0 0.0 0.0 0.0</pose>
      <axis>
        <xyz>0 0 1.0</xyz>
        <limit>
          <lower>-0.5235987902</lower>
          <upper>0.5235987902</upper>
          <effort>10.0</effort>
          <velocity>10.0</velocity>
        </limit>
      </axis>
    </joint>
    <joint name="slender_cockscomb_version0_body_7_link" type="revolute">
      <parent>slender_cockscomb_version0_body_6_link</parent>
      <child>slender_cockscomb_version0_body_7_link</child>
      <pose>0.0 0.0 0.0 0.0 0.0 0.0</pose>
      <axis>
        <xyz>0 0 1.0</xyz>
        <limit>
          <lower>-0.5235987902</lower>
          <upper>0.5235987902</upper>
          <effort>10.0</effort>
          <velocity>10.0</velocity>
        </limit>
      </axis>
    </joint>
    <joint name="slender_cockscomb_version0_body_8_link" type="revolute">
      <parent>slender_cockscomb_version0_body_7_link</parent>
      <child>slender_cockscomb_version0_body_8_link</child>
      <pose>0.0 0.0 0.0 0.0 0.0 0.0</pose>
      <axis>
        <xyz>0 0 1.0</xyz>
        <limit>
          <lower>-0.5235987902</lower>
          <upper>0.5235987902</upper>
          <effort>10.0</effort>
          <velocity>10.0</velocity>
        </limit>
      </axis>
    </joint>
    <joint name="slender_cockscomb_version0_body_9_link" type="revolute">
      <parent>slender_cockscomb_version0_body_8_link</parent>
      <child>slender_cockscomb_version0_body_9_link</child>
      <pose>0.0 0.0 0.0 0.0 0.0 0.0</pose>
      <axis>
        <xyz>0 0 1.0</xyz>
        <limit>
          <lower>-0.5235987902</lower>
          <upper>0.5235987902</upper>
          <effort>10.0</effort>
          <velocity>10.0</velocity>
        </limit>
      </axis>
    </joint>
    <joint name="slender_cockscomb_version0_body_10_link" type="revolute">
      <parent>slender_cockscomb_version0_body_9_link</parent>
      <child>slender_cockscomb_version0_body_10_link</child>
      <pose>0.0 0.0 0.0 0.0 0.0 0.0</pose>
      <axis>
        <xyz>0 0 1.0</xyz>
        <limit>
          <lower>-0.5235987902</lower>
          <upper>0.5235987902</upper>
          <effort>10.0</effort>
          <velocity>10.0</velocity>
        </limit>
      </axis>
    </joint>
    <joint name="slender_cockscomb_version0_body_11_link" type="revolute">
      <parent>slender_cockscomb_version0_body_10_link</parent>
      <child>slender_cockscomb_version0_body_11_link</child>
      <pose>0.0 0.0 0.0 0.0 0.0 0.0</pose>
      <axis>
        <xyz>0 0 1.0</xyz>
        <limit>
          <lower>-0.5235987902</lower>
          <upper>0.5235987902</upper>
          <effort>10.0</effort>
          <velocity>10.0</velocity>
        </limit>
      </axis>
    </joint>
    <joint name="slender_cockscomb_version0_body_12_link" type="revolute">
      <parent>slender_cockscomb_version0_body_11_link</parent>
      <child>slender_cockscomb_version0_body_12_link</child>
      <pose>0.0 0.0 0.0 0.0 0.0 0.0</pose>
      <axis>
        <xyz>0 0 1.0</xyz>
        <limit>
          <lower>-0.5235987902</lower>
          <upper>0.5235987902</upper>
          <effort>10.0</effort>
          <velocity>10.0</velocity>
        </limit>
      </axis>
    </joint>
    <joint name="slender_cockscomb_version0_body_13_link" type="revolute">
      <parent>slender_cockscomb_version0_body_12_link</parent>
      <child>slender_cockscomb_version0_body_13_link</child>
      <pose>0.0 0.0 0.0 0.0 0.0 0.0</pose>
      <axis>
        <xyz>0 0 1.0</xyz>
        <limit>
          <lower>-0.5235987902</lower>
          <upper>0.5235987902</upper>
          <effort>10.0</effort>
          <velocity>10.0</velocity>
        </limit>
      </axis>
    </joint>
    <joint name="slender_cockscomb_version0_body_14_link" type="revolute">
      <parent>slender_cockscomb_version0_body_13_link</parent>
      <child>slender_cockscomb_version0_body_14_link</child>
      <pose>0.0 0.0 0.0 0.0 0.0 0.0</pose>
      <axis>
        <xyz>0 0 1.0</xyz>
        <limit>
          <lower>-0.5235987902</lower>
          <upper>0.5235987902</upper>
          <effort>10.0</effort>
          <velocity>10.0</velocity>
        </limit>
      </axis>
    </joint>
    <joint name="slender_cockscomb_version0_body_15_link" type="revolute">
      <parent>slender_cockscomb_version0_body_14_link</parent>
      <child>slender_cockscomb_version0_body_15_link</child>
      <pose>0.0 0.0 0.0 0.0 0.0 0.0</pose>
      <axis>
        <xyz>0 0 1.0</xyz>
        <limit>
          <lower>-0.5235987902</lower>
          <upper>0.5235987902</upper>
          <effort>10.0</effort>
          <velocity>10.0</velocity>
        </limit>
      </axis>
    </joint>
    <joint name="slender_cockscomb_version0_body_16_link" type="revolute">
      <parent>slender_cockscomb_version0_body_15_link</parent>
      <child>slender_cockscomb_version0_body_16_link</child>
      <pose>0.0 0.0 0.0 0.0 0.0 0.0</pose>
      <axis>
        <xyz>0 0 1.0</xyz>
        <limit>
          <lower>-0.5235987902</lower>
          <upper>0.5235987902</upper>
          <effort>10.0</effort>
          <velocity>10.0</velocity>
        </limit>
      </axis>
    </joint>
    <joint name="slender_cockscomb_version0_body_17_link" type="revolute">
      <parent>slender_cockscomb_version0_body_16_link</parent>
      <child>slender_cockscomb_version0_body_17_link</child>
      <pose>0.0 0.0 0.0 0.0 0.0 0.0</pose>
      <axis>
        <xyz>0 0 1.0</xyz>
        <limit>
          <lower>-0.5235987902</lower>
          <upper>0.5235987902</upper>
          <effort>10.0</effort>
          <velocity>10.0</velocity>
        </limit>
      </axis>
    </joint>
    <joint name="slender_cockscomb_version0_body_18_link" type="revolute">
      <parent>slender_cockscomb_version0_body_17_link</parent>
      <child>slender_cockscomb_version0_body_18_link</child>
      <pose>0.0 0.0 0.0 0.0 0.0 0.0</pose>
      <axis>
        <xyz>0 0 1.0</xyz>
        <limit>
          <lower>-0.5235987902</lower>
          <upper>0.5235987902</upper>
          <effort>10.0</effort>
          <velocity>10.0</velocity>
        </limit>
      </axis>
    </joint>
    <joint name="slender_cockscomb_version0_body_19_link" type="revolute">
      <parent>slender_cockscomb_version0_body_18_link</parent>
      <child>slender_cockscomb_version0_body_19_link</child>
      <pose>0.0 0.0 0.0 0.0 0.0 0.0</pose>
      <axis>
        <xyz>0 0 1.0</xyz>
        <limit>
          <lower>-0.5235987902</lower>
          <upper>0.5235987902</upper>
          <effort>10.0</effort>
          <velocity>10.0</velocity>
        </limit>
      </axis>
    </joint>
    <joint name="slender_cockscomb_version0_body_20_link" type="revolute">
      <parent>slender_cockscomb_version0_body_19_link</parent>
      <child>slender_cockscomb_version0_body_20_link</child>
      <pose>0.0 0.0 0.0 0.0 0.0 0.0</pose>
      <axis>
        <xyz>0 0 1.0</xyz>
        <limit>
          <lower>-0.5235987902</lower>
          <upper>0.5235987902</upper>
          <effort>10.0</effort>
          <velocity>10.0</velocity>
        </limit>
      </axis>
    </joint>
  </model>
</sdf>
