<?xml version="1.0"?>
<!-- created with Phobos 0.7 -->
<sdf version="1.5">
  <model name="penpoint_gunnel">
    <link name="body_0_link">
      <pose>0 0 0 0 0 0</pose>
      <inertial>
        <mass>0.0022868377</mass>
        <inertia>
          <ixx>2.184e-07</ixx>
          <ixy>-9e-09</ixy>
          <ixz>0</ixz>
          <iyy>9.714e-07</iyy>
          <iyz>1e-10</iyz>
          <izz>8.517e-07</izz>
        </inertia>
        <pose>0.0183525383 0 0.0004643761 0 0 0</pose>
      </inertial>
      <collision name="body_0_collision">
        <pose>0 0 0 0 0 0</pose>
        <geometry>
          <mesh>
            <uri>model://penpoint_gunnel/meshes/salamander_body_0_collision.dae</uri>
            <scale>1.0 1.0 1.0</scale>
          </mesh>
        </geometry>
      </collision>
      <visual name="body_0_visual">
        <pose>0.0 0.0 0.0 0.0 -0.0 0.0</pose>
        <material>
          <ambient>0 0 0 0</ambient>
          <diffuse>0 0 0 0</diffuse>
          <specular>0.4499999881 0.4499999881 0 1.0</specular>
        </material>
        <geometry>
          <mesh>
            <uri>model://penpoint_gunnel/meshes/salamander_body_0.dae</uri>
            <scale>1.0 1.0 1.0</scale>
          </mesh>
        </geometry>
      </visual>
    </link>
    <link name="body_1_link">
      <pose>0.0493762009 0 1.19408e-05 0 0 0</pose>
      <inertial>
        <mass>0.0053329165</mass>
        <inertia>
          <ixx>7.765e-07</ixx>
          <ixy>-1.5e-09</ixy>
          <ixz>0</ixz>
          <iyy>1.1945e-06</iyy>
          <iyz>0</iyz>
          <izz>6.876e-07</izz>
        </inertia>
        <pose>-0.0072435774 5e-10 0.0005351721 0 0 0</pose>
      </inertial>
      <collision name="body_1_collision">
        <pose>0 0 0 0 0 0</pose>
        <geometry>
          <mesh>
            <uri>model://penpoint_gunnel/meshes/salamander_body_1_collision.dae</uri>
            <scale>1.0 1.0 1.0</scale>
          </mesh>
        </geometry>
      </collision>
      <visual name="body_1_visual">
        <pose>0.0 0.0 0.0 0.0 -0.0 0.0</pose>
        <material>
          <ambient>0 0 0 0</ambient>
          <diffuse>0 0 0 0</diffuse>
          <specular>0.4499999881 0.4499999881 0 1.0</specular>
        </material>
        <geometry>
          <mesh>
            <uri>model://penpoint_gunnel/meshes/salamander_body_1.dae</uri>
            <scale>1.0 1.0 1.0</scale>
          </mesh>
        </geometry>
      </visual>
    </link>
    <link name="body_2_link">
      <pose>0.066657871 0 1.4092e-06 0 0 0</pose>
      <inertial>
        <mass>0.0004019736</mass>
        <inertia>
          <ixx>5.87e-08</ixx>
          <ixy>0</ixy>
          <ixz>0</ixz>
          <iyy>9.17e-08</iyy>
          <iyz>0</iyz>
          <izz>5.59e-08</izz>
        </inertia>
        <pose>-0.00886897 0 0.0004611732 0 0 0</pose>
      </inertial>
      <collision name="body_2_collision">
        <pose>0 0 0 0 0 0</pose>
        <geometry>
          <mesh>
            <uri>model://penpoint_gunnel/meshes/salamander_body_2_collision.dae</uri>
            <scale>1.0 1.0 1.0</scale>
          </mesh>
        </geometry>
      </collision>
      <visual name="body_2_visual">
        <pose>0.0 0.0 0.0 0.0 -0.0 0.0</pose>
        <material>
          <ambient>0 0 0 0</ambient>
          <diffuse>0 0 0 0</diffuse>
          <specular>0.4499999881 0.4499999881 0 1.0</specular>
        </material>
        <geometry>
          <mesh>
            <uri>model://penpoint_gunnel/meshes/salamander_body_2.dae</uri>
            <scale>1.0 1.0 1.0</scale>
          </mesh>
        </geometry>
      </visual>
    </link>
    <link name="body_3_link">
      <pose>0.0839395374 0 -6.008e-07 0 0 0</pose>
      <inertial>
        <mass>0.0013880638</mass>
        <inertia>
          <ixx>2.129e-07</ixx>
          <ixy>1e-10</ixy>
          <ixz>0</ixz>
          <iyy>3.385e-07</iyy>
          <iyz>0</iyz>
          <izz>2.056e-07</izz>
        </inertia>
        <pose>-0.0093726814 0 0.0005699135 0 0 0</pose>
      </inertial>
      <collision name="body_3_collision">
        <pose>0 0 0 0 0 0</pose>
        <geometry>
          <mesh>
            <uri>model://penpoint_gunnel/meshes/salamander_body_3_collision.dae</uri>
            <scale>1.0 1.0 1.0</scale>
          </mesh>
        </geometry>
      </collision>
      <visual name="body_3_visual">
        <pose>0.0 0.0 0.0 0.0 -0.0 0.0</pose>
        <material>
          <ambient>0 0 0 0</ambient>
          <diffuse>0 0 0 0</diffuse>
          <specular>0.4499999881 0.4499999881 0 1.0</specular>
        </material>
        <geometry>
          <mesh>
            <uri>model://penpoint_gunnel/meshes/salamander_body_3.dae</uri>
            <scale>1.0 1.0 1.0</scale>
          </mesh>
        </geometry>
      </visual>
    </link>
    <link name="body_4_link">
      <pose>0.1012212113 0 6.6e-08 0 0 0</pose>
      <inertial>
        <mass>0.0005924055</mass>
        <inertia>
          <ixx>9.46e-08</ixx>
          <ixy>0</ixy>
          <ixz>0</ixz>
          <iyy>1.542e-07</iyy>
          <iyz>0</iyz>
          <izz>9.45e-08</izz>
        </inertia>
        <pose>-0.0097852275 0 0.0005959554 0 0 0</pose>
      </inertial>
      <collision name="body_4_collision">
        <pose>0 0 0 0 0 0</pose>
        <geometry>
          <mesh>
            <uri>model://penpoint_gunnel/meshes/salamander_body_4_collision.dae</uri>
            <scale>1.0 1.0 1.0</scale>
          </mesh>
        </geometry>
      </collision>
      <visual name="body_4_visual">
        <pose>0.0 0.0 0.0 0.0 -0.0 0.0</pose>
        <material>
          <ambient>0 0 0 0</ambient>
          <diffuse>0 0 0 0</diffuse>
          <specular>0.4499999881 0.4499999881 0 1.0</specular>
        </material>
        <geometry>
          <mesh>
            <uri>model://penpoint_gunnel/meshes/salamander_body_4.dae</uri>
            <scale>1.0 1.0 1.0</scale>
          </mesh>
        </geometry>
      </visual>
    </link>
    <link name="body_5_link">
      <pose>0.1185028777 0 5.3e-09 0 0 0</pose>
      <inertial>
        <mass>0.0006137607</mass>
        <inertia>
          <ixx>1.025e-07</ixx>
          <ixy>-1e-10</ixy>
          <ixz>0</ixz>
          <iyy>1.707e-07</iyy>
          <iyz>0</iyz>
          <izz>1.019e-07</izz>
        </inertia>
        <pose>-0.0086786374 -5e-10 0.00059146 0 0 0</pose>
      </inertial>
      <collision name="body_5_collision">
        <pose>0 0 0 0 0 0</pose>
        <geometry>
          <mesh>
            <uri>model://penpoint_gunnel/meshes/salamander_body_5_collision.dae</uri>
            <scale>1.0 1.0 1.0</scale>
          </mesh>
        </geometry>
      </collision>
      <visual name="body_5_visual">
        <pose>0.0 0.0 0.0 0.0 -0.0 0.0</pose>
        <material>
          <ambient>0 0 0 0</ambient>
          <diffuse>0 0 0 0</diffuse>
          <specular>0.4499999881 0.4499999881 0 1.0</specular>
        </material>
        <geometry>
          <mesh>
            <uri>model://penpoint_gunnel/meshes/salamander_body_5.dae</uri>
            <scale>1.0 1.0 1.0</scale>
          </mesh>
        </geometry>
      </visual>
    </link>
    <link name="body_6_link">
      <pose>0.1357845515 0 2.07e-08 0 0 0</pose>
      <inertial>
        <mass>0.0015753271</mass>
        <inertia>
          <ixx>2.445e-07</ixx>
          <ixy>0</ixy>
          <ixz>0</ixz>
          <iyy>4.285e-07</iyy>
          <iyz>0</iyz>
          <izz>2.587e-07</izz>
        </inertia>
        <pose>-0.0098602325 0 0.0005092666 0 0 0</pose>
      </inertial>
      <collision name="body_6_collision">
        <pose>0 0 0 0 0 0</pose>
        <geometry>
          <mesh>
            <uri>model://penpoint_gunnel/meshes/salamander_body_6_collision.dae</uri>
            <scale>1.0 1.0 1.0</scale>
          </mesh>
        </geometry>
      </collision>
      <visual name="body_6_visual">
        <pose>0.0 0.0 0.0 0.0 -0.0 0.0</pose>
        <material>
          <ambient>0 0 0 0</ambient>
          <diffuse>0 0 0 0</diffuse>
          <specular>0.4499999881 0.4499999881 0 1.0</specular>
        </material>
        <geometry>
          <mesh>
            <uri>model://penpoint_gunnel/meshes/salamander_body_6.dae</uri>
            <scale>1.0 1.0 1.0</scale>
          </mesh>
        </geometry>
      </visual>
    </link>
    <link name="body_7_link">
      <pose>0.1530662179 0 -7.05e-08 0 0 0</pose>
      <inertial>
        <mass>0.0008873846</mass>
        <inertia>
          <ixx>1.361e-07</ixx>
          <ixy>-3e-10</ixy>
          <ixz>0</ixz>
          <iyy>2.552e-07</iyy>
          <iyz>0</iyz>
          <izz>1.492e-07</izz>
        </inertia>
        <pose>-0.0075705652 5e-10 0.0005873374 0 0 0</pose>
      </inertial>
      <collision name="body_7_collision">
        <pose>0 0 0 0 0 0</pose>
        <geometry>
          <mesh>
            <uri>model://penpoint_gunnel/meshes/salamander_body_7_collision.dae</uri>
            <scale>1.0 1.0 1.0</scale>
          </mesh>
        </geometry>
      </collision>
      <visual name="body_7_visual">
        <pose>0.0 0.0 0.0 0.0 -0.0 0.0</pose>
        <material>
          <ambient>0 0 0 0</ambient>
          <diffuse>0 0 0 0</diffuse>
          <specular>0.4499999881 0.4499999881 0 1.0</specular>
        </material>
        <geometry>
          <mesh>
            <uri>model://penpoint_gunnel/meshes/salamander_body_7.dae</uri>
            <scale>1.0 1.0 1.0</scale>
          </mesh>
        </geometry>
      </visual>
    </link>
    <link name="body_8_link">
      <pose>0.1703478843 0 -2.565e-07 0 0 0</pose>
      <inertial>
        <mass>0.0014513227</mass>
        <inertia>
          <ixx>2.032e-07</ixx>
          <ixy>-3e-10</ixy>
          <ixz>0</ixz>
          <iyy>3.857e-07</iyy>
          <iyz>0</iyz>
          <izz>2.154e-07</izz>
        </inertia>
        <pose>-0.006526723 5e-10 0.0003934823 0 0 0</pose>
      </inertial>
      <collision name="body_8_collision">
        <pose>0 0 0 0 0 0</pose>
        <geometry>
          <mesh>
            <uri>model://penpoint_gunnel/meshes/salamander_body_8_collision.dae</uri>
            <scale>1.0 1.0 1.0</scale>
          </mesh>
        </geometry>
      </collision>
      <visual name="body_8_visual">
        <pose>0.0 0.0 0.0 0.0 -0.0 0.0</pose>
        <material>
          <ambient>0 0 0 0</ambient>
          <diffuse>0 0 0 0</diffuse>
          <specular>0.4499999881 0.4499999881 0 1.0</specular>
        </material>
        <geometry>
          <mesh>
            <uri>model://penpoint_gunnel/meshes/salamander_body_8.dae</uri>
            <scale>1.0 1.0 1.0</scale>
          </mesh>
        </geometry>
      </visual>
    </link>
    <link name="body_9_link">
      <pose>0.1876295656 0 4.1544e-06 0 0 0</pose>
      <inertial>
        <mass>0.0006761758</mass>
        <inertia>
          <ixx>8.03e-08</ixx>
          <ixy>-1e-10</ixy>
          <ixz>0</ixz>
          <iyy>1.519e-07</iyy>
          <iyz>0</iyz>
          <izz>8.23e-08</izz>
        </inertia>
        <pose>-0.0047704428 -2e-10 0.0003351403 0 0 0</pose>
      </inertial>
      <collision name="body_9_collision">
        <pose>0 0 0 0 0 0</pose>
        <geometry>
          <mesh>
            <uri>model://penpoint_gunnel/meshes/salamander_body_9_collision.dae</uri>
            <scale>1.0 1.0 1.0</scale>
          </mesh>
        </geometry>
      </collision>
      <visual name="body_9_visual">
        <pose>0.0 0.0 0.0 0.0 -0.0 0.0</pose>
        <material>
          <ambient>0 0 0 0</ambient>
          <diffuse>0 0 0 0</diffuse>
          <specular>0.4499999881 0.4499999881 0 1.0</specular>
        </material>
        <geometry>
          <mesh>
            <uri>model://penpoint_gunnel/meshes/salamander_body_9.dae</uri>
            <scale>1.0 1.0 1.0</scale>
          </mesh>
        </geometry>
      </visual>
    </link>
    <link name="body_10_link">
      <pose>0.204911232 0 -1.63041e-05 0 0 0</pose>
      <inertial>
        <mass>0.0007530724</mass>
        <inertia>
          <ixx>6.53e-08</ixx>
          <ixy>-2e-10</ixy>
          <ixz>0</ixz>
          <iyy>1.27e-07</iyy>
          <iyz>0</iyz>
          <izz>6.99e-08</izz>
        </inertia>
        <pose>-0.0026422143 2e-10 0.0002384516 0 0 0</pose>
      </inertial>
      <collision name="body_10_collision">
        <pose>0 0 0 0 0 0</pose>
        <geometry>
          <mesh>
            <uri>model://penpoint_gunnel/meshes/salamander_body_10_collision.dae</uri>
            <scale>1.0 1.0 1.0</scale>
          </mesh>
        </geometry>
      </collision>
      <visual name="body_10_visual">
        <pose>0.0 0.0 0.0 0.0 -0.0 0.0</pose>
        <material>
          <ambient>0 0 0 0</ambient>
          <diffuse>0 0 0 0</diffuse>
          <specular>0.4499999881 0.4499999881 0 1.0</specular>
        </material>
        <geometry>
          <mesh>
            <uri>model://penpoint_gunnel/meshes/salamander_body_10.dae</uri>
            <scale>1.0 1.0 1.0</scale>
          </mesh>
        </geometry>
      </visual>
    </link>
    <link name="body_11_link">
      <pose>0.2221928984 0 -5.00922e-05 0 0 0</pose>
      <inertial>
        <mass>0.000578408</mass>
        <inertia>
          <ixx>2.52e-08</ixx>
          <ixy>-1.4e-09</ixy>
          <ixz>0</ixz>
          <iyy>7.89e-08</iyy>
          <iyz>0</iyz>
          <izz>5.58e-08</izz>
        </inertia>
        <pose>0.0042862743 1e-10 0.0002158839 0 0 0</pose>
      </inertial>
      <collision name="body_11_collision">
        <pose>0 0 0 0 0 0</pose>
        <geometry>
          <mesh>
            <uri>model://penpoint_gunnel/meshes/salamander_body_11_collision.dae</uri>
            <scale>1.0 1.0 1.0</scale>
          </mesh>
        </geometry>
      </collision>
      <visual name="body_11_visual">
        <pose>0.0 0.0 0.0 0.0 -0.0 0.0</pose>
        <material>
          <ambient>0 0 0 0</ambient>
          <diffuse>0 0 0 0</diffuse>
          <specular>0.4499999881 0.4499999881 0 1.0</specular>
        </material>
        <geometry>
          <mesh>
            <uri>model://penpoint_gunnel/meshes/salamander_body_11.dae</uri>
            <scale>1.0 1.0 1.0</scale>
          </mesh>
        </geometry>
      </visual>
    </link>
    <joint name="body_1_link" type="revolute">
      <parent>body_0_link</parent>
      <child>body_1_link</child>
      <pose>0.0 0.0 0.0 0.0 0.0 0.0</pose>
      <axis>
        <xyz>0 0 1.0</xyz>
        <limit>
          <lower>-0.5235987902</lower>
          <upper>0.5235987902</upper>
          <effort>10.0</effort>
          <velocity>10.0</velocity>
        </limit>
      </axis>
    </joint>
    <joint name="body_2_link" type="revolute">
      <parent>body_1_link</parent>
      <child>body_2_link</child>
      <pose>0.0 0.0 0.0 0.0 0.0 0.0</pose>
      <axis>
        <xyz>0 0 1.0</xyz>
        <limit>
          <lower>-0.5235987902</lower>
          <upper>0.5235987902</upper>
          <effort>10.0</effort>
          <velocity>10.0</velocity>
        </limit>
      </axis>
    </joint>
    <joint name="body_3_link" type="revolute">
      <parent>body_2_link</parent>
      <child>body_3_link</child>
      <pose>0.0 0.0 0.0 0.0 0.0 0.0</pose>
      <axis>
        <xyz>0 0 1.0</xyz>
        <limit>
          <lower>-0.5235987902</lower>
          <upper>0.5235987902</upper>
          <effort>10.0</effort>
          <velocity>10.0</velocity>
        </limit>
      </axis>
    </joint>
    <joint name="body_4_link" type="revolute">
      <parent>body_3_link</parent>
      <child>body_4_link</child>
      <pose>0.0 0.0 0.0 0.0 0.0 0.0</pose>
      <axis>
        <xyz>0 0 1.0</xyz>
        <limit>
          <lower>-0.5235987902</lower>
          <upper>0.5235987902</upper>
          <effort>10.0</effort>
          <velocity>10.0</velocity>
        </limit>
      </axis>
    </joint>
    <joint name="body_5_link" type="revolute">
      <parent>body_4_link</parent>
      <child>body_5_link</child>
      <pose>0.0 0.0 0.0 0.0 0.0 0.0</pose>
      <axis>
        <xyz>0 0 1.0</xyz>
        <limit>
          <lower>-0.5235987902</lower>
          <upper>0.5235987902</upper>
          <effort>10.0</effort>
          <velocity>10.0</velocity>
        </limit>
      </axis>
    </joint>
    <joint name="body_6_link" type="revolute">
      <parent>body_5_link</parent>
      <child>body_6_link</child>
      <pose>0.0 0.0 0.0 0.0 0.0 0.0</pose>
      <axis>
        <xyz>0 0 1.0</xyz>
        <limit>
          <lower>-0.5235987902</lower>
          <upper>0.5235987902</upper>
          <effort>10.0</effort>
          <velocity>10.0</velocity>
        </limit>
      </axis>
    </joint>
    <joint name="body_7_link" type="revolute">
      <parent>body_6_link</parent>
      <child>body_7_link</child>
      <pose>0.0 0.0 0.0 0.0 0.0 0.0</pose>
      <axis>
        <xyz>0 0 1.0</xyz>
        <limit>
          <lower>-0.5235987902</lower>
          <upper>0.5235987902</upper>
          <effort>10.0</effort>
          <velocity>10.0</velocity>
        </limit>
      </axis>
    </joint>
    <joint name="body_8_link" type="revolute">
      <parent>body_7_link</parent>
      <child>body_8_link</child>
      <pose>0.0 0.0 0.0 0.0 0.0 0.0</pose>
      <axis>
        <xyz>0 0 1.0</xyz>
        <limit>
          <lower>-0.5235987902</lower>
          <upper>0.5235987902</upper>
          <effort>10.0</effort>
          <velocity>10.0</velocity>
        </limit>
      </axis>
    </joint>
    <joint name="body_9_link" type="revolute">
      <parent>body_8_link</parent>
      <child>body_9_link</child>
      <pose>0.0 0.0 0.0 0.0 0.0 0.0</pose>
      <axis>
        <xyz>0 0 1.0</xyz>
        <limit>
          <lower>-0.5235987902</lower>
          <upper>0.5235987902</upper>
          <effort>10.0</effort>
          <velocity>10.0</velocity>
        </limit>
      </axis>
    </joint>
    <joint name="body_10_link" type="revolute">
      <parent>body_9_link</parent>
      <child>body_10_link</child>
      <pose>0.0 0.0 0.0 0.0 0.0 0.0</pose>
      <axis>
        <xyz>0 0 1.0</xyz>
        <limit>
          <lower>-0.5235987902</lower>
          <upper>0.5235987902</upper>
          <effort>10.0</effort>
          <velocity>10.0</velocity>
        </limit>
      </axis>
    </joint>
    <joint name="body_11_link" type="revolute">
      <parent>body_10_link</parent>
      <child>body_11_link</child>
      <pose>0.0 0.0 0.0 0.0 0.0 0.0</pose>
      <axis>
        <xyz>0 0 1.0</xyz>
        <limit>
          <lower>-0.5235987902</lower>
          <upper>0.5235987902</upper>
          <effort>10.0</effort>
          <velocity>10.0</velocity>
        </limit>
      </axis>
    </joint>
  </model>
</sdf>
