<?xml version="1.0"?>
<!-- created with Phobos 0.7 -->
<sdf version="1.5">
  <model name="snake_prickleback">
    <link name="snake_prickleback_version0_body_0_link">
      <pose>0 0 0 0 0 0</pose>
      <inertial>
        <mass>0.0005571254</mass>
        <inertia>
          <ixx>4.7e-09</ixx>
          <ixy>0</ixy>
          <ixz>1e-10</ixz>
          <iyy>9.8e-09</iyy>
          <iyz>0</iyz>
          <izz>9.1e-09</izz>
        </inertia>
        <pose>0.0111527415 5.607e-07 0.0001809114 0 0 0</pose>
      </inertial>
      <collision name="snake_prickleback_version0_body_0_collision">
        <pose>0 0 0 0 0 0</pose>
        <geometry>
          <mesh>
            <uri>../meshes/obj/animat_snake_prickleback_version0_body_0_collision.obj</uri>
            <scale>1.0 1.0 1.0</scale>
          </mesh>
        </geometry>
      </collision>
      <visual name="snake_prickleback_version0_body_0_visual">
        <pose>0.0 0.0 0.0 0.0 -0.0 0.0</pose>
        <geometry>
          <mesh>
            <uri>../meshes/obj/animat_snake_prickleback_version0_body_0.obj</uri>
            <scale>1.0 1.0 1.0</scale>
          </mesh>
        </geometry>
      </visual>
    </link>
    <link name="snake_prickleback_version0_body_1_link">
      <pose>0.0184191 0 7.14523e-05 0 0 0</pose>
      <inertial>
        <mass>0.0005828464</mass>
        <inertia>
          <ixx>6.8e-09</ixx>
          <ixy>0</ixy>
          <ixz>-1e-10</ixz>
          <iyy>7.5e-09</iyy>
          <iyz>0</iyz>
          <izz>6.7e-09</izz>
        </inertia>
        <pose>0.0021417532 -1.025e-07 -5.21642e-05 0 0 0</pose>
      </inertial>
      <collision name="snake_prickleback_version0_body_1_collision">
        <pose>0 0 0 0 0 0</pose>
        <geometry>
          <mesh>
            <uri>../meshes/obj/animat_snake_prickleback_version0_body_1_collision.obj</uri>
            <scale>0.0046309829 0.0046309829 0.0052392483</scale>
          </mesh>
        </geometry>
      </collision>
      <visual name="snake_prickleback_version0_body_1_visual">
        <pose>0.0 0.0 0.0 0.0 -0.0 0.0</pose>
        <geometry>
          <mesh>
            <uri>../meshes/obj/animat_snake_prickleback_version0_body_1.obj</uri>
            <scale>0.0046309829 0.0046309829 0.0052392483</scale>
          </mesh>
        </geometry>
      </visual>
    </link>
    <link name="snake_prickleback_version0_body_2_link">
      <pose>0.0267076958 0 -5.70936e-05 0 0 0</pose>
      <inertial>
        <mass>0.0006336774</mass>
        <inertia>
          <ixx>8.1e-09</ixx>
          <ixy>0</ixy>
          <ixz>0</ixz>
          <iyy>8.6e-09</iyy>
          <iyz>0</iyz>
          <izz>7.6e-09</izz>
        </inertia>
        <pose>0.0019967237 -6.17e-08 3.583e-05 0 0 0</pose>
      </inertial>
      <collision name="snake_prickleback_version0_body_2_collision">
        <pose>0 0 0 0 0 0</pose>
        <geometry>
          <mesh>
            <uri>../meshes/obj/animat_snake_prickleback_version0_body_2_collision.obj</uri>
            <scale>0.0048373938 0.0048373938 0.0055332184</scale>
          </mesh>
        </geometry>
      </collision>
      <visual name="snake_prickleback_version0_body_2_visual">
        <pose>0.0 0.0 0.0 0.0 -0.0 0.0</pose>
        <geometry>
          <mesh>
            <uri>../meshes/obj/animat_snake_prickleback_version0_body_2.obj</uri>
            <scale>0.0048373938 0.0048373938 0.0055332184</scale>
          </mesh>
        </geometry>
      </visual>
    </link>
    <link name="snake_prickleback_version0_body_3_link">
      <pose>0.0349962898 0 2.41407e-05 0 0 0</pose>
      <inertial>
        <mass>0.0007152962</mass>
        <inertia>
          <ixx>9.8e-09</ixx>
          <ixy>0</ixy>
          <ixz>0</ixz>
          <iyy>1.02e-08</iyy>
          <iyz>0</iyz>
          <izz>9.5e-09</izz>
        </inertia>
        <pose>0.0019300281 6.82e-08 -1.26897e-05 0 0 0</pose>
      </inertial>
      <collision name="snake_prickleback_version0_body_3_collision">
        <pose>0 0 0 0 0 0</pose>
        <geometry>
          <mesh>
            <uri>../meshes/obj/animat_snake_prickleback_version0_body_3_collision.obj</uri>
            <scale>0.005147934 0.005147934 0.0056570768</scale>
          </mesh>
        </geometry>
      </collision>
      <visual name="snake_prickleback_version0_body_3_visual">
        <pose>0.0 0.0 0.0 0.0 -0.0 0.0</pose>
        <geometry>
          <mesh>
            <uri>../meshes/obj/animat_snake_prickleback_version0_body_3.obj</uri>
            <scale>0.005147934 0.005147934 0.0056570768</scale>
          </mesh>
        </geometry>
      </visual>
    </link>
    <link name="snake_prickleback_version0_body_4_link">
      <pose>0.0432848856 0 -7.4415e-06 0 0 0</pose>
      <inertial>
        <mass>0.0007451672</mass>
        <inertia>
          <ixx>1.07e-08</ixx>
          <ixy>0</ixy>
          <ixz>0</ixz>
          <iyy>1.15e-08</iyy>
          <iyz>0</iyz>
          <izz>9.4e-09</izz>
        </inertia>
        <pose>0.0019387044 4.78e-08 5.2466e-06 0 0 0</pose>
      </inertial>
      <collision name="snake_prickleback_version0_body_4_collision">
        <pose>0 0 0 0 0 0</pose>
        <geometry>
          <mesh>
            <uri>../meshes/obj/animat_snake_prickleback_version0_body_4_collision.obj</uri>
            <scale>0.0050522089 0.0050522089 0.0060181022</scale>
          </mesh>
        </geometry>
      </collision>
      <visual name="snake_prickleback_version0_body_4_visual">
        <pose>0.0 0.0 0.0 0.0 -0.0 0.0</pose>
        <geometry>
          <mesh>
            <uri>../meshes/obj/animat_snake_prickleback_version0_body_4.obj</uri>
            <scale>0.0050522089 0.0050522089 0.0060181022</scale>
          </mesh>
        </geometry>
      </visual>
    </link>
    <link name="snake_prickleback_version0_body_5_link">
      <pose>0.0515734814 0 2.0895e-06 0 0 0</pose>
      <inertial>
        <mass>0.0007798071</mass>
        <inertia>
          <ixx>1.22e-08</ixx>
          <ixy>0</ixy>
          <ixz>0</ixz>
          <iyy>1.31e-08</iyy>
          <iyz>0</iyz>
          <izz>9.7e-09</izz>
        </inertia>
        <pose>0.0020868219 -2.79e-08 6.58e-07 0 0 0</pose>
      </inertial>
      <collision name="snake_prickleback_version0_body_5_collision">
        <pose>0 0 0 0 0 0</pose>
        <geometry>
          <mesh>
            <uri>../meshes/obj/animat_snake_prickleback_version0_body_5_collision.obj</uri>
            <scale>0.0048662424 0.0048662424 0.0065369606</scale>
          </mesh>
        </geometry>
      </collision>
      <visual name="snake_prickleback_version0_body_5_visual">
        <pose>0.0 0.0 0.0 0.0 -0.0 0.0</pose>
        <geometry>
          <mesh>
            <uri>../meshes/obj/animat_snake_prickleback_version0_body_5.obj</uri>
            <scale>0.0048662424 0.0048662424 0.0065369606</scale>
          </mesh>
        </geometry>
      </visual>
    </link>
    <link name="snake_prickleback_version0_body_6_link">
      <pose>0.0598620735 0 -4.402e-07 0 0 0</pose>
      <inertial>
        <mass>0.0008282264</mass>
        <inertia>
          <ixx>1.3e-08</ixx>
          <ixy>0</ixy>
          <ixz>0</ixz>
          <iyy>1.47e-08</iyy>
          <iyz>0</iyz>
          <izz>1.04e-08</izz>
        </inertia>
        <pose>0.0021072105 -1.83e-08 2.1878e-06 0 0 0</pose>
      </inertial>
      <collision name="snake_prickleback_version0_body_6_collision">
        <pose>0 0 0 0 0 0</pose>
        <geometry>
          <mesh>
            <uri>../meshes/obj/animat_snake_prickleback_version0_body_6_collision.obj</uri>
            <scale>0.0048593879 0.0048593879 0.0067826509</scale>
          </mesh>
        </geometry>
      </collision>
      <visual name="snake_prickleback_version0_body_6_visual">
        <pose>0.0 0.0 0.0 0.0 -0.0 0.0</pose>
        <geometry>
          <mesh>
            <uri>../meshes/obj/animat_snake_prickleback_version0_body_6.obj</uri>
            <scale>0.0048593879 0.0048593879 0.0067826509</scale>
          </mesh>
        </geometry>
      </visual>
    </link>
    <link name="snake_prickleback_version0_body_7_link">
      <pose>0.0681506693 0 2.78e-08 0 0 0</pose>
      <inertial>
        <mass>0.0007105453</mass>
        <inertia>
          <ixx>1.01e-08</ixx>
          <ixy>0</ixy>
          <ixz>0</ixz>
          <iyy>1.22e-08</iyy>
          <iyz>0</iyz>
          <izz>7.8e-09</izz>
        </inertia>
        <pose>0.002313301 4.18e-08 1.9693e-06 0 0 0</pose>
      </inertial>
      <collision name="snake_prickleback_version0_body_7_collision">
        <pose>0 0 0 0 0 0</pose>
        <geometry>
          <mesh>
            <uri>../meshes/obj/animat_snake_prickleback_version0_body_7_collision.obj</uri>
            <scale>0.0042871833 0.0042871833 0.0067723989</scale>
          </mesh>
        </geometry>
      </collision>
      <visual name="snake_prickleback_version0_body_7_visual">
        <pose>0.0 0.0 0.0 0.0 -0.0 0.0</pose>
        <geometry>
          <mesh>
            <uri>../meshes/obj/animat_snake_prickleback_version0_body_7.obj</uri>
            <scale>0.0042871833 0.0042871833 0.0067723989</scale>
          </mesh>
        </geometry>
      </visual>
    </link>
    <link name="snake_prickleback_version0_body_8_link">
      <pose>0.0764392614 0 3.64e-08 0 0 0</pose>
      <inertial>
        <mass>0.0006003822</mass>
        <inertia>
          <ixx>7.8e-09</ixx>
          <ixy>0</ixy>
          <ixz>0</ixz>
          <iyy>9.8e-09</iyy>
          <iyz>0</iyz>
          <izz>5.8e-09</izz>
        </inertia>
        <pose>0.0025639087 1.33e-08 2.1201e-06 0 0 0</pose>
      </inertial>
      <collision name="snake_prickleback_version0_body_8_collision">
        <pose>0 0 0 0 0 0</pose>
        <geometry>
          <mesh>
            <uri>../meshes/obj/animat_snake_prickleback_version0_body_8_collision.obj</uri>
            <scale>0.0037754774 0.0037754774 0.0065658092</scale>
          </mesh>
        </geometry>
      </collision>
      <visual name="snake_prickleback_version0_body_8_visual">
        <pose>0.0 0.0 0.0 0.0 -0.0 0.0</pose>
        <geometry>
          <mesh>
            <uri>../meshes/obj/animat_snake_prickleback_version0_body_8.obj</uri>
            <scale>0.0037754774 0.0037754774 0.0065658092</scale>
          </mesh>
        </geometry>
      </visual>
    </link>
    <link name="snake_prickleback_version0_body_9_link">
      <pose>0.084727861 0 -1.96e-08 0 0 0</pose>
      <inertial>
        <mass>0.0005533513</mass>
        <inertia>
          <ixx>6.9e-09</ixx>
          <ixy>0</ixy>
          <ixz>0</ixz>
          <iyy>8.9e-09</iyy>
          <iyz>0</iyz>
          <izz>5.1e-09</izz>
        </inertia>
        <pose>0.0026868284 -5.8e-09 2.574e-06 0 0 0</pose>
      </inertial>
      <collision name="snake_prickleback_version0_body_9_collision">
        <pose>0 0 0 0 0 0</pose>
        <geometry>
          <mesh>
            <uri>../meshes/obj/animat_snake_prickleback_version0_body_9_collision.obj</uri>
            <scale>0.0035068393 0.0035068393 0.0065287948</scale>
          </mesh>
        </geometry>
      </collision>
      <visual name="snake_prickleback_version0_body_9_visual">
        <pose>0.0 0.0 0.0 0.0 -0.0 0.0</pose>
        <geometry>
          <mesh>
            <uri>../meshes/obj/animat_snake_prickleback_version0_body_9.obj</uri>
            <scale>0.0035068393 0.0035068393 0.0065287948</scale>
          </mesh>
        </geometry>
      </visual>
    </link>
    <link name="snake_prickleback_version0_body_10_link">
      <pose>0.0930164531 0 8.7e-09 0 0 0</pose>
      <inertial>
        <mass>0.0005067609</mass>
        <inertia>
          <ixx>5.8e-09</ixx>
          <ixy>0</ixy>
          <ixz>0</ixz>
          <iyy>7.7e-09</iyy>
          <iyz>0</iyz>
          <izz>4.5e-09</izz>
        </inertia>
        <pose>0.0027585623 3.1e-09 2.5507e-06 0 0 0</pose>
      </inertial>
      <collision name="snake_prickleback_version0_body_10_collision">
        <pose>0 0 0 0 0 0</pose>
        <geometry>
          <mesh>
            <uri>../meshes/obj/animat_snake_prickleback_version0_body_10_collision.obj</uri>
            <scale>0.0033442378 0.0033442378 0.0063007474</scale>
          </mesh>
        </geometry>
      </collision>
      <visual name="snake_prickleback_version0_body_10_visual">
        <pose>0.0 0.0 0.0 0.0 -0.0 0.0</pose>
        <geometry>
          <mesh>
            <uri>../meshes/obj/animat_snake_prickleback_version0_body_10.obj</uri>
            <scale>0.0033442378 0.0033442378 0.0063007474</scale>
          </mesh>
        </geometry>
      </visual>
    </link>
    <link name="snake_prickleback_version0_body_11_link">
      <pose>0.1013050526 0 6.5e-09 0 0 0</pose>
      <inertial>
        <mass>0.0004592065</mass>
        <inertia>
          <ixx>4.9e-09</ixx>
          <ixy>0</ixy>
          <ixz>0</ixz>
          <iyy>6.8e-09</iyy>
          <iyz>0</iyz>
          <izz>3.9e-09</izz>
        </inertia>
        <pose>0.0028692856 -7e-10 3.0124e-06 0 0 0</pose>
      </inertial>
      <collision name="snake_prickleback_version0_body_11_collision">
        <pose>0 0 0 0 0 0</pose>
        <geometry>
          <mesh>
            <uri>../meshes/obj/animat_snake_prickleback_version0_body_11_collision.obj</uri>
            <scale>0.0031245947 0.0031245947 0.0061046481</scale>
          </mesh>
        </geometry>
      </collision>
      <visual name="snake_prickleback_version0_body_11_visual">
        <pose>0.0 0.0 0.0 0.0 -0.0 0.0</pose>
        <geometry>
          <mesh>
            <uri>../meshes/obj/animat_snake_prickleback_version0_body_11.obj</uri>
            <scale>0.0031245947 0.0031245947 0.0061046481</scale>
          </mesh>
        </geometry>
      </visual>
    </link>
    <link name="snake_prickleback_version0_body_12_link">
      <pose>0.1095936447 0 -3.19e-08 0 0 0</pose>
      <inertial>
        <mass>0.0003980135</mass>
        <inertia>
          <ixx>3.7e-09</ixx>
          <ixy>0</ixy>
          <ixz>0</ixz>
          <iyy>5.5e-09</iyy>
          <iyz>0</iyz>
          <izz>3.2e-09</izz>
        </inertia>
        <pose>0.0029410124 -2e-10 3.0534e-06 0 0 0</pose>
      </inertial>
      <collision name="snake_prickleback_version0_body_12_collision">
        <pose>0 0 0 0 0 0</pose>
        <geometry>
          <mesh>
            <uri>../meshes/obj/animat_snake_prickleback_version0_body_12_collision.obj</uri>
            <scale>0.0028644204 0.0028644204 0.0058897138</scale>
          </mesh>
        </geometry>
      </collision>
      <visual name="snake_prickleback_version0_body_12_visual">
        <pose>0.0 0.0 0.0 0.0 -0.0 0.0</pose>
        <geometry>
          <mesh>
            <uri>../meshes/obj/animat_snake_prickleback_version0_body_12.obj</uri>
            <scale>0.0028644204 0.0028644204 0.0058897138</scale>
          </mesh>
        </geometry>
      </visual>
    </link>
    <link name="snake_prickleback_version0_body_13_link">
      <pose>0.1178822368 0 4.9e-08 0 0 0</pose>
      <inertial>
        <mass>0.000336624</mass>
        <inertia>
          <ixx>2.7e-09</ixx>
          <ixy>0</ixy>
          <ixz>0</ixz>
          <iyy>4.3e-09</iyy>
          <iyz>0</iyz>
          <izz>2.6e-09</izz>
        </inertia>
        <pose>0.0030598044 4e-10 3.0754e-06 0 0 0</pose>
      </inertial>
      <collision name="snake_prickleback_version0_body_13_collision">
        <pose>0 0 0 0 0 0</pose>
        <geometry>
          <mesh>
            <uri>../meshes/obj/animat_snake_prickleback_version0_body_13_collision.obj</uri>
            <scale>0.0026314259 0.0026314259 0.0054284334</scale>
          </mesh>
        </geometry>
      </collision>
      <visual name="snake_prickleback_version0_body_13_visual">
        <pose>0.0 0.0 0.0 0.0 -0.0 0.0</pose>
        <geometry>
          <mesh>
            <uri>../meshes/obj/animat_snake_prickleback_version0_body_13.obj</uri>
            <scale>0.0026314259 0.0026314259 0.0054284334</scale>
          </mesh>
        </geometry>
      </visual>
    </link>
    <link name="snake_prickleback_version0_body_14_link">
      <pose>0.1261708289 0 -9.9e-09 0 0 0</pose>
      <inertial>
        <mass>0.0002782357</mass>
        <inertia>
          <ixx>1.9e-09</ixx>
          <ixy>0</ixy>
          <ixz>0</ixz>
          <iyy>3.3e-09</iyy>
          <iyz>0</iyz>
          <izz>2.1e-09</izz>
        </inertia>
        <pose>0.0031475127 -3e-10 3.1932e-06 0 0 0</pose>
      </inertial>
      <collision name="snake_prickleback_version0_body_14_collision">
        <pose>0 0 0 0 0 0</pose>
        <geometry>
          <mesh>
            <uri>../meshes/obj/animat_snake_prickleback_version0_body_14_collision.obj</uri>
            <scale>0.002369523 0.002369523 0.0050668716</scale>
          </mesh>
        </geometry>
      </collision>
      <visual name="snake_prickleback_version0_body_14_visual">
        <pose>0.0 0.0 0.0 0.0 -0.0 0.0</pose>
        <geometry>
          <mesh>
            <uri>../meshes/obj/animat_snake_prickleback_version0_body_14.obj</uri>
            <scale>0.002369523 0.002369523 0.0050668716</scale>
          </mesh>
        </geometry>
      </visual>
    </link>
    <link name="snake_prickleback_version0_body_15_link">
      <pose>0.1344594359 0 -3.571e-07 0 0 0</pose>
      <inertial>
        <mass>0.0002225983</mass>
        <inertia>
          <ixx>1.2e-09</ixx>
          <ixy>0</ixy>
          <ixz>0</ixz>
          <iyy>2.4e-09</iyy>
          <iyz>0</iyz>
          <izz>1.6e-09</izz>
        </inertia>
        <pose>0.0032805949 -6.4e-09 3.6695e-06 0 0 0</pose>
      </inertial>
      <collision name="snake_prickleback_version0_body_15_collision">
        <pose>0 0 0 0 0 0</pose>
        <geometry>
          <mesh>
            <uri>../meshes/obj/animat_snake_prickleback_version0_body_15_collision.obj</uri>
            <scale>0.0020856857 0.0020856857 0.0046280026</scale>
          </mesh>
        </geometry>
      </collision>
      <visual name="snake_prickleback_version0_body_15_visual">
        <pose>0.0 0.0 0.0 0.0 -0.0 0.0</pose>
        <geometry>
          <mesh>
            <uri>../meshes/obj/animat_snake_prickleback_version0_body_15.obj</uri>
            <scale>0.0020856857 0.0020856857 0.0046280026</scale>
          </mesh>
        </geometry>
      </visual>
    </link>
    <link name="snake_prickleback_version0_body_16_link">
      <pose>0.142748028 0 2.0839e-06 0 0 0</pose>
      <inertial>
        <mass>0.0001801197</mass>
        <inertia>
          <ixx>8e-10</ixx>
          <ixy>0</ixy>
          <ixz>0</ixz>
          <iyy>1.8e-09</iyy>
          <iyz>0</iyz>
          <izz>1.2e-09</izz>
        </inertia>
        <pose>0.0033335388 2.9e-09 2.0126e-06 0 0 0</pose>
      </inertial>
      <collision name="snake_prickleback_version0_body_16_collision">
        <pose>0 0 0 0 0 0</pose>
        <geometry>
          <mesh>
            <uri>../meshes/obj/animat_snake_prickleback_version0_body_16_collision.obj</uri>
            <scale>0.0018680096 0.0018680096 0.0042484999</scale>
          </mesh>
        </geometry>
      </collision>
      <visual name="snake_prickleback_version0_body_16_visual">
        <pose>0.0 0.0 0.0 0.0 -0.0 0.0</pose>
        <geometry>
          <mesh>
            <uri>../meshes/obj/animat_snake_prickleback_version0_body_16.obj</uri>
            <scale>0.0018680096 0.0018680096 0.0042484999</scale>
          </mesh>
        </geometry>
      </visual>
    </link>
    <link name="snake_prickleback_version0_body_17_link">
      <pose>0.1510366201 0 -8.4605e-06 0 0 0</pose>
      <inertial>
        <mass>0.0001259985</mass>
        <inertia>
          <ixx>4e-10</ixx>
          <ixy>0</ixy>
          <ixz>0</ixz>
          <iyy>1.1e-09</iyy>
          <iyz>0</iyz>
          <izz>8e-10</izz>
        </inertia>
        <pose>0.0033351183 -6e-09 8.6506e-06 0 0 0</pose>
      </inertial>
      <collision name="snake_prickleback_version0_body_17_collision">
        <pose>0 0 0 0 0 0</pose>
        <geometry>
          <mesh>
            <uri>../meshes/obj/animat_snake_prickleback_version0_body_17_collision.obj</uri>
            <scale>0.0016036034 0.0016036034 0.00371176</scale>
          </mesh>
        </geometry>
      </collision>
      <visual name="snake_prickleback_version0_body_17_visual">
        <pose>0.0 0.0 0.0 0.0 -0.0 0.0</pose>
        <geometry>
          <mesh>
            <uri>../meshes/obj/animat_snake_prickleback_version0_body_17.obj</uri>
            <scale>0.0016036034 0.0016036034 0.00371176</scale>
          </mesh>
        </geometry>
      </visual>
    </link>
    <link name="snake_prickleback_version0_body_18_link">
      <pose>0.1593252122 0 2.63617e-05 0 0 0</pose>
      <inertial>
        <mass>1.83365e-05</mass>
        <inertia>
          <ixx>2e-10</ixx>
          <ixy>0</ixy>
          <ixz>0</ixz>
          <iyy>2e-10</iyy>
          <iyz>0</iyz>
          <izz>1e-10</izz>
        </inertia>
        <pose>0.0032947657 6.5e-09 -9.4136e-06 0 0 0</pose>
      </inertial>
      <collision name="snake_prickleback_version0_body_18_collision">
        <pose>0 0 0 0 0 0</pose>
        <geometry>
          <mesh>
            <uri>../meshes/obj/animat_snake_prickleback_version0_body_18_collision.obj</uri>
            <scale>0.0011945963 0.0011945963 0.0030286908</scale>
          </mesh>
        </geometry>
      </collision>
      <visual name="snake_prickleback_version0_body_18_visual">
        <pose>0.0 0.0 0.0 0.0 -0.0 0.0</pose>
        <geometry>
          <mesh>
            <uri>../meshes/obj/animat_snake_prickleback_version0_body_18.obj</uri>
            <scale>0.0011945963 0.0011945963 0.0030286908</scale>
          </mesh>
        </geometry>
      </visual>
    </link>
    <link name="snake_prickleback_version0_body_19_link">
      <pose>0.1676138043 0 -6.52977e-05 0 0 0</pose>
      <inertial>
        <mass>5.90803e-05</mass>
        <inertia>
          <ixx>1e-10</ixx>
          <ixy>0</ixy>
          <ixz>0</ixz>
          <iyy>5e-10</iyy>
          <iyz>0</iyz>
          <izz>4e-10</izz>
        </inertia>
        <pose>0.0038891586 -9.55e-08 4.08778e-05 0 0 0</pose>
      </inertial>
      <collision name="snake_prickleback_version0_body_19_collision">
        <pose>0 0 0 0 0 0</pose>
        <geometry>
          <mesh>
            <uri>../meshes/obj/animat_snake_prickleback_version0_body_19_collision.obj</uri>
            <scale>0.000818491 0.000818491 0.0030527711</scale>
          </mesh>
        </geometry>
      </collision>
      <visual name="snake_prickleback_version0_body_19_visual">
        <pose>0.0 0.0 0.0 0.0 -0.0 0.0</pose>
        <geometry>
          <mesh>
            <uri>../meshes/obj/animat_snake_prickleback_version0_body_19.obj</uri>
            <scale>0.000818491 0.000818491 0.0030527711</scale>
          </mesh>
        </geometry>
      </visual>
    </link>
    <link name="snake_prickleback_version0_body_20_link">
      <pose>0.1759024113 0 0.0001070001 0 0 0</pose>
      <inertial>
        <mass>3.74586e-05</mass>
        <inertia>
          <ixx>1e-10</ixx>
          <ixy>0</ixy>
          <ixz>0</ixz>
          <iyy>2e-10</iyy>
          <iyz>0</iyz>
          <izz>2e-10</izz>
        </inertia>
        <pose>0.0030136555 -3.031e-07 0.0001195936 0 0 0</pose>
      </inertial>
      <collision name="snake_prickleback_version0_body_20_collision">
        <pose>0 0 0 0 0 0</pose>
        <geometry>
          <mesh>
            <uri>../meshes/obj/animat_snake_prickleback_version0_body_20_collision.obj</uri>
            <scale>0.0007066727 0.0007066727 0.0030809045</scale>
          </mesh>
        </geometry>
      </collision>
      <visual name="snake_prickleback_version0_body_20_visual">
        <pose>0.0 0.0 0.0 0.0 -0.0 0.0</pose>
        <geometry>
          <mesh>
            <uri>../meshes/obj/animat_snake_prickleback_version0_body_20.obj</uri>
            <scale>0.0007066727 0.0007066727 0.0030809045</scale>
          </mesh>
        </geometry>
      </visual>
    </link>
    <joint name="snake_prickleback_version0_body_1_link" type="revolute">
      <parent>snake_prickleback_version0_body_0_link</parent>
      <child>snake_prickleback_version0_body_1_link</child>
      <pose>0.0 0.0 0.0 0.0 0.0 0.0</pose>
      <axis>
        <xyz>0 0 1.0</xyz>
        <limit>
          <lower>-0.5235987902</lower>
          <upper>0.5235987902</upper>
          <effort>10.0</effort>
          <velocity>10.0</velocity>
        </limit>
      </axis>
    </joint>
    <joint name="snake_prickleback_version0_body_2_link" type="revolute">
      <parent>snake_prickleback_version0_body_1_link</parent>
      <child>snake_prickleback_version0_body_2_link</child>
      <pose>0.0 0.0 0.0 0.0 0.0 0.0</pose>
      <axis>
        <xyz>0 0 1.0</xyz>
        <limit>
          <lower>-0.5235987902</lower>
          <upper>0.5235987902</upper>
          <effort>10.0</effort>
          <velocity>10.0</velocity>
        </limit>
      </axis>
    </joint>
    <joint name="snake_prickleback_version0_body_3_link" type="revolute">
      <parent>snake_prickleback_version0_body_2_link</parent>
      <child>snake_prickleback_version0_body_3_link</child>
      <pose>0.0 0.0 0.0 0.0 0.0 0.0</pose>
      <axis>
        <xyz>0 0 1.0</xyz>
        <limit>
          <lower>-0.5235987902</lower>
          <upper>0.5235987902</upper>
          <effort>10.0</effort>
          <velocity>10.0</velocity>
        </limit>
      </axis>
    </joint>
    <joint name="snake_prickleback_version0_body_4_link" type="revolute">
      <parent>snake_prickleback_version0_body_3_link</parent>
      <child>snake_prickleback_version0_body_4_link</child>
      <pose>0.0 0.0 0.0 0.0 0.0 0.0</pose>
      <axis>
        <xyz>0 0 1.0</xyz>
        <limit>
          <lower>-0.5235987902</lower>
          <upper>0.5235987902</upper>
          <effort>10.0</effort>
          <velocity>10.0</velocity>
        </limit>
      </axis>
    </joint>
    <joint name="snake_prickleback_version0_body_5_link" type="revolute">
      <parent>snake_prickleback_version0_body_4_link</parent>
      <child>snake_prickleback_version0_body_5_link</child>
      <pose>0.0 0.0 0.0 0.0 0.0 0.0</pose>
      <axis>
        <xyz>0 0 1.0</xyz>
        <limit>
          <lower>-0.5235987902</lower>
          <upper>0.5235987902</upper>
          <effort>10.0</effort>
          <velocity>10.0</velocity>
        </limit>
      </axis>
    </joint>
    <joint name="snake_prickleback_version0_body_6_link" type="revolute">
      <parent>snake_prickleback_version0_body_5_link</parent>
      <child>snake_prickleback_version0_body_6_link</child>
      <pose>0.0 0.0 0.0 0.0 0.0 0.0</pose>
      <axis>
        <xyz>0 0 1.0</xyz>
        <limit>
          <lower>-0.5235987902</lower>
          <upper>0.5235987902</upper>
          <effort>10.0</effort>
          <velocity>10.0</velocity>
        </limit>
      </axis>
    </joint>
    <joint name="snake_prickleback_version0_body_7_link" type="revolute">
      <parent>snake_prickleback_version0_body_6_link</parent>
      <child>snake_prickleback_version0_body_7_link</child>
      <pose>0.0 0.0 0.0 0.0 0.0 0.0</pose>
      <axis>
        <xyz>0 0 1.0</xyz>
        <limit>
          <lower>-0.5235987902</lower>
          <upper>0.5235987902</upper>
          <effort>10.0</effort>
          <velocity>10.0</velocity>
        </limit>
      </axis>
    </joint>
    <joint name="snake_prickleback_version0_body_8_link" type="revolute">
      <parent>snake_prickleback_version0_body_7_link</parent>
      <child>snake_prickleback_version0_body_8_link</child>
      <pose>0.0 0.0 0.0 0.0 0.0 0.0</pose>
      <axis>
        <xyz>0 0 1.0</xyz>
        <limit>
          <lower>-0.5235987902</lower>
          <upper>0.5235987902</upper>
          <effort>10.0</effort>
          <velocity>10.0</velocity>
        </limit>
      </axis>
    </joint>
    <joint name="snake_prickleback_version0_body_9_link" type="revolute">
      <parent>snake_prickleback_version0_body_8_link</parent>
      <child>snake_prickleback_version0_body_9_link</child>
      <pose>0.0 0.0 0.0 0.0 0.0 0.0</pose>
      <axis>
        <xyz>0 0 1.0</xyz>
        <limit>
          <lower>-0.5235987902</lower>
          <upper>0.5235987902</upper>
          <effort>10.0</effort>
          <velocity>10.0</velocity>
        </limit>
      </axis>
    </joint>
    <joint name="snake_prickleback_version0_body_10_link" type="revolute">
      <parent>snake_prickleback_version0_body_9_link</parent>
      <child>snake_prickleback_version0_body_10_link</child>
      <pose>0.0 0.0 0.0 0.0 0.0 0.0</pose>
      <axis>
        <xyz>0 0 1.0</xyz>
        <limit>
          <lower>-0.5235987902</lower>
          <upper>0.5235987902</upper>
          <effort>10.0</effort>
          <velocity>10.0</velocity>
        </limit>
      </axis>
    </joint>
    <joint name="snake_prickleback_version0_body_11_link" type="revolute">
      <parent>snake_prickleback_version0_body_10_link</parent>
      <child>snake_prickleback_version0_body_11_link</child>
      <pose>0.0 0.0 0.0 0.0 0.0 0.0</pose>
      <axis>
        <xyz>0 0 1.0</xyz>
        <limit>
          <lower>-0.5235987902</lower>
          <upper>0.5235987902</upper>
          <effort>10.0</effort>
          <velocity>10.0</velocity>
        </limit>
      </axis>
    </joint>
    <joint name="snake_prickleback_version0_body_12_link" type="revolute">
      <parent>snake_prickleback_version0_body_11_link</parent>
      <child>snake_prickleback_version0_body_12_link</child>
      <pose>0.0 0.0 0.0 0.0 0.0 0.0</pose>
      <axis>
        <xyz>0 0 1.0</xyz>
        <limit>
          <lower>-0.5235987902</lower>
          <upper>0.5235987902</upper>
          <effort>10.0</effort>
          <velocity>10.0</velocity>
        </limit>
      </axis>
    </joint>
    <joint name="snake_prickleback_version0_body_13_link" type="revolute">
      <parent>snake_prickleback_version0_body_12_link</parent>
      <child>snake_prickleback_version0_body_13_link</child>
      <pose>0.0 0.0 0.0 0.0 0.0 0.0</pose>
      <axis>
        <xyz>0 0 1.0</xyz>
        <limit>
          <lower>-0.5235987902</lower>
          <upper>0.5235987902</upper>
          <effort>10.0</effort>
          <velocity>10.0</velocity>
        </limit>
      </axis>
    </joint>
    <joint name="snake_prickleback_version0_body_14_link" type="revolute">
      <parent>snake_prickleback_version0_body_13_link</parent>
      <child>snake_prickleback_version0_body_14_link</child>
      <pose>0.0 0.0 0.0 0.0 0.0 0.0</pose>
      <axis>
        <xyz>0 0 1.0</xyz>
        <limit>
          <lower>-0.5235987902</lower>
          <upper>0.5235987902</upper>
          <effort>10.0</effort>
          <velocity>10.0</velocity>
        </limit>
      </axis>
    </joint>
    <joint name="snake_prickleback_version0_body_15_link" type="revolute">
      <parent>snake_prickleback_version0_body_14_link</parent>
      <child>snake_prickleback_version0_body_15_link</child>
      <pose>0.0 0.0 0.0 0.0 0.0 0.0</pose>
      <axis>
        <xyz>0 0 1.0</xyz>
        <limit>
          <lower>-0.5235987902</lower>
          <upper>0.5235987902</upper>
          <effort>10.0</effort>
          <velocity>10.0</velocity>
        </limit>
      </axis>
    </joint>
    <joint name="snake_prickleback_version0_body_16_link" type="revolute">
      <parent>snake_prickleback_version0_body_15_link</parent>
      <child>snake_prickleback_version0_body_16_link</child>
      <pose>0.0 0.0 0.0 0.0 0.0 0.0</pose>
      <axis>
        <xyz>0 0 1.0</xyz>
        <limit>
          <lower>-0.5235987902</lower>
          <upper>0.5235987902</upper>
          <effort>10.0</effort>
          <velocity>10.0</velocity>
        </limit>
      </axis>
    </joint>
    <joint name="snake_prickleback_version0_body_17_link" type="revolute">
      <parent>snake_prickleback_version0_body_16_link</parent>
      <child>snake_prickleback_version0_body_17_link</child>
      <pose>0.0 0.0 0.0 0.0 0.0 0.0</pose>
      <axis>
        <xyz>0 0 1.0</xyz>
        <limit>
          <lower>-0.5235987902</lower>
          <upper>0.5235987902</upper>
          <effort>10.0</effort>
          <velocity>10.0</velocity>
        </limit>
      </axis>
    </joint>
    <joint name="snake_prickleback_version0_body_18_link" type="revolute">
      <parent>snake_prickleback_version0_body_17_link</parent>
      <child>snake_prickleback_version0_body_18_link</child>
      <pose>0.0 0.0 0.0 0.0 0.0 0.0</pose>
      <axis>
        <xyz>0 0 1.0</xyz>
        <limit>
          <lower>-0.5235987902</lower>
          <upper>0.5235987902</upper>
          <effort>10.0</effort>
          <velocity>10.0</velocity>
        </limit>
      </axis>
    </joint>
    <joint name="snake_prickleback_version0_body_19_link" type="revolute">
      <parent>snake_prickleback_version0_body_18_link</parent>
      <child>snake_prickleback_version0_body_19_link</child>
      <pose>0.0 0.0 0.0 0.0 0.0 0.0</pose>
      <axis>
        <xyz>0 0 1.0</xyz>
        <limit>
          <lower>-0.5235987902</lower>
          <upper>0.5235987902</upper>
          <effort>10.0</effort>
          <velocity>10.0</velocity>
        </limit>
      </axis>
    </joint>
    <joint name="snake_prickleback_version0_body_20_link" type="revolute">
      <parent>snake_prickleback_version0_body_19_link</parent>
      <child>snake_prickleback_version0_body_20_link</child>
      <pose>0.0 0.0 0.0 0.0 0.0 0.0</pose>
      <axis>
        <xyz>0 0 1.0</xyz>
        <limit>
          <lower>-0.5235987902</lower>
          <upper>0.5235987902</upper>
          <effort>10.0</effort>
          <velocity>10.0</velocity>
        </limit>
      </axis>
    </joint>
  </model>
</sdf>
