<?xml version="1.0"?>
<!-- created with Phobos 0.7 -->
<sdf version="1.5">
  <model name="penpoint_gunnel">
    <link name="penpoint_gunnel_version0_body_0_link">
      <pose>0 0 0 0 0 0</pose>
      <inertial>
        <mass>0.0018866652</mass>
        <inertia>
          <ixx>3.79e-08</ixx>
          <ixy>0</ixy>
          <ixz>0</ixz>
          <iyy>7.6e-08</iyy>
          <iyz>0</iyz>
          <izz>5.97e-08</izz>
        </inertia>
        <pose>0.0150142806 2.965e-07 0.0001901388 0 0 0</pose>
      </inertial>
      <collision name="penpoint_gunnel_version0_body_0_collision">
        <pose>0 0 0 0 0 0</pose>
        <geometry>
          <mesh>
            <uri>../meshes/obj/animat_penpoint_gunnel_version0_body_0_collision.obj</uri>
            <scale>1.0 1.0 1.0</scale>
          </mesh>
        </geometry>
      </collision>
      <visual name="penpoint_gunnel_version0_body_0_visual">
        <pose>0.0 0.0 0.0 0.0 -0.0 0.0</pose>
        <geometry>
          <mesh>
            <uri>../meshes/obj/animat_penpoint_gunnel_version0_body_0.obj</uri>
            <scale>1.0 1.0 1.0</scale>
          </mesh>
        </geometry>
      </visual>
    </link>
    <link name="penpoint_gunnel_version0_body_1_link">
      <pose>0.0246881004 0 7.10794e-05 0 0 0</pose>
      <inertial>
        <mass>0.0013655219</mass>
        <inertia>
          <ixx>3.78e-08</ixx>
          <ixy>0</ixy>
          <ixz>-2e-10</ixz>
          <iyy>4.45e-08</iyy>
          <iyz>0</iyz>
          <izz>2.06e-08</izz>
        </inertia>
        <pose>0.0034496116 1e-08 -5.74317e-05 0 0 0</pose>
      </inertial>
      <collision name="penpoint_gunnel_version0_body_1_collision">
        <pose>0 0 0 0 0 0</pose>
        <geometry>
          <mesh>
            <uri>../meshes/obj/animat_penpoint_gunnel_version0_body_1_collision.obj</uri>
            <scale>0.0045797825 0.0045797825 0.0095730424</scale>
          </mesh>
        </geometry>
      </collision>
      <visual name="penpoint_gunnel_version0_body_1_visual">
        <pose>0.0 0.0 0.0 0.0 -0.0 0.0</pose>
        <geometry>
          <mesh>
            <uri>../meshes/obj/animat_penpoint_gunnel_version0_body_1.obj</uri>
            <scale>0.0045797825 0.0045797825 0.0095730424</scale>
          </mesh>
        </geometry>
      </visual>
    </link>
    <link name="penpoint_gunnel_version0_body_2_link">
      <pose>0.035797745 0 -5.5119e-05 0 0 0</pose>
      <inertial>
        <mass>0.0018334551</mass>
        <inertia>
          <ixx>6.33e-08</ixx>
          <ixy>0</ixy>
          <ixz>1e-10</ixz>
          <iyy>6.89e-08</iyy>
          <iyz>0</iyz>
          <izz>3.35e-08</izz>
        </inertia>
        <pose>0.0033030473 -5.64e-08 4.19169e-05 0 0 0</pose>
      </inertial>
      <collision name="penpoint_gunnel_version0_body_2_collision">
        <pose>0 0 0 0 0 0</pose>
        <geometry>
          <mesh>
            <uri>../meshes/obj/animat_penpoint_gunnel_version0_body_2_collision.obj</uri>
            <scale>0.005363822 0.005363822 0.010515511</scale>
          </mesh>
        </geometry>
      </collision>
      <visual name="penpoint_gunnel_version0_body_2_visual">
        <pose>0.0 0.0 0.0 0.0 -0.0 0.0</pose>
        <geometry>
          <mesh>
            <uri>../meshes/obj/animat_penpoint_gunnel_version0_body_2.obj</uri>
            <scale>0.005363822 0.005363822 0.010515511</scale>
          </mesh>
        </geometry>
      </visual>
    </link>
    <link name="penpoint_gunnel_version0_body_3_link">
      <pose>0.0469073914 0 2.30245e-05 0 0 0</pose>
      <inertial>
        <mass>0.0023022733</mass>
        <inertia>
          <ixx>9.21e-08</ixx>
          <ixy>0</ixy>
          <ixz>0</ixz>
          <iyy>9.98e-08</iyy>
          <iyz>0</iyz>
          <izz>4.73e-08</izz>
        </inertia>
        <pose>0.0029689523 -2.9e-09 -9.6402e-06 0 0 0</pose>
      </inertial>
      <collision name="penpoint_gunnel_version0_body_3_collision">
        <pose>0 0 0 0 0 0</pose>
        <geometry>
          <mesh>
            <uri>../meshes/obj/animat_penpoint_gunnel_version0_body_3_collision.obj</uri>
            <scale>0.0060566664 0.0060566664 0.0115554929</scale>
          </mesh>
        </geometry>
      </collision>
      <visual name="penpoint_gunnel_version0_body_3_visual">
        <pose>0.0 0.0 0.0 0.0 -0.0 0.0</pose>
        <geometry>
          <mesh>
            <uri>../meshes/obj/animat_penpoint_gunnel_version0_body_3.obj</uri>
            <scale>0.0060566664 0.0060566664 0.0115554929</scale>
          </mesh>
        </geometry>
      </visual>
    </link>
    <link name="penpoint_gunnel_version0_body_4_link">
      <pose>0.0580170341 0 -8.9174e-06 0 0 0</pose>
      <inertial>
        <mass>0.0022581075</mass>
        <inertia>
          <ixx>8.96e-08</ixx>
          <ixy>0</ixy>
          <ixz>0</ixz>
          <iyy>9.7e-08</iyy>
          <iyz>0</iyz>
          <izz>4.52e-08</izz>
        </inertia>
        <pose>0.0028677282 6.7e-09 8.91e-06 0 0 0</pose>
      </inertial>
      <collision name="penpoint_gunnel_version0_body_4_collision">
        <pose>0 0 0 0 0 0</pose>
        <geometry>
          <mesh>
            <uri>../meshes/obj/animat_penpoint_gunnel_version0_body_4_collision.obj</uri>
            <scale>0.0059828162 0.0059828162 0.0117669106</scale>
          </mesh>
        </geometry>
      </collision>
      <visual name="penpoint_gunnel_version0_body_4_visual">
        <pose>0.0 0.0 0.0 0.0 -0.0 0.0</pose>
        <geometry>
          <mesh>
            <uri>../meshes/obj/animat_penpoint_gunnel_version0_body_4.obj</uri>
            <scale>0.0059828162 0.0059828162 0.0117669106</scale>
          </mesh>
        </geometry>
      </visual>
    </link>
    <link name="penpoint_gunnel_version0_body_5_link">
      <pose>0.0691266805 0 2.2538e-06 0 0 0</pose>
      <inertial>
        <mass>0.002246437</mass>
        <inertia>
          <ixx>8.96e-08</ixx>
          <ixy>0</ixy>
          <ixz>0</ixz>
          <iyy>9.62e-08</iyy>
          <iyz>0</iyz>
          <izz>4.53e-08</izz>
        </inertia>
        <pose>0.0029163137 -5.3e-09 2.6554e-06 0 0 0</pose>
      </inertial>
      <collision name="penpoint_gunnel_version0_body_5_collision">
        <pose>0 0 0 0 0 0</pose>
        <geometry>
          <mesh>
            <uri>../meshes/obj/animat_penpoint_gunnel_version0_body_5_collision.obj</uri>
            <scale>0.0060054064 0.0060054064 0.0115833282</scale>
          </mesh>
        </geometry>
      </collision>
      <visual name="penpoint_gunnel_version0_body_5_visual">
        <pose>0.0 0.0 0.0 0.0 -0.0 0.0</pose>
        <geometry>
          <mesh>
            <uri>../meshes/obj/animat_penpoint_gunnel_version0_body_5.obj</uri>
            <scale>0.0060054064 0.0060054064 0.0115833282</scale>
          </mesh>
        </geometry>
      </visual>
    </link>
    <link name="penpoint_gunnel_version0_body_6_link">
      <pose>0.0802363232 0 -4.528e-07 0 0 0</pose>
      <inertial>
        <mass>0.002392301</mass>
        <inertia>
          <ixx>1.005e-07</ixx>
          <ixy>0</ixy>
          <ixz>0</ixz>
          <iyy>1.073e-07</iyy>
          <iyz>0</iyz>
          <izz>4.98e-08</izz>
        </inertia>
        <pose>0.0028657839 1.76e-08 4.4468e-06 0 0 0</pose>
      </inertial>
      <collision name="penpoint_gunnel_version0_body_6_collision">
        <pose>0 0 0 0 0 0</pose>
        <geometry>
          <mesh>
            <uri>../meshes/obj/animat_penpoint_gunnel_version0_body_6_collision.obj</uri>
            <scale>0.0061576366 0.0061576366 0.0119456649</scale>
          </mesh>
        </geometry>
      </collision>
      <visual name="penpoint_gunnel_version0_body_6_visual">
        <pose>0.0 0.0 0.0 0.0 -0.0 0.0</pose>
        <geometry>
          <mesh>
            <uri>../meshes/obj/animat_penpoint_gunnel_version0_body_6.obj</uri>
            <scale>0.0061576366 0.0061576366 0.0119456649</scale>
          </mesh>
        </geometry>
      </visual>
    </link>
    <link name="penpoint_gunnel_version0_body_7_link">
      <pose>0.0913459733 0 2.71e-08 0 0 0</pose>
      <inertial>
        <mass>0.0024621251</mass>
        <inertia>
          <ixx>1.055e-07</ixx>
          <ixy>0</ixy>
          <ixz>0</ixz>
          <iyy>1.133e-07</iyy>
          <iyz>0</iyz>
          <izz>5.16e-08</izz>
        </inertia>
        <pose>0.0028684959 2.94e-08 4.725e-06 0 0 0</pose>
      </inertial>
      <collision name="penpoint_gunnel_version0_body_7_collision">
        <pose>0 0 0 0 0 0</pose>
        <geometry>
          <mesh>
            <uri>../meshes/obj/animat_penpoint_gunnel_version0_body_7_collision.obj</uri>
            <scale>0.006188333 0.006188333 0.0121418238</scale>
          </mesh>
        </geometry>
      </collision>
      <visual name="penpoint_gunnel_version0_body_7_visual">
        <pose>0.0 0.0 0.0 0.0 -0.0 0.0</pose>
        <geometry>
          <mesh>
            <uri>../meshes/obj/animat_penpoint_gunnel_version0_body_7.obj</uri>
            <scale>0.006188333 0.006188333 0.0121418238</scale>
          </mesh>
        </geometry>
      </visual>
    </link>
    <link name="penpoint_gunnel_version0_body_8_link">
      <pose>0.102455616 0 3.34e-08 0 0 0</pose>
      <inertial>
        <mass>0.0024327552</mass>
        <inertia>
          <ixx>1.066e-07</ixx>
          <ixy>0</ixy>
          <ixz>0</ixz>
          <iyy>1.154e-07</iyy>
          <iyz>0</iyz>
          <izz>4.94e-08</izz>
        </inertia>
        <pose>0.0029719323 4.34e-08 5.6057e-06 0 0 0</pose>
      </inertial>
      <collision name="penpoint_gunnel_version0_body_8_collision">
        <pose>0 0 0 0 0 0</pose>
        <geometry>
          <mesh>
            <uri>../meshes/obj/animat_penpoint_gunnel_version0_body_8_collision.obj</uri>
            <scale>0.0059984922 0.0059984922 0.0123810172</scale>
          </mesh>
        </geometry>
      </collision>
      <visual name="penpoint_gunnel_version0_body_8_visual">
        <pose>0.0 0.0 0.0 0.0 -0.0 0.0</pose>
        <geometry>
          <mesh>
            <uri>../meshes/obj/animat_penpoint_gunnel_version0_body_8.obj</uri>
            <scale>0.0059984922 0.0059984922 0.0123810172</scale>
          </mesh>
        </geometry>
      </visual>
    </link>
    <link name="penpoint_gunnel_version0_body_9_link">
      <pose>0.1135652587 0 -1.75e-08 0 0 0</pose>
      <inertial>
        <mass>0.0024310593</mass>
        <inertia>
          <ixx>1.083e-07</ixx>
          <ixy>0</ixy>
          <ixz>0</ixz>
          <iyy>1.188e-07</iyy>
          <iyz>0</iyz>
          <izz>4.83e-08</izz>
        </inertia>
        <pose>0.0030794516 -1.13e-08 6.9877e-06 0 0 0</pose>
      </inertial>
      <collision name="penpoint_gunnel_version0_body_9_collision">
        <pose>0 0 0 0 0 0</pose>
        <geometry>
          <mesh>
            <uri>../meshes/obj/animat_penpoint_gunnel_version0_body_9_collision.obj</uri>
            <scale>0.0058203936 0.0058203936 0.0126757026</scale>
          </mesh>
        </geometry>
      </collision>
      <visual name="penpoint_gunnel_version0_body_9_visual">
        <pose>0.0 0.0 0.0 0.0 -0.0 0.0</pose>
        <geometry>
          <mesh>
            <uri>../meshes/obj/animat_penpoint_gunnel_version0_body_9.obj</uri>
            <scale>0.0058203936 0.0058203936 0.0126757026</scale>
          </mesh>
        </geometry>
      </visual>
    </link>
    <link name="penpoint_gunnel_version0_body_10_link">
      <pose>0.1246749014 0 4.4e-09 0 0 0</pose>
      <inertial>
        <mass>0.0022845465</mass>
        <inertia>
          <ixx>9.72e-08</ixx>
          <ixy>0</ixy>
          <ixz>0</ixz>
          <iyy>1.096e-07</iyy>
          <iyz>0</iyz>
          <izz>4.33e-08</izz>
        </inertia>
        <pose>0.0032260418 -3.08e-08 8.5048e-06 0 0 0</pose>
      </inertial>
      <collision name="penpoint_gunnel_version0_body_10_collision">
        <pose>0 0 0 0 0 0</pose>
        <geometry>
          <mesh>
            <uri>../meshes/obj/animat_penpoint_gunnel_version0_body_10_collision.obj</uri>
            <scale>0.0055043697 0.0055043697 0.0126144886</scale>
          </mesh>
        </geometry>
      </collision>
      <visual name="penpoint_gunnel_version0_body_10_visual">
        <pose>0.0 0.0 0.0 0.0 -0.0 0.0</pose>
        <geometry>
          <mesh>
            <uri>../meshes/obj/animat_penpoint_gunnel_version0_body_10.obj</uri>
            <scale>0.0055043697 0.0055043697 0.0126144886</scale>
          </mesh>
        </geometry>
      </visual>
    </link>
    <link name="penpoint_gunnel_version0_body_11_link">
      <pose>0.1357845515 0 2.07e-08 0 0 0</pose>
      <inertial>
        <mass>0.0020090819</mass>
        <inertia>
          <ixx>8.07e-08</ixx>
          <ixy>0</ixy>
          <ixz>0</ixz>
          <iyy>9.43e-08</iyy>
          <iyz>0</iyz>
          <izz>3.48e-08</izz>
        </inertia>
        <pose>0.0035087166 2.13e-08 1.18796e-05 0 0 0</pose>
      </inertial>
      <collision name="penpoint_gunnel_version0_body_11_collision">
        <pose>0 0 0 0 0 0</pose>
        <geometry>
          <mesh>
            <uri>../meshes/obj/animat_penpoint_gunnel_version0_body_11_collision.obj</uri>
            <scale>0.0049467087 0.0049467087 0.012407124</scale>
          </mesh>
        </geometry>
      </collision>
      <visual name="penpoint_gunnel_version0_body_11_visual">
        <pose>0.0 0.0 0.0 0.0 -0.0 0.0</pose>
        <geometry>
          <mesh>
            <uri>../meshes/obj/animat_penpoint_gunnel_version0_body_11.obj</uri>
            <scale>0.0049467087 0.0049467087 0.012407124</scale>
          </mesh>
        </geometry>
      </visual>
    </link>
    <link name="penpoint_gunnel_version0_body_12_link">
      <pose>0.1468942016 0 -5.22e-08 0 0 0</pose>
      <inertial>
        <mass>0.0017441379</mass>
        <inertia>
          <ixx>6.94e-08</ixx>
          <ixy>0</ixy>
          <ixz>0</ixz>
          <iyy>8.3e-08</iyy>
          <iyz>0</iyz>
          <izz>2.73e-08</izz>
        </inertia>
        <pose>0.0038219839 1.92e-08 1.84202e-05 0 0 0</pose>
      </inertial>
      <collision name="penpoint_gunnel_version0_body_12_collision">
        <pose>0 0 0 0 0 0</pose>
        <geometry>
          <mesh>
            <uri>../meshes/obj/animat_penpoint_gunnel_version0_body_12_collision.obj</uri>
            <scale>0.0042927861 0.0042927861 0.012501359</scale>
          </mesh>
        </geometry>
      </collision>
      <visual name="penpoint_gunnel_version0_body_12_visual">
        <pose>0.0 0.0 0.0 0.0 -0.0 0.0</pose>
        <geometry>
          <mesh>
            <uri>../meshes/obj/animat_penpoint_gunnel_version0_body_12.obj</uri>
            <scale>0.0042927861 0.0042927861 0.012501359</scale>
          </mesh>
        </geometry>
      </visual>
    </link>
    <link name="penpoint_gunnel_version0_body_13_link">
      <pose>0.1580038369 0 9.84e-08 0 0 0</pose>
      <inertial>
        <mass>0.0014967544</mass>
        <inertia>
          <ixx>5.72e-08</ixx>
          <ixy>0</ixy>
          <ixz>0</ixz>
          <iyy>6.97e-08</iyy>
          <iyz>0</iyz>
          <izz>2.15e-08</izz>
        </inertia>
        <pose>0.004012391 -8.2e-09 2.44093e-05 0 0 0</pose>
      </inertial>
      <collision name="penpoint_gunnel_version0_body_13_collision">
        <pose>0 0 0 0 0 0</pose>
        <geometry>
          <mesh>
            <uri>../meshes/obj/animat_penpoint_gunnel_version0_body_13_collision.obj</uri>
            <scale>0.003736794 0.003736794 0.0125769377</scale>
          </mesh>
        </geometry>
      </collision>
      <visual name="penpoint_gunnel_version0_body_13_visual">
        <pose>0.0 0.0 0.0 0.0 -0.0 0.0</pose>
        <geometry>
          <mesh>
            <uri>../meshes/obj/animat_penpoint_gunnel_version0_body_13.obj</uri>
            <scale>0.003736794 0.003736794 0.0125769377</scale>
          </mesh>
        </geometry>
      </visual>
    </link>
    <link name="penpoint_gunnel_version0_body_14_link">
      <pose>0.169113487 0 -3.04e-08 0 0 0</pose>
      <inertial>
        <mass>0.0012609659</mass>
        <inertia>
          <ixx>4.34e-08</ixx>
          <ixy>0</ixy>
          <ixz>0</ixz>
          <iyy>5.45e-08</iyy>
          <iyz>0</iyz>
          <izz>1.71e-08</izz>
        </inertia>
        <pose>0.0041877925 -1.2e-08 2.76223e-05 0 0 0</pose>
      </inertial>
      <collision name="penpoint_gunnel_version0_body_14_collision">
        <pose>0 0 0 0 0 0</pose>
        <geometry>
          <mesh>
            <uri>../meshes/obj/animat_penpoint_gunnel_version0_body_14_collision.obj</uri>
            <scale>0.0033174753 0.0033174753 0.0120610595</scale>
          </mesh>
        </geometry>
      </collision>
      <visual name="penpoint_gunnel_version0_body_14_visual">
        <pose>0.0 0.0 0.0 0.0 -0.0 0.0</pose>
        <geometry>
          <mesh>
            <uri>../meshes/obj/animat_penpoint_gunnel_version0_body_14.obj</uri>
            <scale>0.0033174753 0.0033174753 0.0120610595</scale>
          </mesh>
        </geometry>
      </visual>
    </link>
    <link name="penpoint_gunnel_version0_body_15_link">
      <pose>0.1802231371 0 -7.741e-07 0 0 0</pose>
      <inertial>
        <mass>0.00106477</mass>
        <inertia>
          <ixx>3.27e-08</ixx>
          <ixy>0</ixy>
          <ixz>0</ixz>
          <iyy>4.23e-08</iyy>
          <iyz>0</iyz>
          <izz>1.37e-08</izz>
        </inertia>
        <pose>0.0043400377 -1.2e-09 3.07695e-05 0 0 0</pose>
      </inertial>
      <collision name="penpoint_gunnel_version0_body_15_collision">
        <pose>0 0 0 0 0 0</pose>
        <geometry>
          <mesh>
            <uri>../meshes/obj/animat_penpoint_gunnel_version0_body_15_collision.obj</uri>
            <scale>0.0029595494 0.0029595494 0.0114676952</scale>
          </mesh>
        </geometry>
      </collision>
      <visual name="penpoint_gunnel_version0_body_15_visual">
        <pose>0.0 0.0 0.0 0.0 -0.0 0.0</pose>
        <geometry>
          <mesh>
            <uri>../meshes/obj/animat_penpoint_gunnel_version0_body_15.obj</uri>
            <scale>0.0029595494 0.0029595494 0.0114676952</scale>
          </mesh>
        </geometry>
      </visual>
    </link>
    <link name="penpoint_gunnel_version0_body_16_link">
      <pose>0.1913327724 0 4.5905e-06 0 0 0</pose>
      <inertial>
        <mass>0.0008844328</mass>
        <inertia>
          <ixx>2.31e-08</ixx>
          <ixy>0</ixy>
          <ixz>0</ixz>
          <iyy>3.15e-08</iyy>
          <iyz>0</iyz>
          <izz>1.11e-08</izz>
        </inertia>
        <pose>0.0044073756 -6e-10 2.83842e-05 0 0 0</pose>
      </inertial>
      <collision name="penpoint_gunnel_version0_body_16_collision">
        <pose>0 0 0 0 0 0</pose>
        <geometry>
          <mesh>
            <uri>../meshes/obj/animat_penpoint_gunnel_version0_body_16_collision.obj</uri>
            <scale>0.002684772 0.002684772 0.0107331872</scale>
          </mesh>
        </geometry>
      </collision>
      <visual name="penpoint_gunnel_version0_body_16_visual">
        <pose>0.0 0.0 0.0 0.0 -0.0 0.0</pose>
        <geometry>
          <mesh>
            <uri>../meshes/obj/animat_penpoint_gunnel_version0_body_16.obj</uri>
            <scale>0.002684772 0.002684772 0.0107331872</scale>
          </mesh>
        </geometry>
      </visual>
    </link>
    <link name="penpoint_gunnel_version0_body_17_link">
      <pose>0.2024424225 0 -1.86275e-05 0 0 0</pose>
      <inertial>
        <mass>0.0006258788</mass>
        <inertia>
          <ixx>1.29e-08</ixx>
          <ixy>0</ixy>
          <ixz>0</ixz>
          <iyy>1.92e-08</iyy>
          <iyz>0</iyz>
          <izz>7.5e-09</izz>
        </inertia>
        <pose>0.0045213252 -2.71e-08 4.96992e-05 0 0 0</pose>
      </inertial>
      <collision name="penpoint_gunnel_version0_body_17_collision">
        <pose>0 0 0 0 0 0</pose>
        <geometry>
          <mesh>
            <uri>../meshes/obj/animat_penpoint_gunnel_version0_body_17_collision.obj</uri>
            <scale>0.00221771 0.00221771 0.009745717</scale>
          </mesh>
        </geometry>
      </collision>
      <visual name="penpoint_gunnel_version0_body_17_visual">
        <pose>0.0 0.0 0.0 0.0 -0.0 0.0</pose>
        <geometry>
          <mesh>
            <uri>../meshes/obj/animat_penpoint_gunnel_version0_body_17.obj</uri>
            <scale>0.00221771 0.00221771 0.009745717</scale>
          </mesh>
        </geometry>
      </visual>
    </link>
    <link name="penpoint_gunnel_version0_body_18_link">
      <pose>0.2135520577 0 6.00916e-05 0 0 0</pose>
      <inertial>
        <mass>0.0003897098</mass>
        <inertia>
          <ixx>5.9e-09</ixx>
          <ixy>0</ixy>
          <ixz>0</ixz>
          <iyy>9.9e-09</iyy>
          <iyz>0</iyz>
          <izz>4.4e-09</izz>
        </inertia>
        <pose>0.004676044 -1.18e-08 8.0498e-06 0 0 0</pose>
      </inertial>
      <collision name="penpoint_gunnel_version0_body_18_collision">
        <pose>0 0 0 0 0 0</pose>
        <geometry>
          <mesh>
            <uri>../meshes/obj/animat_penpoint_gunnel_version0_body_18_collision.obj</uri>
            <scale>0.0016744137 0.0016744137 0.0085254908</scale>
          </mesh>
        </geometry>
      </collision>
      <visual name="penpoint_gunnel_version0_body_18_visual">
        <pose>0.0 0.0 0.0 0.0 -0.0 0.0</pose>
        <geometry>
          <mesh>
            <uri>../meshes/obj/animat_penpoint_gunnel_version0_body_18.obj</uri>
            <scale>0.0016744137 0.0016744137 0.0085254908</scale>
          </mesh>
        </geometry>
      </visual>
    </link>
    <link name="penpoint_gunnel_version0_body_19_link">
      <pose>0.2246617079 0 -0.0001627386 0 0 0</pose>
      <inertial>
        <mass>0.0001892766</mass>
        <inertia>
          <ixx>1.9e-09</ixx>
          <ixy>0</ixy>
          <ixz>0</ixz>
          <iyy>3.9e-09</iyy>
          <iyz>0</iyz>
          <izz>2e-09</izz>
        </inertia>
        <pose>0.004819334 -1.345e-07 0.0001217763 0 0 0</pose>
      </inertial>
      <collision name="penpoint_gunnel_version0_body_19_collision">
        <pose>0 0 0 0 0 0</pose>
        <geometry>
          <mesh>
            <uri>../meshes/obj/animat_penpoint_gunnel_version0_body_19_collision.obj</uri>
            <scale>0.0010741353 0.0010741353 0.0072328448</scale>
          </mesh>
        </geometry>
      </collision>
      <visual name="penpoint_gunnel_version0_body_19_visual">
        <pose>0.0 0.0 0.0 0.0 -0.0 0.0</pose>
        <geometry>
          <mesh>
            <uri>../meshes/obj/animat_penpoint_gunnel_version0_body_19.obj</uri>
            <scale>0.0010741353 0.0010741353 0.0072328448</scale>
          </mesh>
        </geometry>
      </visual>
    </link>
    <link name="penpoint_gunnel_version0_body_20_link">
      <pose>0.235771358 0 0.0002721555 0 0 0</pose>
      <inertial>
        <mass>0.0001008971</mass>
        <inertia>
          <ixx>4e-10</ixx>
          <ixy>0</ixy>
          <ixz>1e-10</ixz>
          <iyy>1.4e-09</iyy>
          <iyz>0</iyz>
          <izz>1e-09</izz>
        </inertia>
        <pose>0.0041966587 -3.324e-07 0.0003259446 0 0 0</pose>
      </inertial>
      <collision name="penpoint_gunnel_version0_body_20_collision">
        <pose>0 0 0 0 0 0</pose>
        <geometry>
          <mesh>
            <uri>../meshes/obj/animat_penpoint_gunnel_version0_body_20_collision.obj</uri>
            <scale>0.0007559061 0.0007559061 0.0054109097</scale>
          </mesh>
        </geometry>
      </collision>
      <visual name="penpoint_gunnel_version0_body_20_visual">
        <pose>0.0 0.0 0.0 0.0 -0.0 0.0</pose>
        <geometry>
          <mesh>
            <uri>../meshes/obj/animat_penpoint_gunnel_version0_body_20.obj</uri>
            <scale>0.0007559061 0.0007559061 0.0054109097</scale>
          </mesh>
        </geometry>
      </visual>
    </link>
    <joint name="penpoint_gunnel_version0_body_1_link" type="revolute">
      <parent>penpoint_gunnel_version0_body_0_link</parent>
      <child>penpoint_gunnel_version0_body_1_link</child>
      <pose>0.0 0.0 0.0 0.0 0.0 0.0</pose>
      <axis>
        <xyz>0 0 1.0</xyz>
        <limit>
          <lower>-0.5235987902</lower>
          <upper>0.5235987902</upper>
          <effort>10.0</effort>
          <velocity>10.0</velocity>
        </limit>
      </axis>
    </joint>
    <joint name="penpoint_gunnel_version0_body_2_link" type="revolute">
      <parent>penpoint_gunnel_version0_body_1_link</parent>
      <child>penpoint_gunnel_version0_body_2_link</child>
      <pose>0.0 0.0 0.0 0.0 0.0 0.0</pose>
      <axis>
        <xyz>0 0 1.0</xyz>
        <limit>
          <lower>-0.5235987902</lower>
          <upper>0.5235987902</upper>
          <effort>10.0</effort>
          <velocity>10.0</velocity>
        </limit>
      </axis>
    </joint>
    <joint name="penpoint_gunnel_version0_body_3_link" type="revolute">
      <parent>penpoint_gunnel_version0_body_2_link</parent>
      <child>penpoint_gunnel_version0_body_3_link</child>
      <pose>0.0 0.0 0.0 0.0 0.0 0.0</pose>
      <axis>
        <xyz>0 0 1.0</xyz>
        <limit>
          <lower>-0.5235987902</lower>
          <upper>0.5235987902</upper>
          <effort>10.0</effort>
          <velocity>10.0</velocity>
        </limit>
      </axis>
    </joint>
    <joint name="penpoint_gunnel_version0_body_4_link" type="revolute">
      <parent>penpoint_gunnel_version0_body_3_link</parent>
      <child>penpoint_gunnel_version0_body_4_link</child>
      <pose>0.0 0.0 0.0 0.0 0.0 0.0</pose>
      <axis>
        <xyz>0 0 1.0</xyz>
        <limit>
          <lower>-0.5235987902</lower>
          <upper>0.5235987902</upper>
          <effort>10.0</effort>
          <velocity>10.0</velocity>
        </limit>
      </axis>
    </joint>
    <joint name="penpoint_gunnel_version0_body_5_link" type="revolute">
      <parent>penpoint_gunnel_version0_body_4_link</parent>
      <child>penpoint_gunnel_version0_body_5_link</child>
      <pose>0.0 0.0 0.0 0.0 0.0 0.0</pose>
      <axis>
        <xyz>0 0 1.0</xyz>
        <limit>
          <lower>-0.5235987902</lower>
          <upper>0.5235987902</upper>
          <effort>10.0</effort>
          <velocity>10.0</velocity>
        </limit>
      </axis>
    </joint>
    <joint name="penpoint_gunnel_version0_body_6_link" type="revolute">
      <parent>penpoint_gunnel_version0_body_5_link</parent>
      <child>penpoint_gunnel_version0_body_6_link</child>
      <pose>0.0 0.0 0.0 0.0 0.0 0.0</pose>
      <axis>
        <xyz>0 0 1.0</xyz>
        <limit>
          <lower>-0.5235987902</lower>
          <upper>0.5235987902</upper>
          <effort>10.0</effort>
          <velocity>10.0</velocity>
        </limit>
      </axis>
    </joint>
    <joint name="penpoint_gunnel_version0_body_7_link" type="revolute">
      <parent>penpoint_gunnel_version0_body_6_link</parent>
      <child>penpoint_gunnel_version0_body_7_link</child>
      <pose>0.0 0.0 0.0 0.0 0.0 0.0</pose>
      <axis>
        <xyz>0 0 1.0</xyz>
        <limit>
          <lower>-0.5235987902</lower>
          <upper>0.5235987902</upper>
          <effort>10.0</effort>
          <velocity>10.0</velocity>
        </limit>
      </axis>
    </joint>
    <joint name="penpoint_gunnel_version0_body_8_link" type="revolute">
      <parent>penpoint_gunnel_version0_body_7_link</parent>
      <child>penpoint_gunnel_version0_body_8_link</child>
      <pose>0.0 0.0 0.0 0.0 0.0 0.0</pose>
      <axis>
        <xyz>0 0 1.0</xyz>
        <limit>
          <lower>-0.5235987902</lower>
          <upper>0.5235987902</upper>
          <effort>10.0</effort>
          <velocity>10.0</velocity>
        </limit>
      </axis>
    </joint>
    <joint name="penpoint_gunnel_version0_body_9_link" type="revolute">
      <parent>penpoint_gunnel_version0_body_8_link</parent>
      <child>penpoint_gunnel_version0_body_9_link</child>
      <pose>0.0 0.0 0.0 0.0 0.0 0.0</pose>
      <axis>
        <xyz>0 0 1.0</xyz>
        <limit>
          <lower>-0.5235987902</lower>
          <upper>0.5235987902</upper>
          <effort>10.0</effort>
          <velocity>10.0</velocity>
        </limit>
      </axis>
    </joint>
    <joint name="penpoint_gunnel_version0_body_10_link" type="revolute">
      <parent>penpoint_gunnel_version0_body_9_link</parent>
      <child>penpoint_gunnel_version0_body_10_link</child>
      <pose>0.0 0.0 0.0 0.0 0.0 0.0</pose>
      <axis>
        <xyz>0 0 1.0</xyz>
        <limit>
          <lower>-0.5235987902</lower>
          <upper>0.5235987902</upper>
          <effort>10.0</effort>
          <velocity>10.0</velocity>
        </limit>
      </axis>
    </joint>
    <joint name="penpoint_gunnel_version0_body_11_link" type="revolute">
      <parent>penpoint_gunnel_version0_body_10_link</parent>
      <child>penpoint_gunnel_version0_body_11_link</child>
      <pose>0.0 0.0 0.0 0.0 0.0 0.0</pose>
      <axis>
        <xyz>0 0 1.0</xyz>
        <limit>
          <lower>-0.5235987902</lower>
          <upper>0.5235987902</upper>
          <effort>10.0</effort>
          <velocity>10.0</velocity>
        </limit>
      </axis>
    </joint>
    <joint name="penpoint_gunnel_version0_body_12_link" type="revolute">
      <parent>penpoint_gunnel_version0_body_11_link</parent>
      <child>penpoint_gunnel_version0_body_12_link</child>
      <pose>0.0 0.0 0.0 0.0 0.0 0.0</pose>
      <axis>
        <xyz>0 0 1.0</xyz>
        <limit>
          <lower>-0.5235987902</lower>
          <upper>0.5235987902</upper>
          <effort>10.0</effort>
          <velocity>10.0</velocity>
        </limit>
      </axis>
    </joint>
    <joint name="penpoint_gunnel_version0_body_13_link" type="revolute">
      <parent>penpoint_gunnel_version0_body_12_link</parent>
      <child>penpoint_gunnel_version0_body_13_link</child>
      <pose>0.0 0.0 0.0 0.0 0.0 0.0</pose>
      <axis>
        <xyz>0 0 1.0</xyz>
        <limit>
          <lower>-0.5235987902</lower>
          <upper>0.5235987902</upper>
          <effort>10.0</effort>
          <velocity>10.0</velocity>
        </limit>
      </axis>
    </joint>
    <joint name="penpoint_gunnel_version0_body_14_link" type="revolute">
      <parent>penpoint_gunnel_version0_body_13_link</parent>
      <child>penpoint_gunnel_version0_body_14_link</child>
      <pose>0.0 0.0 0.0 0.0 0.0 0.0</pose>
      <axis>
        <xyz>0 0 1.0</xyz>
        <limit>
          <lower>-0.5235987902</lower>
          <upper>0.5235987902</upper>
          <effort>10.0</effort>
          <velocity>10.0</velocity>
        </limit>
      </axis>
    </joint>
    <joint name="penpoint_gunnel_version0_body_15_link" type="revolute">
      <parent>penpoint_gunnel_version0_body_14_link</parent>
      <child>penpoint_gunnel_version0_body_15_link</child>
      <pose>0.0 0.0 0.0 0.0 0.0 0.0</pose>
      <axis>
        <xyz>0 0 1.0</xyz>
        <limit>
          <lower>-0.5235987902</lower>
          <upper>0.5235987902</upper>
          <effort>10.0</effort>
          <velocity>10.0</velocity>
        </limit>
      </axis>
    </joint>
    <joint name="penpoint_gunnel_version0_body_16_link" type="revolute">
      <parent>penpoint_gunnel_version0_body_15_link</parent>
      <child>penpoint_gunnel_version0_body_16_link</child>
      <pose>0.0 0.0 0.0 0.0 0.0 0.0</pose>
      <axis>
        <xyz>0 0 1.0</xyz>
        <limit>
          <lower>-0.5235987902</lower>
          <upper>0.5235987902</upper>
          <effort>10.0</effort>
          <velocity>10.0</velocity>
        </limit>
      </axis>
    </joint>
    <joint name="penpoint_gunnel_version0_body_17_link" type="revolute">
      <parent>penpoint_gunnel_version0_body_16_link</parent>
      <child>penpoint_gunnel_version0_body_17_link</child>
      <pose>0.0 0.0 0.0 0.0 0.0 0.0</pose>
      <axis>
        <xyz>0 0 1.0</xyz>
        <limit>
          <lower>-0.5235987902</lower>
          <upper>0.5235987902</upper>
          <effort>10.0</effort>
          <velocity>10.0</velocity>
        </limit>
      </axis>
    </joint>
    <joint name="penpoint_gunnel_version0_body_18_link" type="revolute">
      <parent>penpoint_gunnel_version0_body_17_link</parent>
      <child>penpoint_gunnel_version0_body_18_link</child>
      <pose>0.0 0.0 0.0 0.0 0.0 0.0</pose>
      <axis>
        <xyz>0 0 1.0</xyz>
        <limit>
          <lower>-0.5235987902</lower>
          <upper>0.5235987902</upper>
          <effort>10.0</effort>
          <velocity>10.0</velocity>
        </limit>
      </axis>
    </joint>
    <joint name="penpoint_gunnel_version0_body_19_link" type="revolute">
      <parent>penpoint_gunnel_version0_body_18_link</parent>
      <child>penpoint_gunnel_version0_body_19_link</child>
      <pose>0.0 0.0 0.0 0.0 0.0 0.0</pose>
      <axis>
        <xyz>0 0 1.0</xyz>
        <limit>
          <lower>-0.5235987902</lower>
          <upper>0.5235987902</upper>
          <effort>10.0</effort>
          <velocity>10.0</velocity>
        </limit>
      </axis>
    </joint>
    <joint name="penpoint_gunnel_version0_body_20_link" type="revolute">
      <parent>penpoint_gunnel_version0_body_19_link</parent>
      <child>penpoint_gunnel_version0_body_20_link</child>
      <pose>0.0 0.0 0.0 0.0 0.0 0.0</pose>
      <axis>
        <xyz>0 0 1.0</xyz>
        <limit>
          <lower>-0.5235987902</lower>
          <upper>0.5235987902</upper>
          <effort>10.0</effort>
          <velocity>10.0</velocity>
        </limit>
      </axis>
    </joint>
  </model>
</sdf>
