<?xml version="1.0"?>
<!-- created with Phobos 0.7 -->
<sdf version="1.5">
  <model name="rock_prickleback">
    <link name="rock_prickleback_version0_body_0_link">
      <pose>0 0 0 0 0 0</pose>
      <inertial>
        <mass>0.0008822202</mass>
        <inertia>
          <ixx>1.38e-08</ixx>
          <ixy>0</ixy>
          <ixz>2e-10</ixz>
          <iyy>1.77e-08</iyy>
          <iyz>0</iyz>
          <izz>1.6e-08</izz>
        </inertia>
        <pose>0.0109561663 5.623e-07 0.0001386728 0 0 0</pose>
      </inertial>
      <collision name="rock_prickleback_version0_body_0_collision">
        <pose>0 0 0 0 0 0</pose>
        <geometry>
          <mesh>
            <uri>../meshes/obj/animat_rock_prickleback_version0_body_0_collision.obj</uri>
            <scale>1.0 1.0 1.0</scale>
          </mesh>
        </geometry>
      </collision>
      <visual name="rock_prickleback_version0_body_0_visual">
        <pose>0.0 0.0 0.0 0.0 -0.0 0.0</pose>
        <geometry>
          <mesh>
            <uri>../meshes/obj/animat_rock_prickleback_version0_body_0.obj</uri>
            <scale>1.0 1.0 1.0</scale>
          </mesh>
        </geometry>
      </visual>
    </link>
    <link name="rock_prickleback_version0_body_1_link">
      <pose>0.0187759995 0 4.36485e-05 0 0 0</pose>
      <inertial>
        <mass>0.0012895822</mass>
        <inertia>
          <ixx>3.09e-08</ixx>
          <ixy>0</ixy>
          <ixz>-1e-10</ixz>
          <iyy>2.79e-08</iyy>
          <iyz>0</iyz>
          <izz>2.4e-08</izz>
        </inertia>
        <pose>0.0013126917 1.368e-07 -2.74998e-05 0 0 0</pose>
      </inertial>
      <collision name="rock_prickleback_version0_body_1_collision">
        <pose>0 0 0 0 0 0</pose>
        <geometry>
          <mesh>
            <uri>../meshes/obj/animat_rock_prickleback_version0_body_1_collision.obj</uri>
            <scale>0.00664711 0.00664711 0.0076096058</scale>
          </mesh>
        </geometry>
      </collision>
      <visual name="rock_prickleback_version0_body_1_visual">
        <pose>0.0 0.0 0.0 0.0 -0.0 0.0</pose>
        <geometry>
          <mesh>
            <uri>../meshes/obj/animat_rock_prickleback_version0_body_1.obj</uri>
            <scale>0.00664711 0.00664711 0.0076096058</scale>
          </mesh>
        </geometry>
      </visual>
    </link>
    <link name="rock_prickleback_version0_body_2_link">
      <pose>0.0272252001 0 -3.63454e-05 0 0 0</pose>
      <inertial>
        <mass>0.0012934121</mass>
        <inertia>
          <ixx>3.2e-08</ixx>
          <ixy>0</ixy>
          <ixz>0</ixz>
          <iyy>2.99e-08</iyy>
          <iyz>0</iyz>
          <izz>2.19e-08</izz>
        </inertia>
        <pose>0.0012954231 -7.88e-08 2.20722e-05 0 0 0</pose>
      </inertial>
      <collision name="rock_prickleback_version0_body_2_collision">
        <pose>0 0 0 0 0 0</pose>
        <geometry>
          <mesh>
            <uri>../meshes/obj/animat_rock_prickleback_version0_body_2_collision.obj</uri>
            <scale>0.0063599348 0.0063599348 0.0081834793</scale>
          </mesh>
        </geometry>
      </collision>
      <visual name="rock_prickleback_version0_body_2_visual">
        <pose>0.0 0.0 0.0 0.0 -0.0 0.0</pose>
        <geometry>
          <mesh>
            <uri>../meshes/obj/animat_rock_prickleback_version0_body_2.obj</uri>
            <scale>0.0063599348 0.0063599348 0.0081834793</scale>
          </mesh>
        </geometry>
      </visual>
    </link>
    <link name="rock_prickleback_version0_body_3_link">
      <pose>0.0356744006 0 1.59078e-05 0 0 0</pose>
      <inertial>
        <mass>0.001282366</mass>
        <inertia>
          <ixx>3.23e-08</ixx>
          <ixy>0</ixy>
          <ixz>0</ixz>
          <iyy>3.04e-08</iyy>
          <iyz>0</iyz>
          <izz>2.13e-08</izz>
        </inertia>
        <pose>0.0014170967 1.28e-08 -6.6611e-06 0 0 0</pose>
      </inertial>
      <collision name="rock_prickleback_version0_body_3_collision">
        <pose>0 0 0 0 0 0</pose>
        <geometry>
          <mesh>
            <uri>../meshes/obj/animat_rock_prickleback_version0_body_3_collision.obj</uri>
            <scale>0.0061880946 0.0061880946 0.0083727837</scale>
          </mesh>
        </geometry>
      </collision>
      <visual name="rock_prickleback_version0_body_3_visual">
        <pose>0.0 0.0 0.0 0.0 -0.0 0.0</pose>
        <geometry>
          <mesh>
            <uri>../meshes/obj/animat_rock_prickleback_version0_body_3.obj</uri>
            <scale>0.0061880946 0.0061880946 0.0083727837</scale>
          </mesh>
        </geometry>
      </visual>
    </link>
    <link name="rock_prickleback_version0_body_4_link">
      <pose>0.0441236012 0 -5.449e-06 0 0 0</pose>
      <inertial>
        <mass>0.0012879987</mass>
        <inertia>
          <ixx>3.22e-08</ixx>
          <ixy>0</ixy>
          <ixz>0</ixz>
          <iyy>3.05e-08</iyy>
          <iyz>0</iyz>
          <izz>2.13e-08</izz>
        </inertia>
        <pose>0.0013957843 1.33e-08 4.282e-06 0 0 0</pose>
      </inertial>
      <collision name="rock_prickleback_version0_body_4_collision">
        <pose>0 0 0 0 0 0</pose>
        <geometry>
          <mesh>
            <uri>../meshes/obj/animat_rock_prickleback_version0_body_4_collision.obj</uri>
            <scale>0.006185472 0.006185472 0.0083870888</scale>
          </mesh>
        </geometry>
      </collision>
      <visual name="rock_prickleback_version0_body_4_visual">
        <pose>0.0 0.0 0.0 0.0 -0.0 0.0</pose>
        <geometry>
          <mesh>
            <uri>../meshes/obj/animat_rock_prickleback_version0_body_4.obj</uri>
            <scale>0.006185472 0.006185472 0.0083870888</scale>
          </mesh>
        </geometry>
      </visual>
    </link>
    <link name="rock_prickleback_version0_body_5_link">
      <pose>0.0525728017 0 1.4662e-06 0 0 0</pose>
      <inertial>
        <mass>0.0012641471</mass>
        <inertia>
          <ixx>3.13e-08</ixx>
          <ixy>0</ixy>
          <ixz>0</ixz>
          <iyy>2.99e-08</iyy>
          <iyz>0</iyz>
          <izz>2.05e-08</izz>
        </inertia>
        <pose>0.0014819391 2.49e-08 1.0657e-06 0 0 0</pose>
      </inertial>
      <collision name="rock_prickleback_version0_body_5_collision">
        <pose>0 0 0 0 0 0</pose>
        <geometry>
          <mesh>
            <uri>../meshes/obj/animat_rock_prickleback_version0_body_5_collision.obj</uri>
            <scale>0.0060735345 0.0060735345 0.0083750486</scale>
          </mesh>
        </geometry>
      </collision>
      <visual name="rock_prickleback_version0_body_5_visual">
        <pose>0.0 0.0 0.0 0.0 -0.0 0.0</pose>
        <geometry>
          <mesh>
            <uri>../meshes/obj/animat_rock_prickleback_version0_body_5.obj</uri>
            <scale>0.0060735345 0.0060735345 0.0083750486</scale>
          </mesh>
        </geometry>
      </visual>
    </link>
    <link name="rock_prickleback_version0_body_6_link">
      <pose>0.0610219985 0 -3.01e-07 0 0 0</pose>
      <inertial>
        <mass>0.0012502583</mass>
        <inertia>
          <ixx>3.05e-08</ixx>
          <ixy>0</ixy>
          <ixz>0</ixz>
          <iyy>2.94e-08</iyy>
          <iyz>0</iyz>
          <izz>1.99e-08</izz>
        </inertia>
        <pose>0.0014964566 -1e-08 1.7166e-06 0 0 0</pose>
      </inertial>
      <collision name="rock_prickleback_version0_body_6_collision">
        <pose>0 0 0 0 0 0</pose>
        <geometry>
          <mesh>
            <uri>../meshes/obj/animat_rock_prickleback_version0_body_6_collision.obj</uri>
            <scale>0.0059959888 0.0059959888 0.0083809495</scale>
          </mesh>
        </geometry>
      </collision>
      <visual name="rock_prickleback_version0_body_6_visual">
        <pose>0.0 0.0 0.0 0.0 -0.0 0.0</pose>
        <geometry>
          <mesh>
            <uri>../meshes/obj/animat_rock_prickleback_version0_body_6.obj</uri>
            <scale>0.0059959888 0.0059959888 0.0083809495</scale>
          </mesh>
        </geometry>
      </visual>
    </link>
    <link name="rock_prickleback_version0_body_7_link">
      <pose>0.0694712028 0 1.67e-08 0 0 0</pose>
      <inertial>
        <mass>0.0012094215</mass>
        <inertia>
          <ixx>2.92e-08</ixx>
          <ixy>0</ixy>
          <ixz>0</ixz>
          <iyy>2.84e-08</iyy>
          <iyz>0</iyz>
          <izz>1.87e-08</izz>
        </inertia>
        <pose>0.0015837401 -9.4e-09 1.8231e-06 0 0 0</pose>
      </inertial>
      <collision name="rock_prickleback_version0_body_7_collision">
        <pose>0 0 0 0 0 0</pose>
        <geometry>
          <mesh>
            <uri>../meshes/obj/animat_rock_prickleback_version0_body_7_collision.obj</uri>
            <scale>0.005849421 0.005849421 0.0083636642</scale>
          </mesh>
        </geometry>
      </collision>
      <visual name="rock_prickleback_version0_body_7_visual">
        <pose>0.0 0.0 0.0 0.0 -0.0 0.0</pose>
        <geometry>
          <mesh>
            <uri>../meshes/obj/animat_rock_prickleback_version0_body_7.obj</uri>
            <scale>0.005849421 0.005849421 0.0083636642</scale>
          </mesh>
        </geometry>
      </visual>
    </link>
    <link name="rock_prickleback_version0_body_8_link">
      <pose>0.0779203996 0 1.86e-08 0 0 0</pose>
      <inertial>
        <mass>0.0012570375</mass>
        <inertia>
          <ixx>3.04e-08</ixx>
          <ixy>0</ixy>
          <ixz>0</ixz>
          <iyy>3.03e-08</iyy>
          <iyz>0</iyz>
          <izz>1.96e-08</izz>
        </inertia>
        <pose>0.0016674773 7.83e-08 2.2381e-06 0 0 0</pose>
      </inertial>
      <collision name="rock_prickleback_version0_body_8_collision">
        <pose>0 0 0 0 0 0</pose>
        <geometry>
          <mesh>
            <uri>../meshes/obj/animat_rock_prickleback_version0_body_8_collision.obj</uri>
            <scale>0.0058265924 0.0058265924 0.0084759593</scale>
          </mesh>
        </geometry>
      </collision>
      <visual name="rock_prickleback_version0_body_8_visual">
        <pose>0.0 0.0 0.0 0.0 -0.0 0.0</pose>
        <geometry>
          <mesh>
            <uri>../meshes/obj/animat_rock_prickleback_version0_body_8.obj</uri>
            <scale>0.0058265924 0.0058265924 0.0084759593</scale>
          </mesh>
        </geometry>
      </visual>
    </link>
    <link name="rock_prickleback_version0_body_9_link">
      <pose>0.0863695964 0 -1.63e-08 0 0 0</pose>
      <inertial>
        <mass>0.0011741992</mass>
        <inertia>
          <ixx>2.76e-08</ixx>
          <ixy>0</ixy>
          <ixz>0</ixz>
          <iyy>2.84e-08</iyy>
          <iyz>0</iyz>
          <izz>1.67e-08</izz>
        </inertia>
        <pose>0.0018301533 -2.3e-09 2.4714e-06 0 0 0</pose>
      </inertial>
      <collision name="rock_prickleback_version0_body_9_collision">
        <pose>0 0 0 0 0 0</pose>
        <geometry>
          <mesh>
            <uri>../meshes/obj/animat_rock_prickleback_version0_body_9_collision.obj</uri>
            <scale>0.005445838 0.005445838 0.0085453987</scale>
          </mesh>
        </geometry>
      </collision>
      <visual name="rock_prickleback_version0_body_9_visual">
        <pose>0.0 0.0 0.0 0.0 -0.0 0.0</pose>
        <geometry>
          <mesh>
            <uri>../meshes/obj/animat_rock_prickleback_version0_body_9.obj</uri>
            <scale>0.005445838 0.005445838 0.0085453987</scale>
          </mesh>
        </geometry>
      </visual>
    </link>
    <link name="rock_prickleback_version0_body_10_link">
      <pose>0.0948188007 0 9e-10 0 0 0</pose>
      <inertial>
        <mass>0.0011416248</mass>
        <inertia>
          <ixx>2.78e-08</ixx>
          <ixy>0</ixy>
          <ixz>0</ixz>
          <iyy>2.94e-08</iyy>
          <iyz>0</iyz>
          <izz>1.5e-08</izz>
        </inertia>
        <pose>0.0020514131 -4.63e-08 3.0459e-06 0 0 0</pose>
      </inertial>
      <collision name="rock_prickleback_version0_body_10_collision">
        <pose>0 0 0 0 0 0</pose>
        <geometry>
          <mesh>
            <uri>../meshes/obj/animat_rock_prickleback_version0_body_10_collision.obj</uri>
            <scale>0.0050654411 0.0050654411 0.0089130402</scale>
          </mesh>
        </geometry>
      </collision>
      <visual name="rock_prickleback_version0_body_10_visual">
        <pose>0.0 0.0 0.0 0.0 -0.0 0.0</pose>
        <geometry>
          <mesh>
            <uri>../meshes/obj/animat_rock_prickleback_version0_body_10.obj</uri>
            <scale>0.0050654411 0.0050654411 0.0089130402</scale>
          </mesh>
        </geometry>
      </visual>
    </link>
    <link name="rock_prickleback_version0_body_11_link">
      <pose>0.1032679975 0 6.4e-09 0 0 0</pose>
      <inertial>
        <mass>0.0010883437</mass>
        <inertia>
          <ixx>2.62e-08</ixx>
          <ixy>0</ixy>
          <ixz>0</ixz>
          <iyy>2.83e-08</iyy>
          <iyz>0</iyz>
          <izz>1.34e-08</izz>
        </inertia>
        <pose>0.0021447763 -6.46e-08 3.4549e-06 0 0 0</pose>
      </inertial>
      <collision name="rock_prickleback_version0_body_11_collision">
        <pose>0 0 0 0 0 0</pose>
        <geometry>
          <mesh>
            <uri>../meshes/obj/animat_rock_prickleback_version0_body_11_collision.obj</uri>
            <scale>0.0047720671 0.0047720671 0.0091350079</scale>
          </mesh>
        </geometry>
      </collision>
      <visual name="rock_prickleback_version0_body_11_visual">
        <pose>0.0 0.0 0.0 0.0 -0.0 0.0</pose>
        <geometry>
          <mesh>
            <uri>../meshes/obj/animat_rock_prickleback_version0_body_11.obj</uri>
            <scale>0.0047720671 0.0047720671 0.0091350079</scale>
          </mesh>
        </geometry>
      </visual>
    </link>
    <link name="rock_prickleback_version0_body_12_link">
      <pose>0.1117172018 0 -3.22e-08 0 0 0</pose>
      <inertial>
        <mass>0.0010086662</mass>
        <inertia>
          <ixx>2.29e-08</ixx>
          <ixy>0</ixy>
          <ixz>0</ixz>
          <iyy>2.54e-08</iyy>
          <iyz>0</iyz>
          <izz>1.18e-08</izz>
        </inertia>
        <pose>0.0023018792 4.28e-08 3.9337e-06 0 0 0</pose>
      </inertial>
      <collision name="rock_prickleback_version0_body_12_collision">
        <pose>0 0 0 0 0 0</pose>
        <geometry>
          <mesh>
            <uri>../meshes/obj/animat_rock_prickleback_version0_body_12_collision.obj</uri>
            <scale>0.0044957995 0.0044957995 0.0089677572</scale>
          </mesh>
        </geometry>
      </collision>
      <visual name="rock_prickleback_version0_body_12_visual">
        <pose>0.0 0.0 0.0 0.0 -0.0 0.0</pose>
        <geometry>
          <mesh>
            <uri>../meshes/obj/animat_rock_prickleback_version0_body_12.obj</uri>
            <scale>0.0044957995 0.0044957995 0.0089677572</scale>
          </mesh>
        </geometry>
      </visual>
    </link>
    <link name="rock_prickleback_version0_body_13_link">
      <pose>0.1201663986 0 6.42e-08 0 0 0</pose>
      <inertial>
        <mass>0.0009270442</mass>
        <inertia>
          <ixx>2e-08</ixx>
          <ixy>0</ixy>
          <ixz>0</ixz>
          <iyy>2.3e-08</iyy>
          <iyz>0</iyz>
          <izz>1.02e-08</izz>
        </inertia>
        <pose>0.0024698153 4.09e-08 5.0132e-06 0 0 0</pose>
      </inertial>
      <collision name="rock_prickleback_version0_body_13_collision">
        <pose>0 0 0 0 0 0</pose>
        <geometry>
          <mesh>
            <uri>../meshes/obj/animat_rock_prickleback_version0_body_13_collision.obj</uri>
            <scale>0.0041842461 0.0041842461 0.0088276863</scale>
          </mesh>
        </geometry>
      </collision>
      <visual name="rock_prickleback_version0_body_13_visual">
        <pose>0.0 0.0 0.0 0.0 -0.0 0.0</pose>
        <geometry>
          <mesh>
            <uri>../meshes/obj/animat_rock_prickleback_version0_body_13.obj</uri>
            <scale>0.0041842461 0.0041842461 0.0088276863</scale>
          </mesh>
        </geometry>
      </visual>
    </link>
    <link name="rock_prickleback_version0_body_14_link">
      <pose>0.1286156029 0 -1.79e-08 0 0 0</pose>
      <inertial>
        <mass>0.0008193059</mass>
        <inertia>
          <ixx>1.71e-08</ixx>
          <ixy>0</ixy>
          <ixz>0</ixz>
          <iyy>2.04e-08</iyy>
          <iyz>0</iyz>
          <izz>8.1e-09</izz>
        </inertia>
        <pose>0.0027201327 -1.26e-08 7.6529e-06 0 0 0</pose>
      </inertial>
      <collision name="rock_prickleback_version0_body_14_collision">
        <pose>0 0 0 0 0 0</pose>
        <geometry>
          <mesh>
            <uri>../meshes/obj/animat_rock_prickleback_version0_body_14_collision.obj</uri>
            <scale>0.0036959648 0.0036959648 0.0088663101</scale>
          </mesh>
        </geometry>
      </collision>
      <visual name="rock_prickleback_version0_body_14_visual">
        <pose>0.0 0.0 0.0 0.0 -0.0 0.0</pose>
        <geometry>
          <mesh>
            <uri>../meshes/obj/animat_rock_prickleback_version0_body_14.obj</uri>
            <scale>0.0036959648 0.0036959648 0.0088663101</scale>
          </mesh>
        </geometry>
      </visual>
    </link>
    <link name="rock_prickleback_version0_body_15_link">
      <pose>0.1370647997 0 -4.518e-07 0 0 0</pose>
      <inertial>
        <mass>0.0007038667</mass>
        <inertia>
          <ixx>1.39e-08</ixx>
          <ixy>0</ixy>
          <ixz>0</ixz>
          <iyy>1.74e-08</iyy>
          <iyz>0</iyz>
          <izz>6.4e-09</izz>
        </inertia>
        <pose>0.0028866825 -1.39e-08 1.3074e-05 0 0 0</pose>
      </inertial>
      <collision name="rock_prickleback_version0_body_15_collision">
        <pose>0 0 0 0 0 0</pose>
        <geometry>
          <mesh>
            <uri>../meshes/obj/animat_rock_prickleback_version0_body_15_collision.obj</uri>
            <scale>0.0032270551 0.0032270551 0.0089079738</scale>
          </mesh>
        </geometry>
      </collision>
      <visual name="rock_prickleback_version0_body_15_visual">
        <pose>0.0 0.0 0.0 0.0 -0.0 0.0</pose>
        <geometry>
          <mesh>
            <uri>../meshes/obj/animat_rock_prickleback_version0_body_15.obj</uri>
            <scale>0.0032270551 0.0032270551 0.0089079738</scale>
          </mesh>
        </geometry>
      </visual>
    </link>
    <link name="rock_prickleback_version0_body_16_link">
      <pose>0.1455139965 0 2.6625e-06 0 0 0</pose>
      <inertial>
        <mass>0.0005055041</mass>
        <inertia>
          <ixx>8.9e-09</ixx>
          <ixy>0</ixy>
          <ixz>0</ixz>
          <iyy>1.16e-08</iyy>
          <iyz>0</iyz>
          <izz>4e-09</izz>
        </inertia>
        <pose>0.003160283 -8.3e-09 1.87219e-05 0 0 0</pose>
      </inertial>
      <collision name="rock_prickleback_version0_body_16_collision">
        <pose>0 0 0 0 0 0</pose>
        <geometry>
          <mesh>
            <uri>../meshes/obj/animat_rock_prickleback_version0_body_16_collision.obj</uri>
            <scale>0.0025115013 0.0025115013 0.0086268187</scale>
          </mesh>
        </geometry>
      </collision>
      <visual name="rock_prickleback_version0_body_16_visual">
        <pose>0.0 0.0 0.0 0.0 -0.0 0.0</pose>
        <geometry>
          <mesh>
            <uri>../meshes/obj/animat_rock_prickleback_version0_body_16.obj</uri>
            <scale>0.0025115013 0.0025115013 0.0086268187</scale>
          </mesh>
        </geometry>
      </visual>
    </link>
    <link name="rock_prickleback_version0_body_17_link">
      <pose>0.1539631933 0 -1.07186e-05 0 0 0</pose>
      <inertial>
        <mass>0.0003842931</mass>
        <inertia>
          <ixx>5.8e-09</ixx>
          <ixy>0</ixy>
          <ixz>0</ixz>
          <iyy>7.9e-09</iyy>
          <iyz>0</iyz>
          <izz>2.8e-09</izz>
        </inertia>
        <pose>0.0033599141 -1.05e-08 3.01079e-05 0 0 0</pose>
      </inertial>
      <collision name="rock_prickleback_version0_body_17_collision">
        <pose>0 0 0 0 0 0</pose>
        <geometry>
          <mesh>
            <uri>../meshes/obj/animat_rock_prickleback_version0_body_17_collision.obj</uri>
            <scale>0.0020201802 0.0020201802 0.0081603527</scale>
          </mesh>
        </geometry>
      </collision>
      <visual name="rock_prickleback_version0_body_17_visual">
        <pose>0.0 0.0 0.0 0.0 -0.0 0.0</pose>
        <geometry>
          <mesh>
            <uri>../meshes/obj/animat_rock_prickleback_version0_body_17.obj</uri>
            <scale>0.0020201802 0.0020201802 0.0081603527</scale>
          </mesh>
        </geometry>
      </visual>
    </link>
    <link name="rock_prickleback_version0_body_18_link">
      <pose>0.162412405 0 3.60728e-05 0 0 0</pose>
      <inertial>
        <mass>0.0002818219</mass>
        <inertia>
          <ixx>3.3e-09</ixx>
          <ixy>0</ixy>
          <ixz>0</ixz>
          <iyy>4.9e-09</iyy>
          <iyz>0</iyz>
          <izz>1.9e-09</izz>
        </inertia>
        <pose>0.003434673 4.95e-08 8.7447e-06 0 0 0</pose>
      </inertial>
      <collision name="rock_prickleback_version0_body_18_collision">
        <pose>0 0 0 0 0 0</pose>
        <geometry>
          <mesh>
            <uri>../meshes/obj/animat_rock_prickleback_version0_body_18_collision.obj</uri>
            <scale>0.0017121434 0.0017121434 0.007371068</scale>
          </mesh>
        </geometry>
      </collision>
      <visual name="rock_prickleback_version0_body_18_visual">
        <pose>0.0 0.0 0.0 0.0 -0.0 0.0</pose>
        <geometry>
          <mesh>
            <uri>../meshes/obj/animat_rock_prickleback_version0_body_18.obj</uri>
            <scale>0.0017121434 0.0017121434 0.007371068</scale>
          </mesh>
        </geometry>
      </visual>
    </link>
    <link name="rock_prickleback_version0_body_19_link">
      <pose>0.1708616018 0 -9.59598e-05 0 0 0</pose>
      <inertial>
        <mass>0.0001988023</mass>
        <inertia>
          <ixx>1.7e-09</ixx>
          <ixy>0</ixy>
          <ixz>0</ixz>
          <iyy>2.8e-09</iyy>
          <iyz>0</iyz>
          <izz>1.3e-09</izz>
        </inertia>
        <pose>0.0034930706 -1.13e-07 5.15851e-05 0 0 0</pose>
      </inertial>
      <collision name="rock_prickleback_version0_body_19_collision">
        <pose>0 0 0 0 0 0</pose>
        <geometry>
          <mesh>
            <uri>../meshes/obj/animat_rock_prickleback_version0_body_19_collision.obj</uri>
            <scale>0.0014207363 0.0014207363 0.006377697</scale>
          </mesh>
        </geometry>
      </collision>
      <visual name="rock_prickleback_version0_body_19_visual">
        <pose>0.0 0.0 0.0 0.0 -0.0 0.0</pose>
        <geometry>
          <mesh>
            <uri>../meshes/obj/animat_rock_prickleback_version0_body_19.obj</uri>
            <scale>0.0014207363 0.0014207363 0.006377697</scale>
          </mesh>
        </geometry>
      </visual>
    </link>
    <link name="rock_prickleback_version0_body_20_link">
      <pose>0.1793107986 0 0.0001769 0 0 0</pose>
      <inertial>
        <mass>0.0001008229</mass>
        <inertia>
          <ixx>4e-10</ixx>
          <ixy>0</ixy>
          <ixz>0</ixz>
          <iyy>9e-10</iyy>
          <iyz>0</iyz>
          <izz>6e-10</izz>
        </inertia>
        <pose>0.0027959943 -5.949e-07 0.0002021962 0 0 0</pose>
      </inertial>
      <collision name="rock_prickleback_version0_body_20_collision">
        <pose>0 0 0 0 0 0</pose>
        <geometry>
          <mesh>
            <uri>../meshes/obj/animat_rock_prickleback_version0_body_20_collision.obj</uri>
            <scale>0.0011883974 0.0011883974 0.0049597621</scale>
          </mesh>
        </geometry>
      </collision>
      <visual name="rock_prickleback_version0_body_20_visual">
        <pose>0.0 0.0 0.0 0.0 -0.0 0.0</pose>
        <geometry>
          <mesh>
            <uri>../meshes/obj/animat_rock_prickleback_version0_body_20.obj</uri>
            <scale>0.0011883974 0.0011883974 0.0049597621</scale>
          </mesh>
        </geometry>
      </visual>
    </link>
    <joint name="rock_prickleback_version0_body_1_link" type="revolute">
      <parent>rock_prickleback_version0_body_0_link</parent>
      <child>rock_prickleback_version0_body_1_link</child>
      <pose>0.0 0.0 0.0 0.0 0.0 0.0</pose>
      <axis>
        <xyz>0 0 1.0</xyz>
        <limit>
          <lower>-0.5235987902</lower>
          <upper>0.5235987902</upper>
          <effort>10.0</effort>
          <velocity>10.0</velocity>
        </limit>
      </axis>
    </joint>
    <joint name="rock_prickleback_version0_body_2_link" type="revolute">
      <parent>rock_prickleback_version0_body_1_link</parent>
      <child>rock_prickleback_version0_body_2_link</child>
      <pose>0.0 0.0 0.0 0.0 0.0 0.0</pose>
      <axis>
        <xyz>0 0 1.0</xyz>
        <limit>
          <lower>-0.5235987902</lower>
          <upper>0.5235987902</upper>
          <effort>10.0</effort>
          <velocity>10.0</velocity>
        </limit>
      </axis>
    </joint>
    <joint name="rock_prickleback_version0_body_3_link" type="revolute">
      <parent>rock_prickleback_version0_body_2_link</parent>
      <child>rock_prickleback_version0_body_3_link</child>
      <pose>0.0 0.0 0.0 0.0 0.0 0.0</pose>
      <axis>
        <xyz>0 0 1.0</xyz>
        <limit>
          <lower>-0.5235987902</lower>
          <upper>0.5235987902</upper>
          <effort>10.0</effort>
          <velocity>10.0</velocity>
        </limit>
      </axis>
    </joint>
    <joint name="rock_prickleback_version0_body_4_link" type="revolute">
      <parent>rock_prickleback_version0_body_3_link</parent>
      <child>rock_prickleback_version0_body_4_link</child>
      <pose>0.0 0.0 0.0 0.0 0.0 0.0</pose>
      <axis>
        <xyz>0 0 1.0</xyz>
        <limit>
          <lower>-0.5235987902</lower>
          <upper>0.5235987902</upper>
          <effort>10.0</effort>
          <velocity>10.0</velocity>
        </limit>
      </axis>
    </joint>
    <joint name="rock_prickleback_version0_body_5_link" type="revolute">
      <parent>rock_prickleback_version0_body_4_link</parent>
      <child>rock_prickleback_version0_body_5_link</child>
      <pose>0.0 0.0 0.0 0.0 0.0 0.0</pose>
      <axis>
        <xyz>0 0 1.0</xyz>
        <limit>
          <lower>-0.5235987902</lower>
          <upper>0.5235987902</upper>
          <effort>10.0</effort>
          <velocity>10.0</velocity>
        </limit>
      </axis>
    </joint>
    <joint name="rock_prickleback_version0_body_6_link" type="revolute">
      <parent>rock_prickleback_version0_body_5_link</parent>
      <child>rock_prickleback_version0_body_6_link</child>
      <pose>0.0 0.0 0.0 0.0 0.0 0.0</pose>
      <axis>
        <xyz>0 0 1.0</xyz>
        <limit>
          <lower>-0.5235987902</lower>
          <upper>0.5235987902</upper>
          <effort>10.0</effort>
          <velocity>10.0</velocity>
        </limit>
      </axis>
    </joint>
    <joint name="rock_prickleback_version0_body_7_link" type="revolute">
      <parent>rock_prickleback_version0_body_6_link</parent>
      <child>rock_prickleback_version0_body_7_link</child>
      <pose>0.0 0.0 0.0 0.0 0.0 0.0</pose>
      <axis>
        <xyz>0 0 1.0</xyz>
        <limit>
          <lower>-0.5235987902</lower>
          <upper>0.5235987902</upper>
          <effort>10.0</effort>
          <velocity>10.0</velocity>
        </limit>
      </axis>
    </joint>
    <joint name="rock_prickleback_version0_body_8_link" type="revolute">
      <parent>rock_prickleback_version0_body_7_link</parent>
      <child>rock_prickleback_version0_body_8_link</child>
      <pose>0.0 0.0 0.0 0.0 0.0 0.0</pose>
      <axis>
        <xyz>0 0 1.0</xyz>
        <limit>
          <lower>-0.5235987902</lower>
          <upper>0.5235987902</upper>
          <effort>10.0</effort>
          <velocity>10.0</velocity>
        </limit>
      </axis>
    </joint>
    <joint name="rock_prickleback_version0_body_9_link" type="revolute">
      <parent>rock_prickleback_version0_body_8_link</parent>
      <child>rock_prickleback_version0_body_9_link</child>
      <pose>0.0 0.0 0.0 0.0 0.0 0.0</pose>
      <axis>
        <xyz>0 0 1.0</xyz>
        <limit>
          <lower>-0.5235987902</lower>
          <upper>0.5235987902</upper>
          <effort>10.0</effort>
          <velocity>10.0</velocity>
        </limit>
      </axis>
    </joint>
    <joint name="rock_prickleback_version0_body_10_link" type="revolute">
      <parent>rock_prickleback_version0_body_9_link</parent>
      <child>rock_prickleback_version0_body_10_link</child>
      <pose>0.0 0.0 0.0 0.0 0.0 0.0</pose>
      <axis>
        <xyz>0 0 1.0</xyz>
        <limit>
          <lower>-0.5235987902</lower>
          <upper>0.5235987902</upper>
          <effort>10.0</effort>
          <velocity>10.0</velocity>
        </limit>
      </axis>
    </joint>
    <joint name="rock_prickleback_version0_body_11_link" type="revolute">
      <parent>rock_prickleback_version0_body_10_link</parent>
      <child>rock_prickleback_version0_body_11_link</child>
      <pose>0.0 0.0 0.0 0.0 0.0 0.0</pose>
      <axis>
        <xyz>0 0 1.0</xyz>
        <limit>
          <lower>-0.5235987902</lower>
          <upper>0.5235987902</upper>
          <effort>10.0</effort>
          <velocity>10.0</velocity>
        </limit>
      </axis>
    </joint>
    <joint name="rock_prickleback_version0_body_12_link" type="revolute">
      <parent>rock_prickleback_version0_body_11_link</parent>
      <child>rock_prickleback_version0_body_12_link</child>
      <pose>0.0 0.0 0.0 0.0 0.0 0.0</pose>
      <axis>
        <xyz>0 0 1.0</xyz>
        <limit>
          <lower>-0.5235987902</lower>
          <upper>0.5235987902</upper>
          <effort>10.0</effort>
          <velocity>10.0</velocity>
        </limit>
      </axis>
    </joint>
    <joint name="rock_prickleback_version0_body_13_link" type="revolute">
      <parent>rock_prickleback_version0_body_12_link</parent>
      <child>rock_prickleback_version0_body_13_link</child>
      <pose>0.0 0.0 0.0 0.0 0.0 0.0</pose>
      <axis>
        <xyz>0 0 1.0</xyz>
        <limit>
          <lower>-0.5235987902</lower>
          <upper>0.5235987902</upper>
          <effort>10.0</effort>
          <velocity>10.0</velocity>
        </limit>
      </axis>
    </joint>
    <joint name="rock_prickleback_version0_body_14_link" type="revolute">
      <parent>rock_prickleback_version0_body_13_link</parent>
      <child>rock_prickleback_version0_body_14_link</child>
      <pose>0.0 0.0 0.0 0.0 0.0 0.0</pose>
      <axis>
        <xyz>0 0 1.0</xyz>
        <limit>
          <lower>-0.5235987902</lower>
          <upper>0.5235987902</upper>
          <effort>10.0</effort>
          <velocity>10.0</velocity>
        </limit>
      </axis>
    </joint>
    <joint name="rock_prickleback_version0_body_15_link" type="revolute">
      <parent>rock_prickleback_version0_body_14_link</parent>
      <child>rock_prickleback_version0_body_15_link</child>
      <pose>0.0 0.0 0.0 0.0 0.0 0.0</pose>
      <axis>
        <xyz>0 0 1.0</xyz>
        <limit>
          <lower>-0.5235987902</lower>
          <upper>0.5235987902</upper>
          <effort>10.0</effort>
          <velocity>10.0</velocity>
        </limit>
      </axis>
    </joint>
    <joint name="rock_prickleback_version0_body_16_link" type="revolute">
      <parent>rock_prickleback_version0_body_15_link</parent>
      <child>rock_prickleback_version0_body_16_link</child>
      <pose>0.0 0.0 0.0 0.0 0.0 0.0</pose>
      <axis>
        <xyz>0 0 1.0</xyz>
        <limit>
          <lower>-0.5235987902</lower>
          <upper>0.5235987902</upper>
          <effort>10.0</effort>
          <velocity>10.0</velocity>
        </limit>
      </axis>
    </joint>
    <joint name="rock_prickleback_version0_body_17_link" type="revolute">
      <parent>rock_prickleback_version0_body_16_link</parent>
      <child>rock_prickleback_version0_body_17_link</child>
      <pose>0.0 0.0 0.0 0.0 0.0 0.0</pose>
      <axis>
        <xyz>0 0 1.0</xyz>
        <limit>
          <lower>-0.5235987902</lower>
          <upper>0.5235987902</upper>
          <effort>10.0</effort>
          <velocity>10.0</velocity>
        </limit>
      </axis>
    </joint>
    <joint name="rock_prickleback_version0_body_18_link" type="revolute">
      <parent>rock_prickleback_version0_body_17_link</parent>
      <child>rock_prickleback_version0_body_18_link</child>
      <pose>0.0 0.0 0.0 0.0 0.0 0.0</pose>
      <axis>
        <xyz>0 0 1.0</xyz>
        <limit>
          <lower>-0.5235987902</lower>
          <upper>0.5235987902</upper>
          <effort>10.0</effort>
          <velocity>10.0</velocity>
        </limit>
      </axis>
    </joint>
    <joint name="rock_prickleback_version0_body_19_link" type="revolute">
      <parent>rock_prickleback_version0_body_18_link</parent>
      <child>rock_prickleback_version0_body_19_link</child>
      <pose>0.0 0.0 0.0 0.0 0.0 0.0</pose>
      <axis>
        <xyz>0 0 1.0</xyz>
        <limit>
          <lower>-0.5235987902</lower>
          <upper>0.5235987902</upper>
          <effort>10.0</effort>
          <velocity>10.0</velocity>
        </limit>
      </axis>
    </joint>
    <joint name="rock_prickleback_version0_body_20_link" type="revolute">
      <parent>rock_prickleback_version0_body_19_link</parent>
      <child>rock_prickleback_version0_body_20_link</child>
      <pose>0.0 0.0 0.0 0.0 0.0 0.0</pose>
      <axis>
        <xyz>0 0 1.0</xyz>
        <limit>
          <lower>-0.5235987902</lower>
          <upper>0.5235987902</upper>
          <effort>10.0</effort>
          <velocity>10.0</velocity>
        </limit>
      </axis>
    </joint>
  </model>
</sdf>
